Workbook

Sheet bippity_poppity_boo
A1: =trust!A1 -> sub | B1: tania_subid | C1: =trust!B1 -> computer_defect | D1: =trust!C1 -> computer_recip | E1: =trust!D1 -> stranger_defect | F1: =trust!E1 -> stranger_recip | G1: =trust!F1 -> friend_defect | H1: =trust!G1 -> friend_recip | I1: =island_data!C1 -> screener_date | J1: =island_data!D1 -> dob | K1: =island_data!E1 -> age_mo | L1: =rf1_data!D1 -> sub_age | M1: =rf1_data!E1 -> race | N1: =rf1_data!F1 -> ethnicity | O1: =rf1_data!G1 -> sub_gender | P1: =rf1_data!H1 -> eros_o_score | Q1: =rf1_data!I1 -> eros_s_score | R1: =rf1_data!J1 -> susd_adult_mania | S1: =rf1_data!K1 -> susd_adult_depression | ... DA1: =rf1_data!CS1 -> ios_stranger_score | DB1: =island_data!H1 -> audit_sum | DC1: =island_data!I1 -> dudit_sum | DD1: =island_data!J1 -> usi_sum | DE1: =island_data!K1 -> fevs_sum | DF1: =island_data!L1 -> pmas_sum | DG1: =island_data!M1 -> pam_total_sum | DH1: =island_data!N1 -> pam_adult_duration | DI1: =island_data!O1 -> pam_adult_interaction | ... EI1: =island_data!AO1 -> ecog_score | EJ1: =TabCAT!AU1 -> Flanker_TaskDuration | EK1: =TabCAT!AV1 -> Flanker_PracticeTrialSuccess | EL1: =TabCAT!AW1 -> Flanker_PTSet1_TotalCorrect | EM1: =TabCAT!AX1 -> Flanker_PTSet2_TotalCorrect | EN1: =TabCAT!AY1 -> Flanker_TotalScore | EO1: =TabCAT!AZ1 -> Flanker_Correct_Total | EP1: =TabCAT!BA1 -> Flanker_Correct_MedianRT | EQ1: =TabCAT!BB1 -> Flanker_Correct_StDevRT | ... GH1: =TabCAT!CS1 -> SetShifting_TotalScore_Z
A2: 10317 | B2: =_xlfn.XLOOKUP(bippity_poppity_boo!A2,rf1_data!A:A,rf1_data!B:B) -> 191960 | C2: =(_xlfn.XLOOKUP($A2,trust!$A:$A,trust!B:B,"NaN")) -> 2.8 | D2: =(_xlfn.XLOOKUP($A2,trust!$A:$A,trust!C:C,"NaN")) -> 4 | E2: =(_xlfn.XLOOKUP($A2,trust!$A:$A,trust!D:D,"NaN")) -> 2.8 | F2: =(_xlfn.XLOOKUP($A2,trust!$A:$A,trust!E:E,"NaN")) -> 5.2 | G2: =(_xlfn.XLOOKUP($A2,trust!$A:$A,trust!F:F,"NaN")) -> 6.857143 | H2: =(_xlfn.XLOOKUP($A2,trust!$A:$A,trust!G:G,"NaN")) -> 4.666667 | I2: =IF(_xlfn.XLOOKUP($B2,island_data!$B:$B,island_data!C:C,"NaN")="","NaN",_xlfn.XLOOKUP($B2,island_data!$B:$B,island_data!C:C,"NaN")) -> NaN | J2: =IF(_xlfn.XLOOKUP($B2,island_data!$B:$B,island_data!D:D,"NaN")="","NaN",_xlfn.XLOOKUP($B2,island_data!$B:$B,island_data!D:D,"NaN")) -> NaN | K2: =IF(_xlfn.XLOOKUP($B2,island_data!$B:$B,island_data!E:E,"NaN")="","NaN",_xlfn.XLOOKUP($B2,island_data!$B:$B,island_data!E:E,"NaN")) -> NaN | L2: =IF(_xlfn.XLOOKUP($B2,rf1_data!$B:$B,rf1_data!D:D,"NaN")="","NaN",(_xlfn.XLOOKUP($B2,rf1_data!$B:$B,rf1_data!D:D,"NaN"))) -> 62.96 | M2: =IF(_xlfn.XLOOKUP($B2,rf1_data!$B:$B,rf1_data!E:E,"NaN")="","NaN",(_xlfn.XLOOKUP($B2,rf1_data!$B:$B,rf1_data!E:E,"NaN"))) -> White | N2: =IF(_xlfn.XLOOKUP($B2,rf1_data!$B:$B,rf1_data!F:F,"NaN")="","NaN",(_xlfn.XLOOKUP($B2,rf1_data!$B:$B,rf1_data!F:F,"NaN"))) -> Not Hispanic or Latino | O2: =IF(_xlfn.XLOOKUP($B2,rf1_data!$B:$B,rf1_data!G:G,"NaN")="","NaN",(_xlfn.XLOOKUP($B2,rf1_data!$B:$B,rf1_data!G:G,"NaN"))) -> Female | P2: =IF(_xlfn.XLOOKUP($B2,rf1_data!$B:$B,rf1_data!H:H,"NaN")="","NaN",(_xlfn.XLOOKUP($B2,rf1_data!$B:$B,rf1_data!H:H,"NaN"))) -> 4.22 | Q2: =IF(_xlfn.XLOOKUP($B2,rf1_data!$B:$B,rf1_data!I:I,"NaN")="","NaN",(_xlfn.XLOOKUP($B2,rf1_data!$B:$B,rf1_data!I:I,"NaN"))) -> 4.3 | R2: =IF(_xlfn.XLOOKUP($B2,rf1_data!$B:$B,rf1_data!J:J,"NaN")="","NaN",(_xlfn.XLOOKUP($B2,rf1_data!$B:$B,rf1_data!J:J,"NaN"))) -> 0 | S2: =IF(_xlfn.XLOOKUP($B2,rf1_data!$B:$B,rf1_data!K:K,"NaN")="","NaN",(_xlfn.XLOOKUP($B2,rf1_data!$B:$B,rf1_data!K:K,"NaN"))) -> 6 | T2: =IF(_xlfn.XLOOKUP($B2,rf1_data!$B:$B,rf1_data!L:L,"NaN")="","NaN",(_xlfn.XLOOKUP($B2,rf1_data!$B:$B,rf1_data!L:L,"NaN"))) -> 0 | U2: =IF(_xlfn.XLOOKUP($B2,rf1_data!$B:$B,rf1_data!M:M,"NaN")="","NaN",(_xlfn.XLOOKUP($B2,rf1_data!$B:$B,rf1_data!M:M,"NaN"))) -> 4.83 | V2: =IF(_xlfn.XLOOKUP($B2,rf1_data!$B:$B,rf1_data!N:N,"NaN")="","NaN",(_xlfn.XLOOKUP($B2,rf1_data!$B:$B,rf1_data!N:N,"NaN"))) -> 4.83 | W2: =IF(_xlfn.XLOOKUP($B2,rf1_data!$B:$B,rf1_data!O:O,"NaN")="","NaN",(_xlfn.XLOOKUP($B2,rf1_data!$B:$B,rf1_data!O:O,"NaN"))) -> 5.38 | X2: =IF(_xlfn.XLOOKUP($B2,rf1_data!$B:$B,rf1_data!P:P,"NaN")="","NaN",(_xlfn.XLOOKUP($B2,rf1_data!$B:$B,rf1_data!P:P,"NaN"))) -> 4.5 | Y2: =IF(_xlfn.XLOOKUP($B2,rf1_data!$B:$B,rf1_data!Q:Q,"NaN")="","NaN",(_xlfn.XLOOKUP($B2,rf1_data!$B:$B,rf1_data!Q:Q,"NaN"))) -> 4.97 | Z2: =IF(_xlfn.XLOOKUP($B2,rf1_data!$B:$B,rf1_data!R:R,"NaN")="","NaN",(_xlfn.XLOOKUP($B2,rf1_data!$B:$B,rf1_data!R:R,"NaN"))) -> 21 | AA2: =IF(_xlfn.XLOOKUP($B2,rf1_data!$B:$B,rf1_data!S:S,"NaN")="","NaN",(_xlfn.XLOOKUP($B2,rf1_data!$B:$B,rf1_data!S:S,"NaN"))) -> 3 | AB2: =IF(_xlfn.XLOOKUP($B2,rf1_data!$B:$B,rf1_data!T:T,"NaN")="","NaN",(_xlfn.XLOOKUP($B2,rf1_data!$B:$B,rf1_data!T:T,"NaN"))) -> 11 | AC2: =IF(_xlfn.XLOOKUP($B2,rf1_data!$B:$B,rf1_data!U:U,"NaN")="","NaN",(_xlfn.XLOOKUP($B2,rf1_data!$B:$B,rf1_data!U:U,"NaN"))) -> 1 | AD2: =IF(_xlfn.XLOOKUP($B2,rf1_data!$B:$B,rf1_data!V:V,"NaN")="","NaN",(_xlfn.XLOOKUP($B2,rf1_data!$B:$B,rf1_data!V:V,"NaN"))) -> 6 | AE2: =IF(_xlfn.XLOOKUP($B2,rf1_data!$B:$B,rf1_data!W:W,"NaN")="","NaN",(_xlfn.XLOOKUP($B2,rf1_data!$B:$B,rf1_data!W:W,"NaN"))) -> 3 | AF2: =IF(_xlfn.XLOOKUP($B2,rf1_data!$B:$B,rf1_data!X:X,"NaN")="","NaN",(_xlfn.XLOOKUP($B2,rf1_data!$B:$B,rf1_data!X:X,"NaN"))) -> 7 | AG2: =IF(_xlfn.XLOOKUP($B2,rf1_data!$B:$B,rf1_data!Y:Y,"NaN")="","NaN",(_xlfn.XLOOKUP($B2,rf1_data!$B:$B,rf1_data!Y:Y,"NaN"))) -> 2 | AH2: =IF(_xlfn.XLOOKUP($B2,rf1_data!$B:$B,rf1_data!Z:Z,"NaN")="","NaN",(_xlfn.XLOOKUP($B2,rf1_data!$B:$B,rf1_data!Z:Z,"NaN"))) -> 5 | AI2: =IF(_xlfn.XLOOKUP($B2,rf1_data!$B:$B,rf1_data!AA:AA,"NaN")="","NaN",(_xlfn.XLOOKUP($B2,rf1_data!$B:$B,rf1_data!AA:AA,"NaN"))) -> 2 | AJ2: =IF(_xlfn.XLOOKUP($B2,rf1_data!$B:$B,rf1_data!AB:AB,"NaN")="","NaN",(_xlfn.XLOOKUP($B2,rf1_data!$B:$B,rf1_data!AB:AB,"NaN"))) -> 19 | AK2: =IF(_xlfn.XLOOKUP($B2,rf1_data!$B:$B,rf1_data!AC:AC,"NaN")="","NaN",(_xlfn.XLOOKUP($B2,rf1_data!$B:$B,rf1_data!AC:AC,"NaN"))) -> 30 | AL2: =IF(_xlfn.XLOOKUP($B2,rf1_data!$B:$B,rf1_data!AD:AD,"NaN")="","NaN",(_xlfn.XLOOKUP($B2,rf1_data!$B:$B,rf1_data!AD:AD,"NaN"))) -> 8 | AM2: =IF(_xlfn.XLOOKUP($B2,rf1_data!$B:$B,rf1_data!AE:AE,"NaN")="","NaN",(_xlfn.XLOOKUP($B2,rf1_data!$B:$B,rf1_data!AE:AE,"NaN"))) -> 0 | AN2: =IF(_xlfn.XLOOKUP($B2,rf1_data!$B:$B,rf1_data!AF:AF,"NaN")="","NaN",(_xlfn.XLOOKUP($B2,rf1_data!$B:$B,rf1_data!AF:AF,"NaN"))) -> 0 | AO2: =IF(_xlfn.XLOOKUP($B2,rf1_data!$B:$B,rf1_data!AG:AG,"NaN")="","NaN",(_xlfn.XLOOKUP($B2,rf1_data!$B:$B,rf1_data!AG:AG,"NaN"))) -> 3.83 | AP2: =IF(_xlfn.XLOOKUP($B2,rf1_data!$B:$B,rf1_data!AH:AH,"NaN")="","NaN",(_xlfn.XLOOKUP($B2,rf1_data!$B:$B,rf1_data!AH:AH,"NaN"))) -> 6.5 | AQ2: =IF(_xlfn.XLOOKUP($B2,rf1_data!$B:$B,rf1_data!AI:AI,"NaN")="","NaN",(_xlfn.XLOOKUP($B2,rf1_data!$B:$B,rf1_data!AI:AI,"NaN"))) -> 1 | AR2: =IF(_xlfn.XLOOKUP($B2,rf1_data!$B:$B,rf1_data!AJ:AJ,"NaN")="","NaN",(_xlfn.XLOOKUP($B2,rf1_data!$B:$B,rf1_data!AJ:AJ,"NaN"))) -> 4 | AS2: =IF(_xlfn.XLOOKUP($B2,rf1_data!$B:$B,rf1_data!AK:AK,"NaN")="","NaN",(_xlfn.XLOOKUP($B2,rf1_data!$B:$B,rf1_data!AK:AK,"NaN"))) -> 3 | AT2: =IF(_xlfn.XLOOKUP($B2,rf1_data!$B:$B,rf1_data!AL:AL,"NaN")="","NaN",(_xlfn.XLOOKUP($B2,rf1_data!$B:$B,rf1_data!AL:AL,"NaN"))) -> 17 | AU2: =IF(_xlfn.XLOOKUP($B2,rf1_data!$B:$B,rf1_data!AM:AM,"NaN")="","NaN",(_xlfn.XLOOKUP($B2,rf1_data!$B:$B,rf1_data!AM:AM,"NaN"))) -> 1.58 | AV2: =IF(_xlfn.XLOOKUP($B2,rf1_data!$B:$B,rf1_data!AN:AN,"NaN")="","NaN",(_xlfn.XLOOKUP($B2,rf1_data!$B:$B,rf1_data!AN:AN,"NaN"))) -> 0 | AW2: =IF(_xlfn.XLOOKUP($B2,rf1_data!$B:$B,rf1_data!AO:AO,"NaN")="","NaN",(_xlfn.XLOOKUP($B2,rf1_data!$B:$B,rf1_data!AO:AO,"NaN"))) -> 3 | AX2: =IF(_xlfn.XLOOKUP($B2,rf1_data!$B:$B,rf1_data!AP:AP,"NaN")="","NaN",(_xlfn.XLOOKUP($B2,rf1_data!$B:$B,rf1_data!AP:AP,"NaN"))) -> 2.66 | AY2: =IF(_xlfn.XLOOKUP($B2,rf1_data!$B:$B,rf1_data!AQ:AQ,"NaN")="","NaN",(_xlfn.XLOOKUP($B2,rf1_data!$B:$B,rf1_data!AQ:AQ,"NaN"))) -> 120.1 | AZ2: =IF(_xlfn.XLOOKUP($B2,rf1_data!$B:$B,rf1_data!AR:AR,"NaN")="","NaN",(_xlfn.XLOOKUP($B2,rf1_data!$B:$B,rf1_data!AR:AR,"NaN"))) -> NaN | BA2: =IF(_xlfn.XLOOKUP($B2,rf1_data!$B:$B,rf1_data!AS:AS,"NaN")="","NaN",(_xlfn.XLOOKUP($B2,rf1_data!$B:$B,rf1_data!AS:AS,"NaN"))) -> NaN | BB2: =IF(_xlfn.XLOOKUP($B2,rf1_data!$B:$B,rf1_data!AT:AT,"NaN")="","NaN",(_xlfn.XLOOKUP($B2,rf1_data!$B:$B,rf1_data!AT:AT,"NaN"))) -> NaN | BC2: =IF(_xlfn.XLOOKUP($B2,rf1_data!$B:$B,rf1_data!AU:AU,"NaN")="","NaN",(_xlfn.XLOOKUP($B2,rf1_data!$B:$B,rf1_data!AU:AU,"NaN"))) -> NaN | BD2: =IF(_xlfn.XLOOKUP($B2,rf1_data!$B:$B,rf1_data!AV:AV,"NaN")="","NaN",(_xlfn.XLOOKUP($B2,rf1_data!$B:$B,rf1_data!AV:AV,"NaN"))) -> NaN | BE2: =IF(_xlfn.XLOOKUP($B2,rf1_data!$B:$B,rf1_data!AW:AW,"NaN")="","NaN",(_xlfn.XLOOKUP($B2,rf1_data!$B:$B,rf1_data!AW:AW,"NaN"))) -> NaN | BF2: =IF(_xlfn.XLOOKUP($B2,rf1_data!$B:$B,rf1_data!AX:AX,"NaN")="","NaN",(_xlfn.XLOOKUP($B2,rf1_data!$B:$B,rf1_data!AX:AX,"NaN"))) -> NaN | BG2: =IF(_xlfn.XLOOKUP($B2,rf1_data!$B:$B,rf1_data!AY:AY,"NaN")="","NaN",(_xlfn.XLOOKUP($B2,rf1_data!$B:$B,rf1_data!AY:AY,"NaN"))) -> NaN | BH2: =IF(_xlfn.XLOOKUP($B2,rf1_data!$B:$B,rf1_data!AZ:AZ,"NaN")="","NaN",(_xlfn.XLOOKUP($B2,rf1_data!$B:$B,rf1_data!AZ:AZ,"NaN"))) -> NaN | BI2: =IF(_xlfn.XLOOKUP($B2,rf1_data!$B:$B,rf1_data!BA:BA,"NaN")="","NaN",(_xlfn.XLOOKUP($B2,rf1_data!$B:$B,rf1_data!BA:BA,"NaN"))) -> 20 | BJ2: =IF(_xlfn.XLOOKUP($B2,rf1_data!$B:$B,rf1_data!BB:BB,"NaN")="","NaN",(_xlfn.XLOOKUP($B2,rf1_data!$B:$B,rf1_data!BB:BB,"NaN"))) -> NaN | BK2: =IF(_xlfn.XLOOKUP($B2,rf1_data!$B:$B,rf1_data!BC:BC,"NaN")="","NaN",(_xlfn.XLOOKUP($B2,rf1_data!$B:$B,rf1_data!BC:BC,"NaN"))) -> NaN | BL2: =IF(_xlfn.XLOOKUP($B2,rf1_data!$B:$B,rf1_data!BD:BD,"NaN")="","NaN",(_xlfn.XLOOKUP($B2,rf1_data!$B:$B,rf1_data!BD:BD,"NaN"))) -> NaN | BM2: =IF(_xlfn.XLOOKUP($B2,rf1_data!$B:$B,rf1_data!BE:BE,"NaN")="","NaN",(_xlfn.XLOOKUP($B2,rf1_data!$B:$B,rf1_data!BE:BE,"NaN"))) -> NaN | BN2: =IF(_xlfn.XLOOKUP($B2,rf1_data!$B:$B,rf1_data!BF:BF,"NaN")="","NaN",(_xlfn.XLOOKUP($B2,rf1_data!$B:$B,rf1_data!BF:BF,"NaN"))) -> NaN | BO2: =IF(_xlfn.XLOOKUP($B2,rf1_data!$B:$B,rf1_data!BG:BG,"NaN")="","NaN",(_xlfn.XLOOKUP($B2,rf1_data!$B:$B,rf1_data!BG:BG,"NaN"))) -> NaN | BP2: =IF(_xlfn.XLOOKUP($B2,rf1_data!$B:$B,rf1_data!BH:BH,"NaN")="","NaN",(_xlfn.XLOOKUP($B2,rf1_data!$B:$B,rf1_data!BH:BH,"NaN"))) -> NaN | BQ2: =IF(_xlfn.XLOOKUP($B2,rf1_data!$B:$B,rf1_data!BI:BI,"NaN")="","NaN",(_xlfn.XLOOKUP($B2,rf1_data!$B:$B,rf1_data!BI:BI,"NaN"))) -> NaN | BR2: =IF(_xlfn.XLOOKUP($B2,rf1_data!$B:$B,rf1_data!BJ:BJ,"NaN")="","NaN",(_xlfn.XLOOKUP($B2,rf1_data!$B:$B,rf1_data!BJ:BJ,"NaN"))) -> 8991 | BS2: =IF(_xlfn.XLOOKUP($B2,rf1_data!$B:$B,rf1_data!BK:BK,"NaN")="","NaN",(_xlfn.XLOOKUP($B2,rf1_data!$B:$B,rf1_data!BK:BK,"NaN"))) -> NaN | BT2: =IF(_xlfn.XLOOKUP($B2,rf1_data!$B:$B,rf1_data!BL:BL,"NaN")="","NaN",(_xlfn.XLOOKUP($B2,rf1_data!$B:$B,rf1_data!BL:BL,"NaN"))) -> NaN | BU2: =IF(_xlfn.XLOOKUP($B2,rf1_data!$B:$B,rf1_data!BM:BM,"NaN")="","NaN",(_xlfn.XLOOKUP($B2,rf1_data!$B:$B,rf1_data!BM:BM,"NaN"))) -> NaN | BV2: =IF(_xlfn.XLOOKUP($B2,rf1_data!$B:$B,rf1_data!BN:BN,"NaN")="","NaN",(_xlfn.XLOOKUP($B2,rf1_data!$B:$B,rf1_data!BN:BN,"NaN"))) -> NaN | BW2: =IF(_xlfn.XLOOKUP($B2,rf1_data!$B:$B,rf1_data!BO:BO,"NaN")="","NaN",(_xlfn.XLOOKUP($B2,rf1_data!$B:$B,rf1_data!BO:BO,"NaN"))) -> 4 | BX2: =IF(_xlfn.XLOOKUP($B2,rf1_data!$B:$B,rf1_data!BP:BP,"NaN")="","NaN",(_xlfn.XLOOKUP($B2,rf1_data!$B:$B,rf1_data!BP:BP,"NaN"))) -> 4.4 | BY2: =IF(_xlfn.XLOOKUP($B2,rf1_data!$B:$B,rf1_data!BQ:BQ,"NaN")="","NaN",(_xlfn.XLOOKUP($B2,rf1_data!$B:$B,rf1_data!BQ:BQ,"NaN"))) -> 4.4 | BZ2: =IF(_xlfn.XLOOKUP($B2,rf1_data!$B:$B,rf1_data!BR:BR,"NaN")="","NaN",(_xlfn.XLOOKUP($B2,rf1_data!$B:$B,rf1_data!BR:BR,"NaN"))) -> 4.27 | CA2: =IF(_xlfn.XLOOKUP($B2,rf1_data!$B:$B,rf1_data!BS:BS,"NaN")="","NaN",(_xlfn.XLOOKUP($B2,rf1_data!$B:$B,rf1_data!BS:BS,"NaN"))) -> 6 | CB2: =IF(_xlfn.XLOOKUP($B2,rf1_data!$B:$B,rf1_data!BT:BT,"NaN")="","NaN",(_xlfn.XLOOKUP($B2,rf1_data!$B:$B,rf1_data!BT:BT,"NaN"))) -> 5.1666667 | CC2: =IF(_xlfn.XLOOKUP($B2,rf1_data!$B:$B,rf1_data!BU:BU,"NaN")="","NaN",(_xlfn.XLOOKUP($B2,rf1_data!$B:$B,rf1_data!BU:BU,"NaN"))) -> 6 | CD2: =IF(_xlfn.XLOOKUP($B2,rf1_data!$B:$B,rf1_data!BV:BV,"NaN")="","NaN",(_xlfn.XLOOKUP($B2,rf1_data!$B:$B,rf1_data!BV:BV,"NaN"))) -> 5.1666667 | CE2: =IF(_xlfn.XLOOKUP($B2,rf1_data!$B:$B,rf1_data!BW:BW,"NaN")="","NaN",(_xlfn.XLOOKUP($B2,rf1_data!$B:$B,rf1_data!BW:BW,"NaN"))) -> 2.75 | CF2: =IF(_xlfn.XLOOKUP($B2,rf1_data!$B:$B,rf1_data!BX:BX,"NaN")="","NaN",(_xlfn.XLOOKUP($B2,rf1_data!$B:$B,rf1_data!BX:BX,"NaN"))) -> 0 | CG2: =IF(_xlfn.XLOOKUP($B2,rf1_data!$B:$B,rf1_data!BY:BY,"NaN")="","NaN",(_xlfn.XLOOKUP($B2,rf1_data!$B:$B,rf1_data!BY:BY,"NaN"))) -> 0 | CH2: =IF(_xlfn.XLOOKUP($B2,rf1_data!$B:$B,rf1_data!BZ:BZ,"NaN")="","NaN",(_xlfn.XLOOKUP($B2,rf1_data!$B:$B,rf1_data!BZ:BZ,"NaN"))) -> 28 | CI2: =IF(_xlfn.XLOOKUP($B2,rf1_data!$B:$B,rf1_data!CA:CA,"NaN")="","NaN",(_xlfn.XLOOKUP($B2,rf1_data!$B:$B,rf1_data!CA:CA,"NaN"))) -> 26 | CJ2: =IF(_xlfn.XLOOKUP($B2,rf1_data!$B:$B,rf1_data!CB:CB,"NaN")="","NaN",(_xlfn.XLOOKUP($B2,rf1_data!$B:$B,rf1_data!CB:CB,"NaN"))) -> 12 | CK2: =IF(_xlfn.XLOOKUP($B2,rf1_data!$B:$B,rf1_data!CC:CC,"NaN")="","NaN",(_xlfn.XLOOKUP($B2,rf1_data!$B:$B,rf1_data!CC:CC,"NaN"))) -> 1.2 | CL2: =IF(_xlfn.XLOOKUP($B2,rf1_data!$B:$B,rf1_data!CD:CD,"NaN")=0,"NaN",(_xlfn.XLOOKUP($B2,rf1_data!$B:$B,rf1_data!CD:CD,"NaN"))) -> 40 | CM2: =IF(_xlfn.XLOOKUP($B2,rf1_data!$B:$B,rf1_data!CE:CE,"NaN")="","NaN",(_xlfn.XLOOKUP($B2,rf1_data!$B:$B,rf1_data!CE:CE,"NaN"))) -> 45 | CN2: =IF(_xlfn.XLOOKUP($B2,rf1_data!$B:$B,rf1_data!CF:CF,"NaN")="","NaN",(_xlfn.XLOOKUP($B2,rf1_data!$B:$B,rf1_data!CF:CF,"NaN"))) -> 47 | CO2: =IF(_xlfn.XLOOKUP($B2,rf1_data!$B:$B,rf1_data!CG:CG,"NaN")="","NaN",(_xlfn.XLOOKUP($B2,rf1_data!$B:$B,rf1_data!CG:CG,"NaN"))) -> 26 | CP2: =IF(_xlfn.XLOOKUP($B2,rf1_data!$B:$B,rf1_data!CH:CH,"NaN")=0,"NaN",(_xlfn.XLOOKUP($B2,rf1_data!$B:$B,rf1_data!CH:CH,"NaN"))) -> 29 | CQ2: =IF(_xlfn.XLOOKUP($B2,rf1_data!$B:$B,rf1_data!CI:CI,"NaN")="","NaN",(_xlfn.XLOOKUP($B2,rf1_data!$B:$B,rf1_data!CI:CI,"NaN"))) -> 43 | CR2: =IF(_xlfn.XLOOKUP($B2,rf1_data!$B:$B,rf1_data!CJ:CJ,"NaN")="","NaN",(_xlfn.XLOOKUP($B2,rf1_data!$B:$B,rf1_data!CJ:CJ,"NaN"))) -> 60 | CS2: =IF(_xlfn.XLOOKUP($B2,rf1_data!$B:$B,rf1_data!CK:CK,"NaN")="","NaN",(_xlfn.XLOOKUP($B2,rf1_data!$B:$B,rf1_data!CK:CK,"NaN"))) -> 34 | CT2: =IF(_xlfn.XLOOKUP($B2,rf1_data!$B:$B,rf1_data!CL:CL,"NaN")="","NaN",(_xlfn.XLOOKUP($B2,rf1_data!$B:$B,rf1_data!CL:CL,"NaN"))) -> 60 | CU2: =IF(_xlfn.XLOOKUP($B2,rf1_data!$B:$B,rf1_data!CM:CM,"NaN")="","NaN",(_xlfn.XLOOKUP($B2,rf1_data!$B:$B,rf1_data!CM:CM,"NaN"))) -> 27 | CV2: =IF(_xlfn.XLOOKUP($B2,rf1_data!$B:$B,rf1_data!CN:CN,"NaN")="","NaN",(_xlfn.XLOOKUP($B2,rf1_data!$B:$B,rf1_data!CN:CN,"NaN"))) -> 60 | CW2: =IF(_xlfn.XLOOKUP($B2,rf1_data!$B:$B,rf1_data!CO:CO,"NaN")="","NaN",(_xlfn.XLOOKUP($B2,rf1_data!$B:$B,rf1_data!CO:CO,"NaN"))) -> NaN | CX2: =IF(_xlfn.XLOOKUP($B2,rf1_data!$B:$B,rf1_data!CP:CP,"NaN")="","NaN",(_xlfn.XLOOKUP($B2,rf1_data!$B:$B,rf1_data!CP:CP,"NaN"))) -> NaN | CY2: =IF(_xlfn.XLOOKUP($B2,rf1_data!$B:$B,rf1_data!CQ:CQ,"NaN")="","NaN",(_xlfn.XLOOKUP($B2,rf1_data!$B:$B,rf1_data!CQ:CQ,"NaN"))) -> 3 | CZ2: =IF(_xlfn.XLOOKUP($B2,rf1_data!$B:$B,rf1_data!CR:CR,"NaN")="","NaN",(_xlfn.XLOOKUP($B2,rf1_data!$B:$B,rf1_data!CR:CR,"NaN"))) -> 1 | DA2: =IF(_xlfn.XLOOKUP($B2,rf1_data!$B:$B,rf1_data!CS:CS,"NaN")="","NaN",(_xlfn.XLOOKUP($B2,rf1_data!$B:$B,rf1_data!CS:CS,"NaN"))) -> 2 | DB2: =IF(_xlfn.XLOOKUP($B2,island_data!$B:$B,island_data!H:H,"NaN")="","NaN",_xlfn.XLOOKUP($B2,island_data!$B:$B,island_data!H:H,"NaN")) -> NaN | DC2: =IF(_xlfn.XLOOKUP($B2,island_data!$B:$B,island_data!I:I,"NaN")="","NaN",_xlfn.XLOOKUP($B2,island_data!$B:$B,island_data!I:I,"NaN")) -> NaN | DD2: =IF(_xlfn.XLOOKUP($B2,island_data!$B:$B,island_data!J:J,"NaN")="","NaN",_xlfn.XLOOKUP($B2,island_data!$B:$B,island_data!J:J,"NaN")) -> NaN | DE2: =IF(_xlfn.XLOOKUP($B2,island_data!$B:$B,island_data!K:K,"NaN")="","NaN",_xlfn.XLOOKUP($B2,island_data!$B:$B,island_data!K:K,"NaN")) -> 7 | DF2: =IF(_xlfn.XLOOKUP($B2,island_data!$B:$B,island_data!L:L,"NaN")="","NaN",_xlfn.XLOOKUP($B2,island_data!$B:$B,island_data!L:L,"NaN")) -> NaN | DG2: =IF(_xlfn.XLOOKUP($B2,island_data!$B:$B,island_data!M:M,"NaN")="","NaN",_xlfn.XLOOKUP($B2,island_data!$B:$B,island_data!M:M,"NaN")) -> NaN | DH2: =IF(_xlfn.XLOOKUP($B2,island_data!$B:$B,island_data!N:N,"NaN")="","NaN",_xlfn.XLOOKUP($B2,island_data!$B:$B,island_data!N:N,"NaN")) -> NaN | DI2: =IF(_xlfn.XLOOKUP($B2,island_data!$B:$B,island_data!O:O,"NaN")=999,"NaN",_xlfn.XLOOKUP($B2,island_data!$B:$B,island_data!O:O,"NaN")) -> NaN | DJ2: =IF(_xlfn.XLOOKUP($B2,island_data!$B:$B,island_data!P:P,"NaN")="","NaN",_xlfn.XLOOKUP($B2,island_data!$B:$B,island_data!P:P,"NaN")) -> NaN | DK2: =IF(_xlfn.XLOOKUP($B2,island_data!$B:$B,island_data!Q:Q,"NaN")="","NaN",_xlfn.XLOOKUP($B2,island_data!$B:$B,island_data!Q:Q,"NaN")) -> NaN | DL2: =IF(_xlfn.XLOOKUP($B2,island_data!$B:$B,island_data!R:R,"NaN")=999,"NaN",_xlfn.XLOOKUP($B2,island_data!$B:$B,island_data!R:R,"NaN")) -> NaN | DM2: =IF(_xlfn.XLOOKUP($B2,island_data!$B:$B,island_data!S:S,"NaN")="","NaN",_xlfn.XLOOKUP($B2,island_data!$B:$B,island_data!S:S,"NaN")) -> NaN | DN2: =IF(_xlfn.XLOOKUP($B2,island_data!$B:$B,island_data!T:T,"NaN")="","NaN",_xlfn.XLOOKUP($B2,island_data!$B:$B,island_data!T:T,"NaN")) -> NaN | DO2: =IF(_xlfn.XLOOKUP($B2,island_data!$B:$B,island_data!U:U,"NaN")="","NaN",_xlfn.XLOOKUP($B2,island_data!$B:$B,island_data!U:U,"NaN")) -> 4 | DP2: =IF(_xlfn.XLOOKUP($B2,island_data!$B:$B,island_data!V:V,"NaN")="","NaN",_xlfn.XLOOKUP($B2,island_data!$B:$B,island_data!V:V,"NaN")) -> 0 | DQ2: =IF(_xlfn.XLOOKUP($B2,island_data!$B:$B,island_data!W:W,"NaN")="","NaN",_xlfn.XLOOKUP($B2,island_data!$B:$B,island_data!W:W,"NaN")) -> NaN | DR2: =IF(_xlfn.XLOOKUP($B2,island_data!$B:$B,island_data!X:X,"NaN")="","NaN",_xlfn.XLOOKUP($B2,island_data!$B:$B,island_data!X:X,"NaN")) -> 4 | DS2: =IF(_xlfn.XLOOKUP($B2,island_data!$B:$B,island_data!Y:Y,"NaN")="","NaN",_xlfn.XLOOKUP($B2,island_data!$B:$B,island_data!Y:Y,"NaN")) -> NaN | DT2: =IF(_xlfn.XLOOKUP($B2,island_data!$B:$B,island_data!Z:Z,"NaN")="","NaN",_xlfn.XLOOKUP($B2,island_data!$B:$B,island_data!Z:Z,"NaN")) -> NaN | DU2: =IF(_xlfn.XLOOKUP($B2,island_data!$B:$B,island_data!AA:AA,"NaN")="","NaN",_xlfn.XLOOKUP($B2,island_data!$B:$B,island_data!AA:AA,"NaN")) -> NaN | DV2: =IF(_xlfn.XLOOKUP($B2,island_data!$B:$B,island_data!AB:AB,"NaN")="","NaN",_xlfn.XLOOKUP($B2,island_data!$B:$B,island_data!AB:AB,"NaN")) -> 0 | DW2: =IF(_xlfn.XLOOKUP($B2,island_data!$B:$B,island_data!AC:AC,"NaN")="","NaN",_xlfn.XLOOKUP($B2,island_data!$B:$B,island_data!AC:AC,"NaN")) -> 19810 | DX2: =IF(_xlfn.XLOOKUP($B2,island_data!$B:$B,island_data!AD:AD,"NaN")="","NaN",_xlfn.XLOOKUP($B2,island_data!$B:$B,island_data!AD:AD,"NaN")) -> NaN | DY2: =IF(_xlfn.XLOOKUP($B2,island_data!$B:$B,island_data!AE:AE,"NaN")="","NaN",_xlfn.XLOOKUP($B2,island_data!$B:$B,island_data!AE:AE,"NaN")) -> 1 | DZ2: =IF(_xlfn.XLOOKUP($B2,island_data!$B:$B,island_data!AF:AF,"NaN")="","NaN",_xlfn.XLOOKUP($B2,island_data!$B:$B,island_data!AF:AF,"NaN")) -> NaN | EA2: =IF(_xlfn.XLOOKUP($B2,island_data!$B:$B,island_data!AG:AG,"NaN")="","NaN",_xlfn.XLOOKUP($B2,island_data!$B:$B,island_data!AG:AG,"NaN")) -> NaN | EB2: =IF(_xlfn.XLOOKUP($B2,island_data!$B:$B,island_data!AH:AH,"NaN")="","NaN",_xlfn.XLOOKUP($B2,island_data!$B:$B,island_data!AH:AH,"NaN")) -> NaN | EC2: =IF(_xlfn.XLOOKUP($B2,island_data!$B:$B,island_data!AI:AI,"NaN")="","NaN",_xlfn.XLOOKUP($B2,island_data!$B:$B,island_data!AI:AI,"NaN")) -> NaN | ED2: =IF(_xlfn.XLOOKUP($B2,island_data!$B:$B,island_data!AJ:AJ,"NaN")="","NaN",_xlfn.XLOOKUP($B2,island_data!$B:$B,island_data!AJ:AJ,"NaN")) -> NaN | EE2: =IF(_xlfn.XLOOKUP($B2,island_data!$B:$B,island_data!AK:AK,"NaN")="","NaN",_xlfn.XLOOKUP($B2,island_data!$B:$B,island_data!AK:AK,"NaN")) -> NaN | EF2: =IF(_xlfn.XLOOKUP($B2,island_data!$B:$B,island_data!AL:AL,"NaN")="","NaN",_xlfn.XLOOKUP($B2,island_data!$B:$B,island_data!AL:AL,"NaN")) -> NaN | EG2: =IF(_xlfn.XLOOKUP($B2,island_data!$B:$B,island_data!AM:AM,"NaN")="","NaN",_xlfn.XLOOKUP($B2,island_data!$B:$B,island_data!AM:AM,"NaN")) -> NaN | EH2: =IF(_xlfn.XLOOKUP($B2,island_data!$B:$B,island_data!AN:AN,"NaN")="","NaN",_xlfn.XLOOKUP($B2,island_data!$B:$B,island_data!AN:AN,"NaN")) -> NaN | EI2: =IF(_xlfn.XLOOKUP($B2,island_data!$B:$B,island_data!AO:AO,"NaN")="","NaN",_xlfn.XLOOKUP($B2,island_data!$B:$B,island_data!AO:AO,"NaN")) -> NaN | EJ2: =IF(_xlfn.XLOOKUP($A2,TabCAT!$A:$A,TabCAT!AU:AU,"NaN")="","NaN",(_xlfn.XLOOKUP($A2,TabCAT!$A:$A,TabCAT!AU:AU,"NaN"))) -> 217 | EK2: =IF(_xlfn.XLOOKUP($A2,TabCAT!$A:$A,TabCAT!AV:AV,"NaN")="","NaN",(_xlfn.XLOOKUP($A2,TabCAT!$A:$A,TabCAT!AV:AV,"NaN"))) -> TRUE | EL2: =IF(_xlfn.XLOOKUP($A2,TabCAT!$A:$A,TabCAT!AW:AW,"NaN")="","NaN",(_xlfn.XLOOKUP($A2,TabCAT!$A:$A,TabCAT!AW:AW,"NaN"))) -> 4 | EM2: =IF(_xlfn.XLOOKUP($A2,TabCAT!$A:$A,TabCAT!AX:AX,"NaN")="","NaN",(_xlfn.XLOOKUP($A2,TabCAT!$A:$A,TabCAT!AX:AX,"NaN"))) -> 6 | EN2: =IF(_xlfn.XLOOKUP($A2,TabCAT!$A:$A,TabCAT!AY:AY,"NaN")="","NaN",(_xlfn.XLOOKUP($A2,TabCAT!$A:$A,TabCAT!AY:AY,"NaN"))) -> 7.4 | EO2: =IF(_xlfn.XLOOKUP($A2,TabCAT!$A:$A,TabCAT!AZ:AZ,"NaN")="","NaN",(_xlfn.XLOOKUP($A2,TabCAT!$A:$A,TabCAT!AZ:AZ,"NaN"))) -> 32 | EP2: =IF(_xlfn.XLOOKUP($A2,TabCAT!$A:$A,TabCAT!BA:BA,"NaN")="","NaN",(_xlfn.XLOOKUP($A2,TabCAT!$A:$A,TabCAT!BA:BA,"NaN"))) -> 0.8041145 | EQ2: =IF(_xlfn.XLOOKUP($A2,TabCAT!$A:$A,TabCAT!BB:BB,"NaN")="","NaN",(_xlfn.XLOOKUP($A2,TabCAT!$A:$A,TabCAT!BB:BB,"NaN"))) -> 0.28349804 | ER2: =IF(_xlfn.XLOOKUP($A2,TabCAT!$A:$A,TabCAT!BC:BC,"NaN")="","NaN",(_xlfn.XLOOKUP($A2,TabCAT!$A:$A,TabCAT!BC:BC,"NaN"))) -> 16 | ES2: =IF(_xlfn.XLOOKUP($A2,TabCAT!$A:$A,TabCAT!BD:BD,"NaN")="","NaN",(_xlfn.XLOOKUP($A2,TabCAT!$A:$A,TabCAT!BD:BD,"NaN"))) -> 0.737505 | ET2: =IF(_xlfn.XLOOKUP($A2,TabCAT!$A:$A,TabCAT!BE:BE,"NaN")="","NaN",(_xlfn.XLOOKUP($A2,TabCAT!$A:$A,TabCAT!BE:BE,"NaN"))) -> 16 | EU2: =IF(_xlfn.XLOOKUP($A2,TabCAT!$A:$A,TabCAT!BF:BF,"NaN")="","NaN",(_xlfn.XLOOKUP($A2,TabCAT!$A:$A,TabCAT!BF:BF,"NaN"))) -> 1.0709495 | EV2: =IF(_xlfn.XLOOKUP($A2,TabCAT!$A:$A,TabCAT!BG:BG,"NaN")="","NaN",(_xlfn.XLOOKUP($A2,TabCAT!$A:$A,TabCAT!BG:BG,"NaN"))) -> NaN | EW2: =IF(_xlfn.XLOOKUP($A2,TabCAT!$A:$A,TabCAT!BH:BH,"NaN")="","NaN",(_xlfn.XLOOKUP($A2,TabCAT!$A:$A,TabCAT!BH:BH,"NaN"))) -> 3.0.0 | EX2: =IF(_xlfn.XLOOKUP($A2,TabCAT!$A:$A,TabCAT!BI:BI,"NaN")="","NaN",(_xlfn.XLOOKUP($A2,TabCAT!$A:$A,TabCAT!BI:BI,"NaN"))) -> English | EY2: =IF(_xlfn.XLOOKUP($A2,TabCAT!$A:$A,TabCAT!BJ:BJ,"NaN")="","NaN",(_xlfn.XLOOKUP($A2,TabCAT!$A:$A,TabCAT!BJ:BJ,"NaN"))) -> 234 | EZ2: =IF(_xlfn.XLOOKUP($A2,TabCAT!$A:$A,TabCAT!BK:BK,"NaN")="","NaN",(_xlfn.XLOOKUP($A2,TabCAT!$A:$A,TabCAT!BK:BK,"NaN"))) -> 1 | FA2: =IF(_xlfn.XLOOKUP($A2,TabCAT!$A:$A,TabCAT!BL:BL,"NaN")="","NaN",(_xlfn.XLOOKUP($A2,TabCAT!$A:$A,TabCAT!BL:BL,"NaN"))) -> 6 | FB2: =IF(_xlfn.XLOOKUP($A2,TabCAT!$A:$A,TabCAT!BM:BM,"NaN")="","NaN",(_xlfn.XLOOKUP($A2,TabCAT!$A:$A,TabCAT!BM:BM,"NaN"))) -> 1 | FC2: =IF(_xlfn.XLOOKUP($A2,TabCAT!$A:$A,TabCAT!BN:BN,"NaN")="","NaN",(_xlfn.XLOOKUP($A2,TabCAT!$A:$A,TabCAT!BN:BN,"NaN"))) -> 6 | FD2: =IF(_xlfn.XLOOKUP($A2,TabCAT!$A:$A,TabCAT!BO:BO,"NaN")="","NaN",(_xlfn.XLOOKUP($A2,TabCAT!$A:$A,TabCAT!BO:BO,"NaN"))) -> 9 | FE2: =IF(_xlfn.XLOOKUP($A2,TabCAT!$A:$A,TabCAT!BP:BP,"NaN")="","NaN",(_xlfn.XLOOKUP($A2,TabCAT!$A:$A,TabCAT!BP:BP,"NaN"))) -> 1 | FF2: =IF(_xlfn.XLOOKUP($A2,TabCAT!$A:$A,TabCAT!BQ:BQ,"NaN")="","NaN",(_xlfn.XLOOKUP($A2,TabCAT!$A:$A,TabCAT!BQ:BQ,"NaN"))) -> 9 | FG2: =IF(_xlfn.XLOOKUP($A2,TabCAT!$A:$A,TabCAT!BR:BR,"NaN")="","NaN",(_xlfn.XLOOKUP($A2,TabCAT!$A:$A,TabCAT!BR:BR,"NaN"))) -> 10 | FH2: =IF(_xlfn.XLOOKUP($A2,TabCAT!$A:$A,TabCAT!BS:BS,"NaN")="","NaN",(_xlfn.XLOOKUP($A2,TabCAT!$A:$A,TabCAT!BS:BS,"NaN"))) -> 0.83333333 | FI2: =IF(_xlfn.XLOOKUP($A2,TabCAT!$A:$A,TabCAT!BT:BT,"NaN")="","NaN",(_xlfn.XLOOKUP($A2,TabCAT!$A:$A,TabCAT!BT:BT,"NaN"))) -> 10 | FJ2: =IF(_xlfn.XLOOKUP($A2,TabCAT!$A:$A,TabCAT!BU:BU,"NaN")="","NaN",(_xlfn.XLOOKUP($A2,TabCAT!$A:$A,TabCAT!BU:BU,"NaN"))) -> 11 | FK2: =IF(_xlfn.XLOOKUP($A2,TabCAT!$A:$A,TabCAT!BV:BV,"NaN")="","NaN",(_xlfn.XLOOKUP($A2,TabCAT!$A:$A,TabCAT!BV:BV,"NaN"))) -> 0.73333333 | FL2: =IF(_xlfn.XLOOKUP($A2,TabCAT!$A:$A,TabCAT!BW:BW,"NaN")="","NaN",(_xlfn.XLOOKUP($A2,TabCAT!$A:$A,TabCAT!BW:BW,"NaN"))) -> 8.5 | FM2: =IF(_xlfn.XLOOKUP($A2,TabCAT!$A:$A,TabCAT!BX:BX,"NaN")="","NaN",(_xlfn.XLOOKUP($A2,TabCAT!$A:$A,TabCAT!BX:BX,"NaN"))) -> 36 | FN2: =IF(_xlfn.XLOOKUP($A2,TabCAT!$A:$A,TabCAT!BY:BY,"NaN")="","NaN",(_xlfn.XLOOKUP($A2,TabCAT!$A:$A,TabCAT!BY:BY,"NaN"))) -> 0.85714286 | FO2: =IF(_xlfn.XLOOKUP($A2,TabCAT!$A:$A,TabCAT!BZ:BZ,"NaN")="","NaN",(_xlfn.XLOOKUP($A2,TabCAT!$A:$A,TabCAT!BZ:BZ,"NaN"))) -> 33.5 | FP2: =IF(_xlfn.XLOOKUP($A2,TabCAT!$A:$A,TabCAT!CA:CA,"NaN")="","NaN",(_xlfn.XLOOKUP($A2,TabCAT!$A:$A,TabCAT!CA:CA,"NaN"))) -> 3.0.0 | FQ2: =IF(_xlfn.XLOOKUP($A2,TabCAT!$A:$A,TabCAT!CB:CB,"NaN")="","NaN",(_xlfn.XLOOKUP($A2,TabCAT!$A:$A,TabCAT!CB:CB,"NaN"))) -> English | FR2: =IF(_xlfn.XLOOKUP($A2,TabCAT!$A:$A,TabCAT!CC:CC,"NaN")="","NaN",(_xlfn.XLOOKUP($A2,TabCAT!$A:$A,TabCAT!CC:CC,"NaN"))) -> 235 | FS2: =IF(_xlfn.XLOOKUP($A2,TabCAT!$A:$A,TabCAT!CD:CD,"NaN")="","NaN",(_xlfn.XLOOKUP($A2,TabCAT!$A:$A,TabCAT!CD:CD,"NaN"))) -> TRUE | FT2: =IF(_xlfn.XLOOKUP($A2,TabCAT!$A:$A,TabCAT!CE:CE,"NaN")="","NaN",(_xlfn.XLOOKUP($A2,TabCAT!$A:$A,TabCAT!CE:CE,"NaN"))) -> 8 | FU2: =IF(_xlfn.XLOOKUP($A2,TabCAT!$A:$A,TabCAT!CF:CF,"NaN")="","NaN",(_xlfn.XLOOKUP($A2,TabCAT!$A:$A,TabCAT!CF:CF,"NaN"))) -> 0 | FV2: =IF(_xlfn.XLOOKUP($A2,TabCAT!$A:$A,TabCAT!CG:CG,"NaN")="","NaN",(_xlfn.XLOOKUP($A2,TabCAT!$A:$A,TabCAT!CG:CG,"NaN"))) -> 7.54 | FW2: =IF(_xlfn.XLOOKUP($A2,TabCAT!$A:$A,TabCAT!CH:CH,"NaN")="","NaN",(_xlfn.XLOOKUP($A2,TabCAT!$A:$A,TabCAT!CH:CH,"NaN"))) -> 16 | FX2: =IF(_xlfn.XLOOKUP($A2,TabCAT!$A:$A,TabCAT!CI:CI,"NaN")="","NaN",(_xlfn.XLOOKUP($A2,TabCAT!$A:$A,TabCAT!CI:CI,"NaN"))) -> 0.66297 | FY2: =IF(_xlfn.XLOOKUP($A2,TabCAT!$A:$A,TabCAT!CJ:CJ,"NaN")="","NaN",(_xlfn.XLOOKUP($A2,TabCAT!$A:$A,TabCAT!CJ:CJ,"NaN"))) -> 16 | FZ2: =IF(_xlfn.XLOOKUP($A2,TabCAT!$A:$A,TabCAT!CK:CK,"NaN")="","NaN",(_xlfn.XLOOKUP($A2,TabCAT!$A:$A,TabCAT!CK:CK,"NaN"))) -> 0.5922435 | GA2: =IF(_xlfn.XLOOKUP($A2,TabCAT!$A:$A,TabCAT!CL:CL,"NaN")="","NaN",(_xlfn.XLOOKUP($A2,TabCAT!$A:$A,TabCAT!CL:CL,"NaN"))) -> 31 | GB2: =IF(_xlfn.XLOOKUP($A2,TabCAT!$A:$A,TabCAT!CM:CM,"NaN")="","NaN",(_xlfn.XLOOKUP($A2,TabCAT!$A:$A,TabCAT!CM:CM,"NaN"))) -> 0.904475 | GC2: =IF(_xlfn.XLOOKUP($A2,TabCAT!$A:$A,TabCAT!CN:CN,"NaN")="","NaN",(_xlfn.XLOOKUP($A2,TabCAT!$A:$A,TabCAT!CN:CN,"NaN"))) -> 18 | GD2: =IF(_xlfn.XLOOKUP($A2,TabCAT!$A:$A,TabCAT!CO:CO,"NaN")="","NaN",(_xlfn.XLOOKUP($A2,TabCAT!$A:$A,TabCAT!CO:CO,"NaN"))) -> 0.8671765 | GE2: =IF(_xlfn.XLOOKUP($A2,TabCAT!$A:$A,TabCAT!CP:CP,"NaN")="","NaN",(_xlfn.XLOOKUP($A2,TabCAT!$A:$A,TabCAT!CP:CP,"NaN"))) -> 0.23794223 | GF2: =IF(_xlfn.XLOOKUP($A2,TabCAT!$A:$A,TabCAT!CQ:CQ,"NaN")="","NaN",(_xlfn.XLOOKUP($A2,TabCAT!$A:$A,TabCAT!CQ:CQ,"NaN"))) -> 55 | GG2: =IF(_xlfn.XLOOKUP($A2,TabCAT!$A:$A,TabCAT!CR:CR,"NaN")="","NaN",(_xlfn.XLOOKUP($A2,TabCAT!$A:$A,TabCAT!CR:CR,"NaN"))) -> 0.729848 | GH2: =IF(_xlfn.XLOOKUP($A2,TabCAT!$A:$A,TabCAT!CS:CS,"NaN")="","NaN",(_xlfn.XLOOKUP($A2,TabCAT!$A:$A,TabCAT!CS:CS,"NaN"))) -> NaN
A3: 10369 | B3: =_xlfn.XLOOKUP(bippity_poppity_boo!A3,rf1_data!A:A,rf1_data!B:B) -> 30791 | C3: =(_xlfn.XLOOKUP($A3,trust!$A:$A,trust!B:B,"NaN")) -> 4.5 | D3: =(_xlfn.XLOOKUP($A3,trust!$A:$A,trust!C:C,"NaN")) -> 4.285714 | E3: =(_xlfn.XLOOKUP($A3,trust!$A:$A,trust!D:D,"NaN")) -> 3 | F3: =(_xlfn.XLOOKUP($A3,trust!$A:$A,trust!E:E,"NaN")) -> 4.8 | G3: =(_xlfn.XLOOKUP($A3,trust!$A:$A,trust!F:F,"NaN")) -> 5.428571 | H3: =(_xlfn.XLOOKUP($A3,trust!$A:$A,trust!G:G,"NaN")) -> 4.666667 | I3: =IF(_xlfn.XLOOKUP($B3,island_data!$B:$B,island_data!C:C,"NaN")="","NaN",_xlfn.XLOOKUP($B3,island_data!$B:$B,island_data!C:C,"NaN")) -> 45105 | J3: =IF(_xlfn.XLOOKUP($B3,island_data!$B:$B,island_data!D:D,"NaN")="","NaN",_xlfn.XLOOKUP($B3,island_data!$B:$B,island_data!D:D,"NaN")) -> 33288 | K3: =IF(_xlfn.XLOOKUP($B3,island_data!$B:$B,island_data!E:E,"NaN")="","NaN",_xlfn.XLOOKUP($B3,island_data!$B:$B,island_data!E:E,"NaN")) -> 32.35 | L3: =IF(_xlfn.XLOOKUP($B3,rf1_data!$B:$B,rf1_data!D:D,"NaN")="","NaN",(_xlfn.XLOOKUP($B3,rf1_data!$B:$B,rf1_data!D:D,"NaN"))) -> 31.95 | M3: =IF(_xlfn.XLOOKUP($B3,rf1_data!$B:$B,rf1_data!E:E,"NaN")="","NaN",(_xlfn.XLOOKUP($B3,rf1_data!$B:$B,rf1_data!E:E,"NaN"))) -> White | N3: =IF(_xlfn.XLOOKUP($B3,rf1_data!$B:$B,rf1_data!F:F,"NaN")="","NaN",(_xlfn.XLOOKUP($B3,rf1_data!$B:$B,rf1_data!F:F,"NaN"))) -> Not Hispanic or Latino | O3: =IF(_xlfn.XLOOKUP($B3,rf1_data!$B:$B,rf1_data!G:G,"NaN")="","NaN",(_xlfn.XLOOKUP($B3,rf1_data!$B:$B,rf1_data!G:G,"NaN"))) -> Male | P3: =IF(_xlfn.XLOOKUP($B3,rf1_data!$B:$B,rf1_data!H:H,"NaN")="","NaN",(_xlfn.XLOOKUP($B3,rf1_data!$B:$B,rf1_data!H:H,"NaN"))) -> 4.56 | Q3: =IF(_xlfn.XLOOKUP($B3,rf1_data!$B:$B,rf1_data!I:I,"NaN")="","NaN",(_xlfn.XLOOKUP($B3,rf1_data!$B:$B,rf1_data!I:I,"NaN"))) -> 3.44 | R3: =IF(_xlfn.XLOOKUP($B3,rf1_data!$B:$B,rf1_data!J:J,"NaN")="","NaN",(_xlfn.XLOOKUP($B3,rf1_data!$B:$B,rf1_data!J:J,"NaN"))) -> 0 | S3: =IF(_xlfn.XLOOKUP($B3,rf1_data!$B:$B,rf1_data!K:K,"NaN")="","NaN",(_xlfn.XLOOKUP($B3,rf1_data!$B:$B,rf1_data!K:K,"NaN"))) -> 8 | T3: =IF(_xlfn.XLOOKUP($B3,rf1_data!$B:$B,rf1_data!L:L,"NaN")="","NaN",(_xlfn.XLOOKUP($B3,rf1_data!$B:$B,rf1_data!L:L,"NaN"))) -> 1 | U3: =IF(_xlfn.XLOOKUP($B3,rf1_data!$B:$B,rf1_data!M:M,"NaN")="","NaN",(_xlfn.XLOOKUP($B3,rf1_data!$B:$B,rf1_data!M:M,"NaN"))) -> 3.5 | V3: =IF(_xlfn.XLOOKUP($B3,rf1_data!$B:$B,rf1_data!N:N,"NaN")="","NaN",(_xlfn.XLOOKUP($B3,rf1_data!$B:$B,rf1_data!N:N,"NaN"))) -> 3.83 | W3: =IF(_xlfn.XLOOKUP($B3,rf1_data!$B:$B,rf1_data!O:O,"NaN")="","NaN",(_xlfn.XLOOKUP($B3,rf1_data!$B:$B,rf1_data!O:O,"NaN"))) -> 5.13 | X3: =IF(_xlfn.XLOOKUP($B3,rf1_data!$B:$B,rf1_data!P:P,"NaN")="","NaN",(_xlfn.XLOOKUP($B3,rf1_data!$B:$B,rf1_data!P:P,"NaN"))) -> 4.67 | Y3: =IF(_xlfn.XLOOKUP($B3,rf1_data!$B:$B,rf1_data!Q:Q,"NaN")="","NaN",(_xlfn.XLOOKUP($B3,rf1_data!$B:$B,rf1_data!Q:Q,"NaN"))) -> 4.3 | Z3: =IF(_xlfn.XLOOKUP($B3,rf1_data!$B:$B,rf1_data!R:R,"NaN")="","NaN",(_xlfn.XLOOKUP($B3,rf1_data!$B:$B,rf1_data!R:R,"NaN"))) -> 18 | AA3: =IF(_xlfn.XLOOKUP($B3,rf1_data!$B:$B,rf1_data!S:S,"NaN")="","NaN",(_xlfn.XLOOKUP($B3,rf1_data!$B:$B,rf1_data!S:S,"NaN"))) -> 5 | AB3: =IF(_xlfn.XLOOKUP($B3,rf1_data!$B:$B,rf1_data!T:T,"NaN")="","NaN",(_xlfn.XLOOKUP($B3,rf1_data!$B:$B,rf1_data!T:T,"NaN"))) -> 10 | AC3: =IF(_xlfn.XLOOKUP($B3,rf1_data!$B:$B,rf1_data!U:U,"NaN")="","NaN",(_xlfn.XLOOKUP($B3,rf1_data!$B:$B,rf1_data!U:U,"NaN"))) -> 0 | AD3: =IF(_xlfn.XLOOKUP($B3,rf1_data!$B:$B,rf1_data!V:V,"NaN")="","NaN",(_xlfn.XLOOKUP($B3,rf1_data!$B:$B,rf1_data!V:V,"NaN"))) -> 3 | AE3: =IF(_xlfn.XLOOKUP($B3,rf1_data!$B:$B,rf1_data!W:W,"NaN")="","NaN",(_xlfn.XLOOKUP($B3,rf1_data!$B:$B,rf1_data!W:W,"NaN"))) -> 2 | AF3: =IF(_xlfn.XLOOKUP($B3,rf1_data!$B:$B,rf1_data!X:X,"NaN")="","NaN",(_xlfn.XLOOKUP($B3,rf1_data!$B:$B,rf1_data!X:X,"NaN"))) -> 7 | AG3: =IF(_xlfn.XLOOKUP($B3,rf1_data!$B:$B,rf1_data!Y:Y,"NaN")="","NaN",(_xlfn.XLOOKUP($B3,rf1_data!$B:$B,rf1_data!Y:Y,"NaN"))) -> 5 | AH3: =IF(_xlfn.XLOOKUP($B3,rf1_data!$B:$B,rf1_data!Z:Z,"NaN")="","NaN",(_xlfn.XLOOKUP($B3,rf1_data!$B:$B,rf1_data!Z:Z,"NaN"))) -> 5 | AI3: =IF(_xlfn.XLOOKUP($B3,rf1_data!$B:$B,rf1_data!AA:AA,"NaN")="","NaN",(_xlfn.XLOOKUP($B3,rf1_data!$B:$B,rf1_data!AA:AA,"NaN"))) -> 2 | AJ3: =IF(_xlfn.XLOOKUP($B3,rf1_data!$B:$B,rf1_data!AB:AB,"NaN")="","NaN",(_xlfn.XLOOKUP($B3,rf1_data!$B:$B,rf1_data!AB:AB,"NaN"))) -> 21 | AK3: =IF(_xlfn.XLOOKUP($B3,rf1_data!$B:$B,rf1_data!AC:AC,"NaN")="","NaN",(_xlfn.XLOOKUP($B3,rf1_data!$B:$B,rf1_data!AC:AC,"NaN"))) -> 26 | AL3: =IF(_xlfn.XLOOKUP($B3,rf1_data!$B:$B,rf1_data!AD:AD,"NaN")="","NaN",(_xlfn.XLOOKUP($B3,rf1_data!$B:$B,rf1_data!AD:AD,"NaN"))) -> 10 | AM3: =IF(_xlfn.XLOOKUP($B3,rf1_data!$B:$B,rf1_data!AE:AE,"NaN")="","NaN",(_xlfn.XLOOKUP($B3,rf1_data!$B:$B,rf1_data!AE:AE,"NaN"))) -> 0 | AN3: =IF(_xlfn.XLOOKUP($B3,rf1_data!$B:$B,rf1_data!AF:AF,"NaN")="","NaN",(_xlfn.XLOOKUP($B3,rf1_data!$B:$B,rf1_data!AF:AF,"NaN"))) -> 0 | AO3: =IF(_xlfn.XLOOKUP($B3,rf1_data!$B:$B,rf1_data!AG:AG,"NaN")="","NaN",(_xlfn.XLOOKUP($B3,rf1_data!$B:$B,rf1_data!AG:AG,"NaN"))) -> NaN | AP3: =IF(_xlfn.XLOOKUP($B3,rf1_data!$B:$B,rf1_data!AH:AH,"NaN")="","NaN",(_xlfn.XLOOKUP($B3,rf1_data!$B:$B,rf1_data!AH:AH,"NaN"))) -> NaN | AQ3: =IF(_xlfn.XLOOKUP($B3,rf1_data!$B:$B,rf1_data!AI:AI,"NaN")="","NaN",(_xlfn.XLOOKUP($B3,rf1_data!$B:$B,rf1_data!AI:AI,"NaN"))) -> NaN | AR3: =IF(_xlfn.XLOOKUP($B3,rf1_data!$B:$B,rf1_data!AJ:AJ,"NaN")="","NaN",(_xlfn.XLOOKUP($B3,rf1_data!$B:$B,rf1_data!AJ:AJ,"NaN"))) -> NaN | AS3: =IF(_xlfn.XLOOKUP($B3,rf1_data!$B:$B,rf1_data!AK:AK,"NaN")="","NaN",(_xlfn.XLOOKUP($B3,rf1_data!$B:$B,rf1_data!AK:AK,"NaN"))) -> 2.7 | AT3: =IF(_xlfn.XLOOKUP($B3,rf1_data!$B:$B,rf1_data!AL:AL,"NaN")="","NaN",(_xlfn.XLOOKUP($B3,rf1_data!$B:$B,rf1_data!AL:AL,"NaN"))) -> 13 | AU3: =IF(_xlfn.XLOOKUP($B3,rf1_data!$B:$B,rf1_data!AM:AM,"NaN")="","NaN",(_xlfn.XLOOKUP($B3,rf1_data!$B:$B,rf1_data!AM:AM,"NaN"))) -> 2.25 | AV3: =IF(_xlfn.XLOOKUP($B3,rf1_data!$B:$B,rf1_data!AN:AN,"NaN")="","NaN",(_xlfn.XLOOKUP($B3,rf1_data!$B:$B,rf1_data!AN:AN,"NaN"))) -> 0 | AW3: =IF(_xlfn.XLOOKUP($B3,rf1_data!$B:$B,rf1_data!AO:AO,"NaN")="","NaN",(_xlfn.XLOOKUP($B3,rf1_data!$B:$B,rf1_data!AO:AO,"NaN"))) -> NaN | AX3: =IF(_xlfn.XLOOKUP($B3,rf1_data!$B:$B,rf1_data!AP:AP,"NaN")="","NaN",(_xlfn.XLOOKUP($B3,rf1_data!$B:$B,rf1_data!AP:AP,"NaN"))) -> 2.63 | AY3: =IF(_xlfn.XLOOKUP($B3,rf1_data!$B:$B,rf1_data!AQ:AQ,"NaN")="","NaN",(_xlfn.XLOOKUP($B3,rf1_data!$B:$B,rf1_data!AQ:AQ,"NaN"))) -> 44.05 | AZ3: =IF(_xlfn.XLOOKUP($B3,rf1_data!$B:$B,rf1_data!AR:AR,"NaN")="","NaN",(_xlfn.XLOOKUP($B3,rf1_data!$B:$B,rf1_data!AR:AR,"NaN"))) -> NaN | BA3: =IF(_xlfn.XLOOKUP($B3,rf1_data!$B:$B,rf1_data!AS:AS,"NaN")="","NaN",(_xlfn.XLOOKUP($B3,rf1_data!$B:$B,rf1_data!AS:AS,"NaN"))) -> NaN | BB3: =IF(_xlfn.XLOOKUP($B3,rf1_data!$B:$B,rf1_data!AT:AT,"NaN")="","NaN",(_xlfn.XLOOKUP($B3,rf1_data!$B:$B,rf1_data!AT:AT,"NaN"))) -> NaN | BC3: =IF(_xlfn.XLOOKUP($B3,rf1_data!$B:$B,rf1_data!AU:AU,"NaN")="","NaN",(_xlfn.XLOOKUP($B3,rf1_data!$B:$B,rf1_data!AU:AU,"NaN"))) -> NaN | BD3: =IF(_xlfn.XLOOKUP($B3,rf1_data!$B:$B,rf1_data!AV:AV,"NaN")="","NaN",(_xlfn.XLOOKUP($B3,rf1_data!$B:$B,rf1_data!AV:AV,"NaN"))) -> NaN | BE3: =IF(_xlfn.XLOOKUP($B3,rf1_data!$B:$B,rf1_data!AW:AW,"NaN")="","NaN",(_xlfn.XLOOKUP($B3,rf1_data!$B:$B,rf1_data!AW:AW,"NaN"))) -> NaN | BF3: =IF(_xlfn.XLOOKUP($B3,rf1_data!$B:$B,rf1_data!AX:AX,"NaN")="","NaN",(_xlfn.XLOOKUP($B3,rf1_data!$B:$B,rf1_data!AX:AX,"NaN"))) -> NaN | BG3: =IF(_xlfn.XLOOKUP($B3,rf1_data!$B:$B,rf1_data!AY:AY,"NaN")="","NaN",(_xlfn.XLOOKUP($B3,rf1_data!$B:$B,rf1_data!AY:AY,"NaN"))) -> NaN | BH3: =IF(_xlfn.XLOOKUP($B3,rf1_data!$B:$B,rf1_data!AZ:AZ,"NaN")="","NaN",(_xlfn.XLOOKUP($B3,rf1_data!$B:$B,rf1_data!AZ:AZ,"NaN"))) -> NaN | BI3: =IF(_xlfn.XLOOKUP($B3,rf1_data!$B:$B,rf1_data!BA:BA,"NaN")="","NaN",(_xlfn.XLOOKUP($B3,rf1_data!$B:$B,rf1_data!BA:BA,"NaN"))) -> 20 | BJ3: =IF(_xlfn.XLOOKUP($B3,rf1_data!$B:$B,rf1_data!BB:BB,"NaN")="","NaN",(_xlfn.XLOOKUP($B3,rf1_data!$B:$B,rf1_data!BB:BB,"NaN"))) -> NaN | BK3: =IF(_xlfn.XLOOKUP($B3,rf1_data!$B:$B,rf1_data!BC:BC,"NaN")="","NaN",(_xlfn.XLOOKUP($B3,rf1_data!$B:$B,rf1_data!BC:BC,"NaN"))) -> NaN | BL3: =IF(_xlfn.XLOOKUP($B3,rf1_data!$B:$B,rf1_data!BD:BD,"NaN")="","NaN",(_xlfn.XLOOKUP($B3,rf1_data!$B:$B,rf1_data!BD:BD,"NaN"))) -> NaN | BM3: =IF(_xlfn.XLOOKUP($B3,rf1_data!$B:$B,rf1_data!BE:BE,"NaN")="","NaN",(_xlfn.XLOOKUP($B3,rf1_data!$B:$B,rf1_data!BE:BE,"NaN"))) -> NaN | BN3: =IF(_xlfn.XLOOKUP($B3,rf1_data!$B:$B,rf1_data!BF:BF,"NaN")="","NaN",(_xlfn.XLOOKUP($B3,rf1_data!$B:$B,rf1_data!BF:BF,"NaN"))) -> NaN | BO3: =IF(_xlfn.XLOOKUP($B3,rf1_data!$B:$B,rf1_data!BG:BG,"NaN")="","NaN",(_xlfn.XLOOKUP($B3,rf1_data!$B:$B,rf1_data!BG:BG,"NaN"))) -> NaN | BP3: =IF(_xlfn.XLOOKUP($B3,rf1_data!$B:$B,rf1_data!BH:BH,"NaN")="","NaN",(_xlfn.XLOOKUP($B3,rf1_data!$B:$B,rf1_data!BH:BH,"NaN"))) -> NaN | BQ3: =IF(_xlfn.XLOOKUP($B3,rf1_data!$B:$B,rf1_data!BI:BI,"NaN")="","NaN",(_xlfn.XLOOKUP($B3,rf1_data!$B:$B,rf1_data!BI:BI,"NaN"))) -> NaN | BR3: =IF(_xlfn.XLOOKUP($B3,rf1_data!$B:$B,rf1_data!BJ:BJ,"NaN")="","NaN",(_xlfn.XLOOKUP($B3,rf1_data!$B:$B,rf1_data!BJ:BJ,"NaN"))) -> 8991 | BS3: =IF(_xlfn.XLOOKUP($B3,rf1_data!$B:$B,rf1_data!BK:BK,"NaN")="","NaN",(_xlfn.XLOOKUP($B3,rf1_data!$B:$B,rf1_data!BK:BK,"NaN"))) -> NaN | BT3: =IF(_xlfn.XLOOKUP($B3,rf1_data!$B:$B,rf1_data!BL:BL,"NaN")="","NaN",(_xlfn.XLOOKUP($B3,rf1_data!$B:$B,rf1_data!BL:BL,"NaN"))) -> NaN | BU3: =IF(_xlfn.XLOOKUP($B3,rf1_data!$B:$B,rf1_data!BM:BM,"NaN")="","NaN",(_xlfn.XLOOKUP($B3,rf1_data!$B:$B,rf1_data!BM:BM,"NaN"))) -> NaN | BV3: =IF(_xlfn.XLOOKUP($B3,rf1_data!$B:$B,rf1_data!BN:BN,"NaN")="","NaN",(_xlfn.XLOOKUP($B3,rf1_data!$B:$B,rf1_data!BN:BN,"NaN"))) -> NaN | BW3: =IF(_xlfn.XLOOKUP($B3,rf1_data!$B:$B,rf1_data!BO:BO,"NaN")="","NaN",(_xlfn.XLOOKUP($B3,rf1_data!$B:$B,rf1_data!BO:BO,"NaN"))) -> 3.6 | BX3: =IF(_xlfn.XLOOKUP($B3,rf1_data!$B:$B,rf1_data!BP:BP,"NaN")="","NaN",(_xlfn.XLOOKUP($B3,rf1_data!$B:$B,rf1_data!BP:BP,"NaN"))) -> 3.9 | BY3: =IF(_xlfn.XLOOKUP($B3,rf1_data!$B:$B,rf1_data!BQ:BQ,"NaN")="","NaN",(_xlfn.XLOOKUP($B3,rf1_data!$B:$B,rf1_data!BQ:BQ,"NaN"))) -> 3.5 | BZ3: =IF(_xlfn.XLOOKUP($B3,rf1_data!$B:$B,rf1_data!BR:BR,"NaN")="","NaN",(_xlfn.XLOOKUP($B3,rf1_data!$B:$B,rf1_data!BR:BR,"NaN"))) -> 3.67 | CA3: =IF(_xlfn.XLOOKUP($B3,rf1_data!$B:$B,rf1_data!BS:BS,"NaN")="","NaN",(_xlfn.XLOOKUP($B3,rf1_data!$B:$B,rf1_data!BS:BS,"NaN"))) -> 6 | CB3: =IF(_xlfn.XLOOKUP($B3,rf1_data!$B:$B,rf1_data!BT:BT,"NaN")="","NaN",(_xlfn.XLOOKUP($B3,rf1_data!$B:$B,rf1_data!BT:BT,"NaN"))) -> 5.6666667 | CC3: =IF(_xlfn.XLOOKUP($B3,rf1_data!$B:$B,rf1_data!BU:BU,"NaN")="","NaN",(_xlfn.XLOOKUP($B3,rf1_data!$B:$B,rf1_data!BU:BU,"NaN"))) -> 6 | CD3: =IF(_xlfn.XLOOKUP($B3,rf1_data!$B:$B,rf1_data!BV:BV,"NaN")="","NaN",(_xlfn.XLOOKUP($B3,rf1_data!$B:$B,rf1_data!BV:BV,"NaN"))) -> 5.6666667 | CE3: =IF(_xlfn.XLOOKUP($B3,rf1_data!$B:$B,rf1_data!BW:BW,"NaN")="","NaN",(_xlfn.XLOOKUP($B3,rf1_data!$B:$B,rf1_data!BW:BW,"NaN"))) -> 0.75 | CF3: =IF(_xlfn.XLOOKUP($B3,rf1_data!$B:$B,rf1_data!BX:BX,"NaN")="","NaN",(_xlfn.XLOOKUP($B3,rf1_data!$B:$B,rf1_data!BX:BX,"NaN"))) -> 0 | CG3: =IF(_xlfn.XLOOKUP($B3,rf1_data!$B:$B,rf1_data!BY:BY,"NaN")="","NaN",(_xlfn.XLOOKUP($B3,rf1_data!$B:$B,rf1_data!BY:BY,"NaN"))) -> 0 | CH3: =IF(_xlfn.XLOOKUP($B3,rf1_data!$B:$B,rf1_data!BZ:BZ,"NaN")="","NaN",(_xlfn.XLOOKUP($B3,rf1_data!$B:$B,rf1_data!BZ:BZ,"NaN"))) -> 18 | CI3: =IF(_xlfn.XLOOKUP($B3,rf1_data!$B:$B,rf1_data!CA:CA,"NaN")="","NaN",(_xlfn.XLOOKUP($B3,rf1_data!$B:$B,rf1_data!CA:CA,"NaN"))) -> 25 | CJ3: =IF(_xlfn.XLOOKUP($B3,rf1_data!$B:$B,rf1_data!CB:CB,"NaN")="","NaN",(_xlfn.XLOOKUP($B3,rf1_data!$B:$B,rf1_data!CB:CB,"NaN"))) -> 4 | CK3: =IF(_xlfn.XLOOKUP($B3,rf1_data!$B:$B,rf1_data!CC:CC,"NaN")="","NaN",(_xlfn.XLOOKUP($B3,rf1_data!$B:$B,rf1_data!CC:CC,"NaN"))) -> 0.57142857 | CL3: =IF(_xlfn.XLOOKUP($B3,rf1_data!$B:$B,rf1_data!CD:CD,"NaN")=0,"NaN",(_xlfn.XLOOKUP($B3,rf1_data!$B:$B,rf1_data!CD:CD,"NaN"))) -> 18 | CM3: =IF(_xlfn.XLOOKUP($B3,rf1_data!$B:$B,rf1_data!CE:CE,"NaN")="","NaN",(_xlfn.XLOOKUP($B3,rf1_data!$B:$B,rf1_data!CE:CE,"NaN"))) -> 42 | CN3: =IF(_xlfn.XLOOKUP($B3,rf1_data!$B:$B,rf1_data!CF:CF,"NaN")="","NaN",(_xlfn.XLOOKUP($B3,rf1_data!$B:$B,rf1_data!CF:CF,"NaN"))) -> 41 | CO3: =IF(_xlfn.XLOOKUP($B3,rf1_data!$B:$B,rf1_data!CG:CG,"NaN")="","NaN",(_xlfn.XLOOKUP($B3,rf1_data!$B:$B,rf1_data!CG:CG,"NaN"))) -> 23 | CP3: =IF(_xlfn.XLOOKUP($B3,rf1_data!$B:$B,rf1_data!CH:CH,"NaN")=0,"NaN",(_xlfn.XLOOKUP($B3,rf1_data!$B:$B,rf1_data!CH:CH,"NaN"))) -> 33 | CQ3: =IF(_xlfn.XLOOKUP($B3,rf1_data!$B:$B,rf1_data!CI:CI,"NaN")="","NaN",(_xlfn.XLOOKUP($B3,rf1_data!$B:$B,rf1_data!CI:CI,"NaN"))) -> 38 | CR3: =IF(_xlfn.XLOOKUP($B3,rf1_data!$B:$B,rf1_data!CJ:CJ,"NaN")="","NaN",(_xlfn.XLOOKUP($B3,rf1_data!$B:$B,rf1_data!CJ:CJ,"NaN"))) -> 60 | CS3: =IF(_xlfn.XLOOKUP($B3,rf1_data!$B:$B,rf1_data!CK:CK,"NaN")="","NaN",(_xlfn.XLOOKUP($B3,rf1_data!$B:$B,rf1_data!CK:CK,"NaN"))) -> 42 | CT3: =IF(_xlfn.XLOOKUP($B3,rf1_data!$B:$B,rf1_data!CL:CL,"NaN")="","NaN",(_xlfn.XLOOKUP($B3,rf1_data!$B:$B,rf1_data!CL:CL,"NaN"))) -> 60 | CU3: =IF(_xlfn.XLOOKUP($B3,rf1_data!$B:$B,rf1_data!CM:CM,"NaN")="","NaN",(_xlfn.XLOOKUP($B3,rf1_data!$B:$B,rf1_data!CM:CM,"NaN"))) -> 38 | CV3: =IF(_xlfn.XLOOKUP($B3,rf1_data!$B:$B,rf1_data!CN:CN,"NaN")="","NaN",(_xlfn.XLOOKUP($B3,rf1_data!$B:$B,rf1_data!CN:CN,"NaN"))) -> 60 | CW3: =IF(_xlfn.XLOOKUP($B3,rf1_data!$B:$B,rf1_data!CO:CO,"NaN")="","NaN",(_xlfn.XLOOKUP($B3,rf1_data!$B:$B,rf1_data!CO:CO,"NaN"))) -> NaN | CX3: =IF(_xlfn.XLOOKUP($B3,rf1_data!$B:$B,rf1_data!CP:CP,"NaN")="","NaN",(_xlfn.XLOOKUP($B3,rf1_data!$B:$B,rf1_data!CP:CP,"NaN"))) -> NaN | CY3: =IF(_xlfn.XLOOKUP($B3,rf1_data!$B:$B,rf1_data!CQ:CQ,"NaN")="","NaN",(_xlfn.XLOOKUP($B3,rf1_data!$B:$B,rf1_data!CQ:CQ,"NaN"))) -> 4 | CZ3: =IF(_xlfn.XLOOKUP($B3,rf1_data!$B:$B,rf1_data!CR:CR,"NaN")="","NaN",(_xlfn.XLOOKUP($B3,rf1_data!$B:$B,rf1_data!CR:CR,"NaN"))) -> 1 | DA3: =IF(_xlfn.XLOOKUP($B3,rf1_data!$B:$B,rf1_data!CS:CS,"NaN")="","NaN",(_xlfn.XLOOKUP($B3,rf1_data!$B:$B,rf1_data!CS:CS,"NaN"))) -> 1 | DB3: =IF(_xlfn.XLOOKUP($B3,island_data!$B:$B,island_data!H:H,"NaN")="","NaN",_xlfn.XLOOKUP($B3,island_data!$B:$B,island_data!H:H,"NaN")) -> 9 | DC3: =IF(_xlfn.XLOOKUP($B3,island_data!$B:$B,island_data!I:I,"NaN")="","NaN",_xlfn.XLOOKUP($B3,island_data!$B:$B,island_data!I:I,"NaN")) -> 13 | DD3: =IF(_xlfn.XLOOKUP($B3,island_data!$B:$B,island_data!J:J,"NaN")="","NaN",_xlfn.XLOOKUP($B3,island_data!$B:$B,island_data!J:J,"NaN")) -> 3 | DE3: =IF(_xlfn.XLOOKUP($B3,island_data!$B:$B,island_data!K:K,"NaN")="","NaN",_xlfn.XLOOKUP($B3,island_data!$B:$B,island_data!K:K,"NaN")) -> NaN | DF3: =IF(_xlfn.XLOOKUP($B3,island_data!$B:$B,island_data!L:L,"NaN")="","NaN",_xlfn.XLOOKUP($B3,island_data!$B:$B,island_data!L:L,"NaN")) -> 0 | DG3: =IF(_xlfn.XLOOKUP($B3,island_data!$B:$B,island_data!M:M,"NaN")="","NaN",_xlfn.XLOOKUP($B3,island_data!$B:$B,island_data!M:M,"NaN")) -> 3.5 | DH3: =IF(_xlfn.XLOOKUP($B3,island_data!$B:$B,island_data!N:N,"NaN")="","NaN",_xlfn.XLOOKUP($B3,island_data!$B:$B,island_data!N:N,"NaN")) -> 12 | DI3: =IF(_xlfn.XLOOKUP($B3,island_data!$B:$B,island_data!O:O,"NaN")=999,"NaN",_xlfn.XLOOKUP($B3,island_data!$B:$B,island_data!O:O,"NaN")) -> NaN | DJ3: =IF(_xlfn.XLOOKUP($B3,island_data!$B:$B,island_data!P:P,"NaN")="","NaN",_xlfn.XLOOKUP($B3,island_data!$B:$B,island_data!P:P,"NaN")) -> 8 | DK3: =IF(_xlfn.XLOOKUP($B3,island_data!$B:$B,island_data!Q:Q,"NaN")="","NaN",_xlfn.XLOOKUP($B3,island_data!$B:$B,island_data!Q:Q,"NaN")) -> 12 | DL3: =IF(_xlfn.XLOOKUP($B3,island_data!$B:$B,island_data!R:R,"NaN")=999,"NaN",_xlfn.XLOOKUP($B3,island_data!$B:$B,island_data!R:R,"NaN")) -> NaN | DM3: =IF(_xlfn.XLOOKUP($B3,island_data!$B:$B,island_data!S:S,"NaN")="","NaN",_xlfn.XLOOKUP($B3,island_data!$B:$B,island_data!S:S,"NaN")) -> 11 | DN3: =IF(_xlfn.XLOOKUP($B3,island_data!$B:$B,island_data!T:T,"NaN")="","NaN",_xlfn.XLOOKUP($B3,island_data!$B:$B,island_data!T:T,"NaN")) -> 4.5 | DO3: =IF(_xlfn.XLOOKUP($B3,island_data!$B:$B,island_data!U:U,"NaN")="","NaN",_xlfn.XLOOKUP($B3,island_data!$B:$B,island_data!U:U,"NaN")) -> 5 | DP3: =IF(_xlfn.XLOOKUP($B3,island_data!$B:$B,island_data!V:V,"NaN")="","NaN",_xlfn.XLOOKUP($B3,island_data!$B:$B,island_data!V:V,"NaN")) -> 1 | DQ3: =IF(_xlfn.XLOOKUP($B3,island_data!$B:$B,island_data!W:W,"NaN")="","NaN",_xlfn.XLOOKUP($B3,island_data!$B:$B,island_data!W:W,"NaN")) -> 4 | DR3: =IF(_xlfn.XLOOKUP($B3,island_data!$B:$B,island_data!X:X,"NaN")="","NaN",_xlfn.XLOOKUP($B3,island_data!$B:$B,island_data!X:X,"NaN")) -> 5 | DS3: =IF(_xlfn.XLOOKUP($B3,island_data!$B:$B,island_data!Y:Y,"NaN")="","NaN",_xlfn.XLOOKUP($B3,island_data!$B:$B,island_data!Y:Y,"NaN")) -> NaN | DT3: =IF(_xlfn.XLOOKUP($B3,island_data!$B:$B,island_data!Z:Z,"NaN")="","NaN",_xlfn.XLOOKUP($B3,island_data!$B:$B,island_data!Z:Z,"NaN")) -> NaN | DU3: =IF(_xlfn.XLOOKUP($B3,island_data!$B:$B,island_data!AA:AA,"NaN")="","NaN",_xlfn.XLOOKUP($B3,island_data!$B:$B,island_data!AA:AA,"NaN")) -> NaN | DV3: =IF(_xlfn.XLOOKUP($B3,island_data!$B:$B,island_data!AB:AB,"NaN")="","NaN",_xlfn.XLOOKUP($B3,island_data!$B:$B,island_data!AB:AB,"NaN")) -> NaN | DW3: =IF(_xlfn.XLOOKUP($B3,island_data!$B:$B,island_data!AC:AC,"NaN")="","NaN",_xlfn.XLOOKUP($B3,island_data!$B:$B,island_data!AC:AC,"NaN")) -> 19054 | DX3: =IF(_xlfn.XLOOKUP($B3,island_data!$B:$B,island_data!AD:AD,"NaN")="","NaN",_xlfn.XLOOKUP($B3,island_data!$B:$B,island_data!AD:AD,"NaN")) -> 4 | DY3: =IF(_xlfn.XLOOKUP($B3,island_data!$B:$B,island_data!AE:AE,"NaN")="","NaN",_xlfn.XLOOKUP($B3,island_data!$B:$B,island_data!AE:AE,"NaN")) -> 1 | DZ3: =IF(_xlfn.XLOOKUP($B3,island_data!$B:$B,island_data!AF:AF,"NaN")="","NaN",_xlfn.XLOOKUP($B3,island_data!$B:$B,island_data!AF:AF,"NaN")) -> NaN | EA3: =IF(_xlfn.XLOOKUP($B3,island_data!$B:$B,island_data!AG:AG,"NaN")="","NaN",_xlfn.XLOOKUP($B3,island_data!$B:$B,island_data!AG:AG,"NaN")) -> NaN | EB3: =IF(_xlfn.XLOOKUP($B3,island_data!$B:$B,island_data!AH:AH,"NaN")="","NaN",_xlfn.XLOOKUP($B3,island_data!$B:$B,island_data!AH:AH,"NaN")) -> NaN | EC3: =IF(_xlfn.XLOOKUP($B3,island_data!$B:$B,island_data!AI:AI,"NaN")="","NaN",_xlfn.XLOOKUP($B3,island_data!$B:$B,island_data!AI:AI,"NaN")) -> NaN | ED3: =IF(_xlfn.XLOOKUP($B3,island_data!$B:$B,island_data!AJ:AJ,"NaN")="","NaN",_xlfn.XLOOKUP($B3,island_data!$B:$B,island_data!AJ:AJ,"NaN")) -> NaN | EE3: =IF(_xlfn.XLOOKUP($B3,island_data!$B:$B,island_data!AK:AK,"NaN")="","NaN",_xlfn.XLOOKUP($B3,island_data!$B:$B,island_data!AK:AK,"NaN")) -> NaN | EF3: =IF(_xlfn.XLOOKUP($B3,island_data!$B:$B,island_data!AL:AL,"NaN")="","NaN",_xlfn.XLOOKUP($B3,island_data!$B:$B,island_data!AL:AL,"NaN")) -> NaN | EG3: =IF(_xlfn.XLOOKUP($B3,island_data!$B:$B,island_data!AM:AM,"NaN")="","NaN",_xlfn.XLOOKUP($B3,island_data!$B:$B,island_data!AM:AM,"NaN")) -> NaN | EH3: =IF(_xlfn.XLOOKUP($B3,island_data!$B:$B,island_data!AN:AN,"NaN")="","NaN",_xlfn.XLOOKUP($B3,island_data!$B:$B,island_data!AN:AN,"NaN")) -> NaN | EI3: =IF(_xlfn.XLOOKUP($B3,island_data!$B:$B,island_data!AO:AO,"NaN")="","NaN",_xlfn.XLOOKUP($B3,island_data!$B:$B,island_data!AO:AO,"NaN")) -> NaN | EJ3: =IF(_xlfn.XLOOKUP($A3,TabCAT!$A:$A,TabCAT!AU:AU,"NaN")="","NaN",(_xlfn.XLOOKUP($A3,TabCAT!$A:$A,TabCAT!AU:AU,"NaN"))) -> 183 | EK3: =IF(_xlfn.XLOOKUP($A3,TabCAT!$A:$A,TabCAT!AV:AV,"NaN")="","NaN",(_xlfn.XLOOKUP($A3,TabCAT!$A:$A,TabCAT!AV:AV,"NaN"))) -> TRUE | EL3: =IF(_xlfn.XLOOKUP($A3,TabCAT!$A:$A,TabCAT!AW:AW,"NaN")="","NaN",(_xlfn.XLOOKUP($A3,TabCAT!$A:$A,TabCAT!AW:AW,"NaN"))) -> 6 | EM3: =IF(_xlfn.XLOOKUP($A3,TabCAT!$A:$A,TabCAT!AX:AX,"NaN")="","NaN",(_xlfn.XLOOKUP($A3,TabCAT!$A:$A,TabCAT!AX:AX,"NaN"))) -> 0 | EN3: =IF(_xlfn.XLOOKUP($A3,TabCAT!$A:$A,TabCAT!AY:AY,"NaN")="","NaN",(_xlfn.XLOOKUP($A3,TabCAT!$A:$A,TabCAT!AY:AY,"NaN"))) -> 8.32 | EO3: =IF(_xlfn.XLOOKUP($A3,TabCAT!$A:$A,TabCAT!AZ:AZ,"NaN")="","NaN",(_xlfn.XLOOKUP($A3,TabCAT!$A:$A,TabCAT!AZ:AZ,"NaN"))) -> 32 | EP3: =IF(_xlfn.XLOOKUP($A3,TabCAT!$A:$A,TabCAT!BA:BA,"NaN")="","NaN",(_xlfn.XLOOKUP($A3,TabCAT!$A:$A,TabCAT!BA:BA,"NaN"))) -> 0.829171 | EQ3: =IF(_xlfn.XLOOKUP($A3,TabCAT!$A:$A,TabCAT!BB:BB,"NaN")="","NaN",(_xlfn.XLOOKUP($A3,TabCAT!$A:$A,TabCAT!BB:BB,"NaN"))) -> 0.19469296 | ER3: =IF(_xlfn.XLOOKUP($A3,TabCAT!$A:$A,TabCAT!BC:BC,"NaN")="","NaN",(_xlfn.XLOOKUP($A3,TabCAT!$A:$A,TabCAT!BC:BC,"NaN"))) -> 16 | ES3: =IF(_xlfn.XLOOKUP($A3,TabCAT!$A:$A,TabCAT!BD:BD,"NaN")="","NaN",(_xlfn.XLOOKUP($A3,TabCAT!$A:$A,TabCAT!BD:BD,"NaN"))) -> 0.708541 | ET3: =IF(_xlfn.XLOOKUP($A3,TabCAT!$A:$A,TabCAT!BE:BE,"NaN")="","NaN",(_xlfn.XLOOKUP($A3,TabCAT!$A:$A,TabCAT!BE:BE,"NaN"))) -> 16 | EU3: =IF(_xlfn.XLOOKUP($A3,TabCAT!$A:$A,TabCAT!BF:BF,"NaN")="","NaN",(_xlfn.XLOOKUP($A3,TabCAT!$A:$A,TabCAT!BF:BF,"NaN"))) -> 0.858221 | EV3: =IF(_xlfn.XLOOKUP($A3,TabCAT!$A:$A,TabCAT!BG:BG,"NaN")="","NaN",(_xlfn.XLOOKUP($A3,TabCAT!$A:$A,TabCAT!BG:BG,"NaN"))) -> NaN | EW3: =IF(_xlfn.XLOOKUP($A3,TabCAT!$A:$A,TabCAT!BH:BH,"NaN")="","NaN",(_xlfn.XLOOKUP($A3,TabCAT!$A:$A,TabCAT!BH:BH,"NaN"))) -> 3.0.0 | EX3: =IF(_xlfn.XLOOKUP($A3,TabCAT!$A:$A,TabCAT!BI:BI,"NaN")="","NaN",(_xlfn.XLOOKUP($A3,TabCAT!$A:$A,TabCAT!BI:BI,"NaN"))) -> English | EY3: =IF(_xlfn.XLOOKUP($A3,TabCAT!$A:$A,TabCAT!BJ:BJ,"NaN")="","NaN",(_xlfn.XLOOKUP($A3,TabCAT!$A:$A,TabCAT!BJ:BJ,"NaN"))) -> 262 | EZ3: =IF(_xlfn.XLOOKUP($A3,TabCAT!$A:$A,TabCAT!BK:BK,"NaN")="","NaN",(_xlfn.XLOOKUP($A3,TabCAT!$A:$A,TabCAT!BK:BK,"NaN"))) -> 1 | FA3: =IF(_xlfn.XLOOKUP($A3,TabCAT!$A:$A,TabCAT!BL:BL,"NaN")="","NaN",(_xlfn.XLOOKUP($A3,TabCAT!$A:$A,TabCAT!BL:BL,"NaN"))) -> 6 | FB3: =IF(_xlfn.XLOOKUP($A3,TabCAT!$A:$A,TabCAT!BM:BM,"NaN")="","NaN",(_xlfn.XLOOKUP($A3,TabCAT!$A:$A,TabCAT!BM:BM,"NaN"))) -> 1 | FC3: =IF(_xlfn.XLOOKUP($A3,TabCAT!$A:$A,TabCAT!BN:BN,"NaN")="","NaN",(_xlfn.XLOOKUP($A3,TabCAT!$A:$A,TabCAT!BN:BN,"NaN"))) -> 6 | FD3: =IF(_xlfn.XLOOKUP($A3,TabCAT!$A:$A,TabCAT!BO:BO,"NaN")="","NaN",(_xlfn.XLOOKUP($A3,TabCAT!$A:$A,TabCAT!BO:BO,"NaN"))) -> 8 | FE3: =IF(_xlfn.XLOOKUP($A3,TabCAT!$A:$A,TabCAT!BP:BP,"NaN")="","NaN",(_xlfn.XLOOKUP($A3,TabCAT!$A:$A,TabCAT!BP:BP,"NaN"))) -> 0.88888889 | FF3: =IF(_xlfn.XLOOKUP($A3,TabCAT!$A:$A,TabCAT!BQ:BQ,"NaN")="","NaN",(_xlfn.XLOOKUP($A3,TabCAT!$A:$A,TabCAT!BQ:BQ,"NaN"))) -> 8 | FG3: =IF(_xlfn.XLOOKUP($A3,TabCAT!$A:$A,TabCAT!BR:BR,"NaN")="","NaN",(_xlfn.XLOOKUP($A3,TabCAT!$A:$A,TabCAT!BR:BR,"NaN"))) -> 9 | FH3: =IF(_xlfn.XLOOKUP($A3,TabCAT!$A:$A,TabCAT!BS:BS,"NaN")="","NaN",(_xlfn.XLOOKUP($A3,TabCAT!$A:$A,TabCAT!BS:BS,"NaN"))) -> 0.75 | FI3: =IF(_xlfn.XLOOKUP($A3,TabCAT!$A:$A,TabCAT!BT:BT,"NaN")="","NaN",(_xlfn.XLOOKUP($A3,TabCAT!$A:$A,TabCAT!BT:BT,"NaN"))) -> 8 | FJ3: =IF(_xlfn.XLOOKUP($A3,TabCAT!$A:$A,TabCAT!BU:BU,"NaN")="","NaN",(_xlfn.XLOOKUP($A3,TabCAT!$A:$A,TabCAT!BU:BU,"NaN"))) -> 10 | FK3: =IF(_xlfn.XLOOKUP($A3,TabCAT!$A:$A,TabCAT!BV:BV,"NaN")="","NaN",(_xlfn.XLOOKUP($A3,TabCAT!$A:$A,TabCAT!BV:BV,"NaN"))) -> 0.66666667 | FL3: =IF(_xlfn.XLOOKUP($A3,TabCAT!$A:$A,TabCAT!BW:BW,"NaN")="","NaN",(_xlfn.XLOOKUP($A3,TabCAT!$A:$A,TabCAT!BW:BW,"NaN"))) -> 8.5 | FM3: =IF(_xlfn.XLOOKUP($A3,TabCAT!$A:$A,TabCAT!BX:BX,"NaN")="","NaN",(_xlfn.XLOOKUP($A3,TabCAT!$A:$A,TabCAT!BX:BX,"NaN"))) -> 33 | FN3: =IF(_xlfn.XLOOKUP($A3,TabCAT!$A:$A,TabCAT!BY:BY,"NaN")="","NaN",(_xlfn.XLOOKUP($A3,TabCAT!$A:$A,TabCAT!BY:BY,"NaN"))) -> 0.78571429 | FO3: =IF(_xlfn.XLOOKUP($A3,TabCAT!$A:$A,TabCAT!BZ:BZ,"NaN")="","NaN",(_xlfn.XLOOKUP($A3,TabCAT!$A:$A,TabCAT!BZ:BZ,"NaN"))) -> 30.5 | FP3: =IF(_xlfn.XLOOKUP($A3,TabCAT!$A:$A,TabCAT!CA:CA,"NaN")="","NaN",(_xlfn.XLOOKUP($A3,TabCAT!$A:$A,TabCAT!CA:CA,"NaN"))) -> 3.0.0 | FQ3: =IF(_xlfn.XLOOKUP($A3,TabCAT!$A:$A,TabCAT!CB:CB,"NaN")="","NaN",(_xlfn.XLOOKUP($A3,TabCAT!$A:$A,TabCAT!CB:CB,"NaN"))) -> English | FR3: =IF(_xlfn.XLOOKUP($A3,TabCAT!$A:$A,TabCAT!CC:CC,"NaN")="","NaN",(_xlfn.XLOOKUP($A3,TabCAT!$A:$A,TabCAT!CC:CC,"NaN"))) -> 275 | FS3: =IF(_xlfn.XLOOKUP($A3,TabCAT!$A:$A,TabCAT!CD:CD,"NaN")="","NaN",(_xlfn.XLOOKUP($A3,TabCAT!$A:$A,TabCAT!CD:CD,"NaN"))) -> TRUE | FT3: =IF(_xlfn.XLOOKUP($A3,TabCAT!$A:$A,TabCAT!CE:CE,"NaN")="","NaN",(_xlfn.XLOOKUP($A3,TabCAT!$A:$A,TabCAT!CE:CE,"NaN"))) -> 8 | FU3: =IF(_xlfn.XLOOKUP($A3,TabCAT!$A:$A,TabCAT!CF:CF,"NaN")="","NaN",(_xlfn.XLOOKUP($A3,TabCAT!$A:$A,TabCAT!CF:CF,"NaN"))) -> 0 | FV3: =IF(_xlfn.XLOOKUP($A3,TabCAT!$A:$A,TabCAT!CG:CG,"NaN")="","NaN",(_xlfn.XLOOKUP($A3,TabCAT!$A:$A,TabCAT!CG:CG,"NaN"))) -> 6.47 | FW3: =IF(_xlfn.XLOOKUP($A3,TabCAT!$A:$A,TabCAT!CH:CH,"NaN")="","NaN",(_xlfn.XLOOKUP($A3,TabCAT!$A:$A,TabCAT!CH:CH,"NaN"))) -> 15 | FX3: =IF(_xlfn.XLOOKUP($A3,TabCAT!$A:$A,TabCAT!CI:CI,"NaN")="","NaN",(_xlfn.XLOOKUP($A3,TabCAT!$A:$A,TabCAT!CI:CI,"NaN"))) -> 0.938216 | FY3: =IF(_xlfn.XLOOKUP($A3,TabCAT!$A:$A,TabCAT!CJ:CJ,"NaN")="","NaN",(_xlfn.XLOOKUP($A3,TabCAT!$A:$A,TabCAT!CJ:CJ,"NaN"))) -> 16 | FZ3: =IF(_xlfn.XLOOKUP($A3,TabCAT!$A:$A,TabCAT!CK:CK,"NaN")="","NaN",(_xlfn.XLOOKUP($A3,TabCAT!$A:$A,TabCAT!CK:CK,"NaN"))) -> 1.562937 | GA3: =IF(_xlfn.XLOOKUP($A3,TabCAT!$A:$A,TabCAT!CL:CL,"NaN")="","NaN",(_xlfn.XLOOKUP($A3,TabCAT!$A:$A,TabCAT!CL:CL,"NaN"))) -> 32 | GB3: =IF(_xlfn.XLOOKUP($A3,TabCAT!$A:$A,TabCAT!CM:CM,"NaN")="","NaN",(_xlfn.XLOOKUP($A3,TabCAT!$A:$A,TabCAT!CM:CM,"NaN"))) -> 1.296432 | GC3: =IF(_xlfn.XLOOKUP($A3,TabCAT!$A:$A,TabCAT!CN:CN,"NaN")="","NaN",(_xlfn.XLOOKUP($A3,TabCAT!$A:$A,TabCAT!CN:CN,"NaN"))) -> 16 | GD3: =IF(_xlfn.XLOOKUP($A3,TabCAT!$A:$A,TabCAT!CO:CO,"NaN")="","NaN",(_xlfn.XLOOKUP($A3,TabCAT!$A:$A,TabCAT!CO:CO,"NaN"))) -> 1.3922405 | GE3: =IF(_xlfn.XLOOKUP($A3,TabCAT!$A:$A,TabCAT!CP:CP,"NaN")="","NaN",(_xlfn.XLOOKUP($A3,TabCAT!$A:$A,TabCAT!CP:CP,"NaN"))) -> 0.54860256 | GF3: =IF(_xlfn.XLOOKUP($A3,TabCAT!$A:$A,TabCAT!CQ:CQ,"NaN")="","NaN",(_xlfn.XLOOKUP($A3,TabCAT!$A:$A,TabCAT!CQ:CQ,"NaN"))) -> 57 | GG3: =IF(_xlfn.XLOOKUP($A3,TabCAT!$A:$A,TabCAT!CR:CR,"NaN")="","NaN",(_xlfn.XLOOKUP($A3,TabCAT!$A:$A,TabCAT!CR:CR,"NaN"))) -> 1.196073 | GH3: =IF(_xlfn.XLOOKUP($A3,TabCAT!$A:$A,TabCAT!CS:CS,"NaN")="","NaN",(_xlfn.XLOOKUP($A3,TabCAT!$A:$A,TabCAT!CS:CS,"NaN"))) -> NaN
