Workbook

Sheet Sheet1
A1: sub | B1: tania_subid | C1: precuneus_mask_activation | D1: computer_defect | E1: computer_recip | F1: stranger_defect | G1: stranger_recip | H1: friend_defect | I1: friend_recip | J1: sub_age | K1: race | L1: sub_gender | M1: eros_o_score | N1: eros_s_score | O1: susd_adult_mania | P1: susd_adult_depression | Q1: sogs_total | R1: score_tei_wellbeing | S1: score_tei_selfcontrol | T1: score_tei_emotionality | U1: score_tei_sociability | V1: score_tei_globaltrait | W1: scaared_adult_total | X1: scaared_adult_panic | Y1: scaared_adult_gad | Z1: scaared_adult_separation | AA1: scaared_adult_socanx | AB1: score_aq_socialskill | AC1: score_aq_attnswitch | AD1: score_aq_attndetail | AE1: score_aq_communication | AF1: score_aq_imagination | AG1: score_aq_total | AH1: panas_p_prescan_total | AI1: panas_n_prescan_total | AJ1: norc_lifetime_total | AK1: norc_year_total | AL1: mspss_retest_scoring | AM1: mspss_retest_friends | AN1: mspss_retest_family | AO1: mspss_retest_sig_other | AP1: nbs_adult_sum | AQ1: bsmas_total | AR1: gs_short_form_total | AS1: oafem_total | AT1: gti_score | AU1: gs_total | AV1: crt_score_total | AW1: iat_total | AX1: bsas_salience_score | AY1: bsas_mood_score | AZ1: bsas_conflict_score | BA1: bsas_tolerance_score | BB1: bsas_relapse_score | BC1: bsas_withdrawl_score | BD1: bsas_problems_score | BE1: bsas_total_score | BF1: mach_iv_total | BG1: mach_iv_sum | BH1: bpaqsf_total_sum | BI1: bpaqsf_physical_sum | BJ1: bpaqsf_anger_sum | BK1: bpaqsf_verbal_sum | BL1: bpaqsf_hostile_sum | BM1: pnr_p_total | BN1: pnr_n_total | BO1: quic_adult_scoring_parent_involve | BP1: quic_adult_scoring_parent_predictability | BQ1: quic_adult_scoring_parent_enviornment | BR1: quic_adult_scoring_parent_physicalenviro | BS1: quic_adult_scoring_parent_safety | BT1: plan_score_mf | BU1: plan_score_to | BV1: plan_score_cs | BW1: plan_score_total | BX1: ctb_1_score | BY1: ctb_2_score | BZ1: ctb_3_score | CA1: ctb_4_score | CB1: scd_score_total | CC1: nih_sum | CD1: nih_score_yn | CE1: hvltimm_equation | CF1: hvlt_delaytime_equation | CG1: hvlt_delay_score | CH1: hvlt_retention | CI1: hvlt_rec_dis | CJ1: salthouse_let_score | CK1: salthouse_pat_score | CL1: har_score | CM1: kbit_score | CN1: math_addition_score | CO1: math_addition_time | CP1: math_subtraction_score | CQ1: math_subtraction_time | CR1: math_multiplication_score | CS1: math_multiplication_time | CT1: ios_sr_score | CU1: ios_invest_score | CV1: ios_friend_score | CW1: ios_computer_score | CX1: screener_date | CY1: dob | CZ1: age_mo | DA1: race | DB1: gender | DC1: audit_sum | DD1: dudit_sum | DE1: usi_sum | DF1: fevs_sum | DG1: pmas_sum | DH1: pam_total_sum | DI1: pam_adult_duration | DJ1: pam_adult_interaction | DK1: pam_adult_knowledge | DL1: pam_adult_intimate | DM1: pam_adult_disclose | DN1: pam_adult_social | DO1: mspss_sum | DP1: ses_2 | DQ1: ses_03 | DR1: ses_4 | DS1: ses_score_1 | DT1: ses_score_2 | DU1: ses_score_3 | DV1: ses_score_4 | DW1: ses_score_5 | DX1: ses_score_6 | DY1: ses_score_7 | DZ1: fraud_score_1 | EA1: fraud_score_2 | EB1: fraud_score_3 | EC1: fraud_score_4 | ED1: dospert_score_e | EE1: dospert_score_fi_fg | EF1: dospert_score_hs | EG1: dospert_score_r | EH1: dospert_score_s | EI1: faq_score | EJ1: ecog_score
A2: 10317 | B2: 191960 | C2: -46.00628 | D2: 2.8 | E2: 4 | F2: 2.8 | G2: 5.2 | H2: 6.857143 | I2: 4.666667 | J2: 62.96 | K2: White | L2: Female | M2: 4.22 | N2: 4.3 | O2: 0 | P2: 6 | Q2: 0 | R2: 4.83 | S2: 4.83 | T2: 5.38 | U2: 4.5 | V2: 4.97 | W2: 21 | X2: 3 | Y2: 11 | Z2: 1 | AA2: 6 | AB2: 3 | AC2: 7 | AD2: 2 | AE2: 5 | AF2: 2 | AG2: 19 | AH2: 30 | AI2: 8 | AJ2: 0 | AK2: 0 | AL2: 3.83 | AM2: 6.5 | AN2: 1 | AO2: 4 | AP2: 3 | AQ2: 17 | AR2: 1.58 | AS2: 92 | AT2: 3 | AU2: 2.66 | AV2: 120.1 | AW2: 0 | AX2: 0 | AY2: 0 | AZ2: 0 | BA2: 0 | BB2: 0 | BC2: 0 | BD2: 0 | BE2: 0 | BF2: 20 | BG2: 0 | BH2: 0 | BI2: 0 | BJ2: 0 | BK2: 0 | BL2: 0 | BM2: 0 | BN2: 0 | BO2: 8991 | BP2: 0 | BQ2: 0 | BR2: 0 | BS2: 0 | BT2: 4 | BU2: 4.4 | BV2: 4.4 | BW2: 4.27 | BX2: 6 | BY2: 5.1666667 | BZ2: 6 | CA2: 5.1666667 | CB2: 2.75 | CC2: 0 | CD2: 0 | CE2: 28 | CF2: 26 | CG2: 12 | CH2: 1.2 | CI2: 40 | CJ2: 45 | CK2: 47 | CL2: 26 | CM2: 29 | CN2: 43 | CO2: 60 | CP2: 34 | CQ2: 60 | CR2: 27 | CS2: 60 | CT2: 0 | CU2: 0 | CV2: 3 | CW2: 1 | CX2: NaN | CY2: NaN | CZ2: NaN | DA2: NaN | DB2: NaN | DC2: NaN | DD2: NaN | DE2: NaN | DF2: NaN | DG2: NaN | DH2: NaN | DI2: NaN | DJ2: NaN | DK2: NaN | DL2: NaN | DM2: NaN | DN2: NaN | DO2: NaN | DP2: NaN | DQ2: NaN | DR2: NaN | DS2: NaN | DT2: NaN | DU2: NaN | DV2: NaN | DW2: NaN | DX2: NaN | DY2: NaN | DZ2: NaN | EA2: NaN | EB2: NaN | EC2: NaN | ED2: NaN | EE2: NaN | EF2: NaN | EG2: NaN | EH2: NaN | EI2: NaN | EJ2: NaN
A3: 10369 | B3: 30791 | C3: 131.48849 | D3: 4.5 | E3: 4.285714 | F3: 3 | G3: 4.8 | H3: 5.428571 | I3: 4.666667 | J3: 31.95 | K3: White | L3: Male | M3: 4.56 | N3: 3.44 | O3: 0 | P3: 8 | Q3: 1 | R3: 3.5 | S3: 3.83 | T3: 5.13 | U3: 4.67 | V3: 4.3 | W3: 18 | X3: 5 | Y3: 10 | Z3: 0 | AA3: 3 | AB3: 2 | AC3: 7 | AD3: 5 | AE3: 5 | AF3: 2 | AG3: 21 | AH3: 26 | AI3: 10 | AJ3: 0 | AK3: 0 | AL3: 0 | AM3: 0 | AN3: 0 | AO3: 0 | AP3: 2.7 | AQ3: 13 | AR3: 2.25 | AS3: 94 | AT3: 0 | AU3: 2.63 | AV3: 44.05 | AW3: 0 | AX3: 0 | AY3: 0 | AZ3: 0 | BA3: 0 | BB3: 0 | BC3: 0 | BD3: 0 | BE3: 0 | BF3: 20 | BG3: 0 | BH3: 0 | BI3: 0 | BJ3: 0 | BK3: 0 | BL3: 0 | BM3: 0 | BN3: 0 | BO3: 8991 | BP3: 0 | BQ3: 0 | BR3: 0 | BS3: 0 | BT3: 3.6 | BU3: 3.9 | BV3: 3.5 | BW3: 3.67 | BX3: 6 | BY3: 5.6666667 | BZ3: 6 | CA3: 5.6666667 | CB3: 0.75 | CC3: 0 | CD3: 0 | CE3: 18 | CF3: 25 | CG3: 4 | CH3: 0.57142857 | CI3: 18 | CJ3: 42 | CK3: 41 | CL3: 23 | CM3: 33 | CN3: 38 | CO3: 60 | CP3: 42 | CQ3: 60 | CR3: 38 | CS3: 60 | CT3: 0 | CU3: 0 | CV3: 4 | CW3: 1 | CX3: 45105 | CY3: 33288 | CZ3: 32.35 | DA3: NaN | DB3: NaN | DC3: 9 | DD3: 13 | DE3: 3 | DF3: NaN | DG3: 0 | DH3: 3.5 | DI3: 12 | DJ3: 999 | DK3: 8 | DL3: 12 | DM3: 999 | DN3: 11 | DO3: 4.5 | DP3: 5 | DQ3: 1 | DR3: 4 | DS3: 5 | DT3: NaN | DU3: NaN | DV3: NaN | DW3: NaN | DX3: 19054 | DY3: 4 | DZ3: 1 | EA3: NaN | EB3: NaN | EC3: NaN | ED3: NaN | EE3: NaN | EF3: NaN | EG3: NaN | EH3: NaN | EI3: NaN | EJ3: NaN
A4: 10391 | B4: 111978 | C4: -135.44364 | D4: NaN | E4: NaN | F4: NaN | G4: NaN | H4: NaN | I4: NaN | J4: 44.21 | K4: White | L4: Female | M4: 3.33 | N4: 2.67 | O4: 0 | P4: 6 | Q4: 0 | R4: 0 | S4: 0 | T4: 0 | U4: 0 | V4: 0 | W4: 33 | X4: 3 | Y4: 12 | Z4: 4 | AA4: 14 | AB4: 7 | AC4: 8 | AD4: 3 | AE4: 4 | AF4: 5 | AG4: 27 | AH4: 0 | AI4: 0 | AJ4: 0 | AK4: 0 | AL4: 0 | AM4: 0 | AN4: 0 | AO4: 0 | AP4: 3.7 | AQ4: 24 | AR4: 3.17 | AS4: 66 | AT4: 0 | AU4: 9999 | AV4: 209 | AW4: 0 | AX4: 0 | AY4: 0 | AZ4: 0 | BA4: 0 | BB4: 0 | BC4: 0 | BD4: 0 | BE4: 0 | BF4: 20 | BG4: 0 | BH4: 20 | BI4: 6 | BJ4: 3 | BK4: 7 | BL4: 4 | BM4: 0 | BN4: 0 | BO4: 8991 | BP4: 0 | BQ4: 0 | BR4: 0 | BS4: 0 | BT4: 2.7 | BU4: 2.8 | BV4: 3.2 | BW4: 2.9 | BX4: 0 | BY4: 0 | BZ4: 0 | CA4: 0 | CB4: 2.65 | CC4: 1 | CD4: 0 | CE4: 17 | CF4: 20 | CG4: 5 | CH4: 0.71428571 | CI4: 22 | CJ4: 38 | CK4: 53 | CL4: 30 | CM4: 30 | CN4: 47 | CO4: 58 | CP4: 48 | CQ4: 60 | CR4: 41 | CS4: 60 | CT4: 0 | CU4: 0 | CV4: 4 | CW4: 1 | CX4: 45105 | CY4: 28713 | CZ4: 44.88 | DA4: NaN | DB4: NaN | DC4: 3 | DD4: 0 | DE4: 1 | DF4: 13 | DG4: 21 | DH4: 1.8888889 | DI4: 8 | DJ4: 999 | DK4: 5 | DL4: 1 | DM4: 999 | DN4: 8 | DO4: 4.0833333 | DP4: 5 | DQ4: 1 | DR4: 6 | DS4: 5 | DT4: NaN | DU4: NaN | DV4: NaN | DW4: NaN | DX4: 13210 | DY4: 6 | DZ4: 1 | EA4: NaN | EB4: NaN | EC4: NaN | ED4: NaN | EE4: NaN | EF4: NaN | EG4: NaN | EH4: NaN | EI4: NaN | EJ4: NaN
A5: 10402 | B5: 20286 | C5: 18.702979 | D5: 3.714286 | E5: 3.166667 | F5: 4.153846 | G5: 4.857143 | H5: 4 | I5: 5.384615 | J5: 35.94 | K5: Black or African American | L5: Male | M5: 3.56 | N5: 2.67 | O5: 4 | P5: 6 | Q5: 0 | R5: 0 | S5: 0 | T5: 0 | U5: 0 | V5: 0 | W5: 10 | X5: 0 | Y5: 8 | Z5: 0 | AA5: 2 | AB5: 5 | AC5: 6 | AD5: 8 | AE5: 4 | AF5: 3 | AG5: 26 | AH5: 22 | AI5: 14 | AJ5: 1 | AK5: 0 | AL5: 0 | AM5: 0 | AN5: 0 | AO5: 0 | AP5: 2.8 | AQ5: 22 | AR5: 4.42 | AS5: 89 | AT5: 0 | AU5: 3.71 | AV5: 104 | AW5: 0 | AX5: 0 | AY5: 0 | AZ5: 0 | BA5: 0 | BB5: 0 | BC5: 0 | BD5: 0 | BE5: 0 | BF5: 20 | BG5: 0 | BH5: 0 | BI5: 0 | BJ5: 0 | BK5: 0 | BL5: 0 | BM5: 0 | BN5: 0 | BO5: 8991 | BP5: 0 | BQ5: 0 | BR5: 0 | BS5: 0 | BT5: 3.1 | BU5: 4 | BV5: 3.5 | BW5: 3.53 | BX5: 6 | BY5: 5.1666667 | BZ5: 6 | CA5: 6 | CB5: 2.05 | CC5: 2 | CD5: 0 | CE5: 28 | CF5: 18 | CG5: 10 | CH5: 1 | CI5: 38 | CJ5: 31 | CK5: 41 | CL5: 19 | CM5: 35 | CN5: 44 | CO5: 60 | CP5: 36 | CQ5: 60 | CR5: 41 | CS5: 60 | CT5: 0 | CU5: 0 | CV5: 4 | CW5: 5 | CX5: 45105 | CY5: 31748 | CZ5: 36.57 | DA5: NaN | DB5: NaN | DC5: 3 | DD5: 2 | DE5: 2 | DF5: NaN | DG5: 28 | DH5: 2 | DI5: 3 | DJ5: 999 | DK5: 8 | DL5: 0 | DM5: 999 | DN5: 7 | DO5: 3.25 | DP5: 4 | DQ5: 1 | DR5: 3 | DS5: 4 | DT5: NaN | DU5: NaN | DV5: NaN | DW5: NaN | DX5: 8081 | DY5: 3 | DZ5: 1 | EA5: NaN | EB5: NaN | EC5: NaN | ED5: NaN | EE5: NaN | EF5: NaN | EG5: NaN | EH5: NaN | EI5: NaN | EJ5: NaN
A6: 10418 | B6: 102054 | C6: 402.2851 | D6: 4.666667 | E6: 3.538462 | F6: 4.333333 | G6: 3.384615 | H6: 5.692308 | I6: 6.142857 | J6: 68.64 | K6: White | L6: Female | M6: 4.22 | N6: 3.44 | O6: 0 | P6: 2 | Q6: 4 | R6: 5.67 | S6: 5.33 | T6: 5.25 | U6: 4.83 | V6: 5.1 | W6: 16 | X6: 4 | Y6: 2 | Z6: 0 | AA6: 10 | AB6: 9 | AC6: 2 | AD6: 4 | AE6: 3 | AF6: 3 | AG6: 21 | AH6: 26 | AI6: 11 | AJ6: 0 | AK6: 0 | AL6: 0 | AM6: 0 | AN6: 0 | AO6: 0 | AP6: 2.6 | AQ6: 7 | AR6: 4 | AS6: 90 | AT6: 0 | AU6: 4.2 | AV6: 127 | AW6: 35 | AX6: 0 | AY6: 0 | AZ6: 0 | BA6: 0.25 | BB6: 0 | BC6: 0 | BD6: 0 | BE6: 0.035714286 | BF6: 90 | BG6: 70 | BH6: 0 | BI6: 0 | BJ6: 0 | BK6: 0 | BL6: 0 | BM6: 52 | BN6: 13 | BO6: 8991 | BP6: 0 | BQ6: 0 | BR6: 0 | BS6: 0 | BT6: 3.3 | BU6: 3 | BV6: 3.1 | BW6: 3.13 | BX6: 6 | BY6: 5.1666667 | BZ6: 6 | CA6: 5.1666667 | CB6: 1.6 | CC6: 0 | CD6: 0 | CE6: 22 | CF6: 20 | CG6: 7 | CH6: 0.875 | CI6: 28 | CJ6: 24 | CK6: 33 | CL6: 25 | CM6: 27 | CN6: 35 | CO6: 60 | CP6: 29 | CQ6: 60 | CR6: 27 | CS6: 60 | CT6: 0 | CU6: 0 | CV6: 3 | CW6: 3 | CX6: 45000 | CY6: 19888 | CZ6: 68.75 | DA6: 4 | DB6: 1 | DC6: 3 | DD6: 0 | DE6: 1 | DF6: NaN | DG6: 27 | DH6: 2.5555556 | DI6: 12 | DJ6: 999 | DK6: 7 | DL6: 1 | DM6: 999 | DN6: 10 | DO6: 4.75 | DP6: 6 | DQ6: 1 | DR6: 7 | DS6: 6 | DT6: NaN | DU6: NaN | DV6: NaN | DW6: 1 | DX6: 44112 | DY6: 7 | DZ6: 0 | EA6: NaN | EB6: NaN | EC6: NaN | ED6: NaN | EE6: NaN | EF6: NaN | EG6: NaN | EH6: NaN | EI6: 1 | EJ6: NaN
A7: 10462 | B7: 21960 | C7: 181.11733 | D7: 2 | E7: 3 | F7: 2.857143 | G7: 3.5 | H7: 3.666667 | I7: 5.2 | J7: 62.04 | K7: Black or African American | L7: Male | M7: 4.67 | N7: 3.44 | O7: 4 | P7: 3 | Q7: 0 | R7: 0 | S7: 0 | T7: 0 | U7: 0 | V7: 0 | W7: 5 | X7: 0 | Y7: 5 | Z7: 0 | AA7: 0 | AB7: 3 | AC7: 4 | AD7: 6 | AE7: 2 | AF7: 1 | AG7: 16 | AH7: 27 | AI7: 10 | AJ7: 0 | AK7: 0 | AL7: 0 | AM7: 0 | AN7: 0 | AO7: 0 | AP7: 3.2 | AQ7: 8 | AR7: 2.67 | AS7: 90 | AT7: 0 | AU7: 3.14 | AV7: 110 | AW7: 0 | AX7: 0 | AY7: 0 | AZ7: 0 | BA7: 0 | BB7: 0 | BC7: 0 | BD7: 0 | BE7: 0 | BF7: 20 | BG7: 0 | BH7: 0 | BI7: 0 | BJ7: 0 | BK7: 0 | BL7: 0 | BM7: 0 | BN7: 0 | BO7: 8991 | BP7: 0 | BQ7: 0 | BR7: 0 | BS7: 0 | BT7: 3.6 | BU7: 4.3 | BV7: 4 | BW7: 3.97 | BX7: 6 | BY7: 5.1666667 | BZ7: 6 | CA7: 6 | CB7: 0.5 | CC7: 4 | CD7: 1 | CE7: 20 | CF7: 23 | CG7: 4 | CH7: 0.5 | CI7: 20 | CJ7: 0 | CK7: 0 | CL7: 31 | CM7: 27 | CN7: 37 | CO7: 60 | CP7: 30 | CQ7: 60 | CR7: 19 | CS7: 60 | CT7: 0 | CU7: 0 | CV7: 3 | CW7: 1 | CX7: 45105 | CY7: 22225 | CZ7: 62.64 | DA7: NaN | DB7: NaN | DC7: 0 | DD7: 0 | DE7: 8 | DF7: 4 | DG7: 0 | DH7: 2.2222222 | DI7: 12 | DJ7: 999 | DK7: 7 | DL7: 2 | DM7: 999 | DN7: 11 | DO7: 4.25 | DP7: 6 | DQ7: 1 | DR7: 7 | DS7: 6 | DT7: NaN | DU7: NaN | DV7: NaN | DW7: NaN | DX7: 90044 | DY7: 7 | DZ7: 1 | EA7: NaN | EB7: NaN | EC7: NaN | ED7: NaN | EE7: NaN | EF7: NaN | EG7: NaN | EH7: NaN | EI7: 0 | EJ7: NaN
A8: 10478 | B8: 201495 | C8: -29.8846 | D8: 4.4 | E8: 4.833333 | F8: 5 | G8: 4.307692 | H8: 5.571429 | I8: 6.307692 | J8: 27.9 | K8: Asian | L8: Female | M8: 3.56 | N8: 4.22 | O8: 6 | P8: 3 | Q8: 0 | R8: 0 | S8: 0 | T8: 0 | U8: 0 | V8: 0 | W8: 37 | X8: 9 | Y8: 11 | Z8: 5 | AA8: 12 | AB8: 8 | AC8: 7 | AD8: 7 | AE8: 10 | AF8: 3 | AG8: 35 | AH8: 18 | AI8: 11 | AJ8: 0 | AK8: 0 | AL8: 0 | AM8: 0 | AN8: 0 | AO8: 0 | AP8: 3.6 | AQ8: 10 | AR8: 3.33 | AS8: 82 | AT8: 0 | AU8: 4.34 | AV8: 109 | AW8: 0 | AX8: 0 | AY8: 0 | AZ8: 0 | BA8: 0 | BB8: 0 | BC8: 0 | BD8: 0 | BE8: 0 | BF8: 20 | BG8: 0 | BH8: 0 | BI8: 0 | BJ8: 0 | BK8: 0 | BL8: 0 | BM8: 0 | BN8: 0 | BO8: 8991 | BP8: 0 | BQ8: 0 | BR8: 0 | BS8: 0 | BT8: 3.2 | BU8: 3.5 | BV8: 3.3 | BW8: 3.33 | BX8: 6 | BY8: 5.1666667 | BZ8: 6 | CA8: 5.1666667 | CB8: 2.85 | CC8: 2 | CD8: 0 | CE8: 31 | CF8: 35 | CG8: 12 | CH8: 1.0909091 | CI8: 42 | CJ8: 36 | CK8: 62 | CL8: 23 | CM8: 30 | CN8: 48 | CO8: 57 | CP8: 48 | CQ8: 53 | CR8: 48 | CS8: 54 | CT8: 0 | CU8: 0 | CV8: 7 | CW8: 4 | CX8: 45105 | CY8: 34703 | CZ8: 28.48 | DA8: NaN | DB8: NaN | DC8: 1 | DD8: 0 | DE8: 3 | DF8: NaN | DG8: 33 | DH8: 3 | DI8: 12 | DJ8: 999 | DK8: 7 | DL8: 7 | DM8: 999 | DN8: 11 | DO8: 4.5 | DP8: 6 | DQ8: 2 | DR8: 9 | DS8: 6 | DT8: NaN | DU8: NaN | DV8: NaN | DW8: NaN | DX8: 19120 | DY8: 9 | DZ8: 1 | EA8: NaN | EB8: NaN | EC8: NaN | ED8: NaN | EE8: NaN | EF8: NaN | EG8: NaN | EH8: NaN | EI8: NaN | EJ8: NaN
A9: 10486 | B9: 131381 | C9: -152.35064 | D9: 5.666667 | E9: 6 | F9: 5 | G9: 6.571429 | H9: 6.857143 | I9: 4.666667 | J9: 41.91 | K9: White | L9: Female | M9: 4.33 | N9: 3.9 | O9: 4 | P9: 4 | Q9: 0 | R9: 4.33 | S9: 3.83 | T9: 4.63 | U9: 4.17 | V9: 4.4 | W9: 37 | X9: 9 | Y9: 15 | Z9: 6 | AA9: 7 | AB9: 3 | AC9: 7 | AD9: 5 | AE9: 6 | AF9: 2 | AG9: 23 | AH9: 35 | AI9: 14 | AJ9: 0 | AK9: 0 | AL9: 4.75 | AM9: 5.25 | AN9: 5 | AO9: 4 | AP9: 3 | AQ9: 15 | AR9: 3.08 | AS9: 77 | AT9: 0 | AU9: 3.51 | AV9: 29 | AW9: 0 | AX9: 0 | AY9: 0 | AZ9: 0 | BA9: 0 | BB9: 0 | BC9: 0 | BD9: 0 | BE9: 0 | BF9: 20 | BG9: 0 | BH9: 0 | BI9: 0 | BJ9: 0 | BK9: 0 | BL9: 0 | BM9: 0 | BN9: 0 | BO9: 8991 | BP9: 0 | BQ9: 0 | BR9: 0 | BS9: 0 | BT9: 3.7 | BU9: 3.9 | BV9: 3.9 | BW9: 3.83 | BX9: 6 | BY9: 4.3333333 | BZ9: 2.6666667 | CA9: 1.8333333 | CB9: 2.95 | CC9: 0 | CD9: 0 | CE9: 27 | CF9: 24 | CG9: 11 | CH9: 1.1 | CI9: 38 | CJ9: 40 | CK9: 39 | CL9: 23 | CM9: 36 | CN9: 47 | CO9: 0 | CP9: 47 | CQ9: 60 | CR9: 34 | CS9: 60 | CT9: 0 | CU9: 0 | CV9: 4 | CW9: 4 | CX9: 45105 | CY9: 29682 | CZ9: 42.23 | DA9: NaN | DB9: NaN | DC9: 1 | DD9: 0 | DE9: 1 | DF9: 5 | DG9: 23 | DH9: 2.1111111 | DI9: 9 | DJ9: 999 | DK9: 5 | DL9: 2 | DM9: 999 | DN9: 9 | DO9: NaN | DP9: 6 | DQ9: 2 | DR9: 6 | DS9: 6 | DT9: NaN | DU9: NaN | DV9: NaN | DW9: NaN | DX9: 19403 | DY9: 6 | DZ9: 1 | EA9: NaN | EB9: NaN | EC9: NaN | ED9: NaN | EE9: NaN | EF9: NaN | EG9: NaN | EH9: NaN | EI9: NaN | EJ9: NaN
A10: 10529 | B10: 110255 | C10: 187.4052 | D10: 4.142857 | E10: 4.727273 | F10: 3.818182 | G10: 4.857143 | H10: 5.384615 | I10: 4.461538 | J10: 67.8 | K10: White | L10: Male | M10: 4.89 | N10: 3.33 | O10: 0 | P10: 0 | Q10: 2 | R10: 6.17 | S10: 5.17 | T10: 5.63 | U10: 4.83 | V10: 5.4 | W10: 13 | X10: 1 | Y10: 2 | Z10: 5 | AA10: 5 | AB10: 6 | AC10: 5 | AD10: 8 | AE10: 4 | AF10: 2 | AG10: 25 | AH10: 40 | AI10: 10 | AJ10: 1 | AK10: 0 | AL10: 0 | AM10: 0 | AN10: 0 | AO10: 0 | AP10: 2.6 | AQ10: 10 | AR10: 1.25 | AS10: 86 | AT10: 0 | AU10: 9999 | AV10: 0.1 | AW10: 0 | AX10: 0 | AY10: 0 | AZ10: 0 | BA10: 0 | BB10: 0 | BC10: 0 | BD10: 0 | BE10: 0 | BF10: 20 | BG10: 0 | BH10: 0 | BI10: 0 | BJ10: 0 | BK10: 0 | BL10: 0 | BM10: 0 | BN10: 0 | BO10: 8991 | BP10: 0 | BQ10: 0 | BR10: 0 | BS10: 0 | BT10: 3.8 | BU10: 3.8 | BV10: 3.9 | BW10: 3.83 | BX10: 6 | BY10: 5.1666667 | BZ10: 6 | CA10: 5.1666667 | CB10: 1.35 | CC10: 0 | CD10: 0 | CE10: 32 | CF10: 17 | CG10: 12 | CH10: 1 | CI10: 43 | CJ10: 30 | CK10: 45 | CL10: 27 | CM10: 28 | CN10: 48 | CO10: 55 | CP10: 48 | CQ10: 49 | CR10: 48 | CS10: 60 | CT10: 0 | CU10: 0 | CV10: 7 | CW10: 1 | CX10: 45106 | CY10: 20208 | CZ10: 68.17 | DA10: NaN | DB10: NaN | DC10: 1 | DD10: 0 | DE10: 2 | DF10: 6 | DG10: 28 | DH10: 2.2222222 | DI10: 12 | DJ10: 999 | DK10: 7 | DL10: 0 | DM10: 999 | DN10: 11 | DO10: 3.5 | DP10: 1 | DQ10: 0 | DR10: 1 | DS10: 1 | DT10: NaN | DU10: NaN | DV10: NaN | DW10: NaN | DX10: 19120 | DY10: 1 | DZ10: 0 | EA10: NaN | EB10: NaN | EC10: NaN | ED10: NaN | EE10: NaN | EF10: NaN | EG10: NaN | EH10: NaN | EI10: 0 | EJ10: NaN
A11: 10541 | B11: 30253 | C11: -48.674747 | D11: 5.384615 | E11: 5.142857 | F11: 3.833333 | G11: 4.5 | H11: 6 | I11: 4.166667 | J11: 69.16 | K11: White | L11: Male | M11: 4.22 | N11: 2.67 | O11: 3 | P11: 14 | Q11: 0 | R11: 0 | S11: 0 | T11: 0 | U11: 0 | V11: 0 | W11: 20 | X11: 1 | Y11: 5 | Z11: 2 | AA11: 12 | AB11: 8 | AC11: 6 | AD11: 6 | AE11: 7 | AF11: 5 | AG11: 32 | AH11: 25 | AI11: 10 | AJ11: 0 | AK11: 0 | AL11: 4.25 | AM11: 4 | AN11: 5.5 | AO11: 3.25 | AP11: 2.8 | AQ11: 7 | AR11: 3.75 | AS11: 83 | AT11: 3.17 | AU11: 4.11 | AV11: 0 | AW11: 0 | AX11: 0 | AY11: 0 | AZ11: 0 | BA11: 0 | BB11: 0 | BC11: 0 | BD11: 0 | BE11: 0 | BF11: 20 | BG11: 0 | BH11: 0 | BI11: 0 | BJ11: 0 | BK11: 0 | BL11: 0 | BM11: 0 | BN11: 0 | BO11: 8991 | BP11: 0 | BQ11: 0 | BR11: 0 | BS11: 0 | BT11: 3.4 | BU11: 3.1 | BV11: 3.4 | BW11: 3.3 | BX11: 2.3333333 | BY11: 3.6666667 | BZ11: 4.5 | CA11: 3.5 | CB11: 1.3 | CC11: 2 | CD11: 0 | CE11: 27 | CF11: 16 | CG11: 11 | CH11: 1.1 | CI11: 35 | CJ11: 27 | CK11: 36 | CL11: 30 | CM11: 31 | CN11: 48 | CO11: 57 | CP11: 48 | CQ11: 58 | CR11: 41 | CS11: 60 | CT11: 0 | CU11: 0 | CV11: 3 | CW11: 1 | CX11: 45106 | CY11: 19652 | CZ11: 69.69 | DA11: NaN | DB11: NaN | DC11: 1 | DD11: 0 | DE11: 0 | DF11: 0 | DG11: 24 | DH11: 1.9444444 | DI11: 12 | DJ11: 999 | DK11: 4 | DL11: 1 | DM11: 999 | DN11: 9 | DO11: 3.5833333 | DP11: 5 | DQ11: 4 | DR11: 8 | DS11: 5 | DT11: NaN | DU11: NaN | DV11: NaN | DW11: 1 | DX11: 7067 | DY11: 8 | DZ11: 1 | EA11: NaN | EB11: NaN | EC11: NaN | ED11: NaN | EE11: NaN | EF11: NaN | EG11: NaN | EH11: NaN | EI11: 0 | EJ11: NaN
A12: 10555 | B12: 141294 | C12: 218.31717 | D12: NaN | E12: NaN | F12: NaN | G12: NaN | H12: NaN | I12: NaN | J12: 28.86 | K12: White | L12: Female | M12: 3.67 | N12: 3.67 | O12: 5 | P12: 18 | Q12: 0 | R12: 3.83 | S12: 2.67 | T12: 4.5 | U12: 4.5 | V12: 3.83 | W12: 71 | X12: 25 | Y12: 25 | Z12: 7 | AA12: 14 | AB12: 7 | AC12: 9 | AD12: 7 | AE12: 8 | AF12: 2 | AG12: 33 | AH12: 35 | AI12: 17 | AJ12: 0 | AK12: 0 | AL12: 0 | AM12: 0 | AN12: 0 | AO12: 0 | AP12: 3.6 | AQ12: 17 | AR12: 3.25 | AS12: 84 | AT12: 0 | AU12: 3.2 | AV12: 49.1 | AW12: 41 | AX12: 1.5 | AY12: 1 | AZ12: 0 | BA12: 0.75 | BB12: 0.75 | BC12: 0.75 | BD12: 1.25 | BE12: 0.85714286 | BF12: 100 | BG12: 80 | BH12: 0 | BI12: 0 | BJ12: 0 | BK12: 0 | BL12: 0 | BM12: 32 | BN12: 27 | BO12: 8991 | BP12: 0 | BQ12: 0 | BR12: 0 | BS12: 0 | BT12: 3.8 | BU12: 4.2 | BV12: 3.6 | BW12: 3.87 | BX12: 5 | BY12: 5.6666667 | BZ12: 6 | CA12: 5.1666667 | CB12: 2.35 | CC12: 0 | CD12: 0 | CE12: 33 | CF12: 19 | CG12: 12 | CH12: 1 | CI12: 45 | CJ12: 30 | CK12: 47 | CL12: 26 | CM12: 0 | CN12: 48 | CO12: 59 | CP12: 35 | CQ12: 60 | CR12: 45 | CS12: 60 | CT12: 0 | CU12: 0 | CV12: 5 | CW12: 1 | CX12: 45106 | CY12: 34427 | CZ12: 29.24 | DA12: NaN | DB12: NaN | DC12: 3 | DD12: 8 | DE12: 5 | DF12: NaN | DG12: 0 | DH12: 3.1666667 | DI12: 7 | DJ12: 999 | DK12: 6 | DL12: 11 | DM12: 999 | DN12: 11 | DO12: 4.5 | DP12: 4 | DQ12: 2 | DR12: 5 | DS12: 4 | DT12: NaN | DU12: NaN | DV12: NaN | DW12: 1 | DX12: 18077 | DY12: 5 | DZ12: 1 | EA12: NaN | EB12: NaN | EC12: NaN | ED12: NaN | EE12: NaN | EF12: NaN | EG12: NaN | EH12: NaN | EI12: NaN | EJ12: NaN
A13: 10559 | B13: 131894 | C13: -63.871857 | D13: NaN | E13: NaN | F13: NaN | G13: NaN | H13: NaN | I13: NaN | J13: 28.31 | K13: Black or African American | L13: Male | M13: 4.44 | N13: 3.8 | O13: 9 | P13: 3 | Q13: 0 | R13: 0 | S13: 0 | T13: 0 | U13: 0 | V13: 0 | W13: 0 | X13: 0 | Y13: 0 | Z13: 0 | AA13: 0 | AB13: 0 | AC13: 0 | AD13: 0 | AE13: 0 | AF13: 0 | AG13: 0 | AH13: 25 | AI13: 12 | AJ13: 0 | AK13: 0 | AL13: 5 | AM13: 5.5 | AN13: 5.25 | AO13: 4.25 | AP13: 2.5 | AQ13: 12 | AR13: 1.08 | AS13: 81 | AT13: 1.67 | AU13: 1.63 | AV13: 0 | AW13: 0 | AX13: 0 | AY13: 0 | AZ13: 0 | BA13: 0 | BB13: 0 | BC13: 0 | BD13: 0 | BE13: 0 | BF13: 20 | BG13: 0 | BH13: 0 | BI13: 0 | BJ13: 0 | BK13: 0 | BL13: 0 | BM13: 0 | BN13: 0 | BO13: 8991 | BP13: 0 | BQ13: 0 | BR13: 0 | BS13: 0 | BT13: 4 | BU13: 4.4 | BV13: 4.1 | BW13: 4.1666667 | BX13: 1 | BY13: 1 | BZ13: 1 | CA13: 1 | CB13: 2.4 | CC13: 0 | CD13: 0 | CE13: 23 | CF13: 20 | CG13: 10 | CH13: 1 | CI13: 33 | CJ13: 43 | CK13: 42 | CL13: 19 | CM13: 32 | CN13: 48 | CO13: 44 | CP13: 47 | CQ13: 57 | CR13: 48 | CS13: 60 | CT13: 0 | CU13: 0 | CV13: 5 | CW13: 2 | CX13: NaN | CY13: NaN | CZ13: NaN | DA13: NaN | DB13: NaN | DC13: 13 | DD13: 5 | DE13: 2 | DF13: 16 | DG13: 0 | DH13: 2.5625 | DI13: 1 | DJ13: 10 | DK13: 7 | DL13: 0 | DM13: 14 | DN13: 9 | DO13: 4.0833333 | DP13: 5 | DQ13: 5 | DR13: 7 | DS13: 5 | DT13: NaN | DU13: NaN | DV13: NaN | DW13: 4 | DX13: 19454 | DY13: 7 | DZ13: 1 | EA13: NaN | EB13: NaN | EC13: NaN | ED13: NaN | EE13: NaN | EF13: NaN | EG13: NaN | EH13: NaN | EI13: NaN | EJ13: NaN
A14: 10572 | B14: 10252 | C14: 165.76556 | D14: 3 | E14: 3.090909 | F14: 3.5 | G14: 3.454545 | H14: 4.545455 | I14: 3.166667 | J14: 70.46 | K14: White | L14: Female | M14: 4.22 | N14: 3.1 | O14: 0 | P14: 0 | Q14: 0 | R14: 6.17 | S14: 5.67 | T14: 6.13 | U14: 5.17 | V14: 5.83 | W14: 4 | X14: 0 | Y14: 1 | Z14: 0 | AA14: 3 | AB14: 2 | AC14: 4 | AD14: 5 | AE14: 3 | AF14: 4 | AG14: 18 | AH14: 31 | AI14: 12 | AJ14: 0 | AK14: 0 | AL14: 6 | AM14: 6 | AN14: 6 | AO14: 6 | AP14: 2.6 | AQ14: 6 | AR14: 2.25 | AS14: 91 | AT14: 3.17 | AU14: 2.69 | AV14: 72 | AW14: 0 | AX14: 0 | AY14: 0 | AZ14: 0 | BA14: 0 | BB14: 0 | BC14: 0 | BD14: 0 | BE14: 0 | BF14: 20 | BG14: 0 | BH14: 0 | BI14: 0 | BJ14: 0 | BK14: 0 | BL14: 0 | BM14: 0 | BN14: 0 | BO14: 8991 | BP14: 0 | BQ14: 0 | BR14: 0 | BS14: 0 | BT14: 3.2 | BU14: 3.3 | BV14: 3.7 | BW14: 3.4 | BX14: 2.6666667 | BY14: 2.6666667 | BZ14: 4.3333333 | CA14: 2.6666667 | CB14: 0.3 | CC14: 0 | CD14: 0 | CE14: 29 | CF14: 18 | CG14: 11 | CH14: 0.91666667 | CI14: 40 | CJ14: 28 | CK14: 42 | CL14: 27 | CM14: 29 | CN14: 46 | CO14: 60 | CP14: 42 | CQ14: 60 | CR14: 29 | CS14: 60 | CT14: 0 | CU14: 0 | CV14: 2 | CW14: 1 | CX14: 45106 | CY14: 19250 | CZ14: 70.79 | DA14: NaN | DB14: NaN | DC14: 1 | DD14: 0 | DE14: 0 | DF14: NaN | DG14: 28 | DH14: 2.3333333 | DI14: 12 | DJ14: 999 | DK14: 6 | DL14: 2 | DM14: 999 | DN14: 8 | DO14: NaN | DP14: 5 | DQ14: 1 | DR14: 7 | DS14: 5 | DT14: NaN | DU14: NaN | DV14: NaN | DW14: 1 | DX14: 18249 | DY14: 7 | DZ14: 1 | EA14: NaN | EB14: NaN | EC14: NaN | ED14: NaN | EE14: NaN | EF14: NaN | EG14: NaN | EH14: NaN | EI14: 0 | EJ14: NaN
A15: 10581 | B15: 101274 | C15: 181.56469 | D15: 3.4 | E15: 2.25 | F15: 4.545455 | G15: 3 | H15: 6.545455 | I15: 5.571429 | J15: 48.03 | K15: Black or African American | L15: Male | M15: 4.44 | N15: 3.78 | O15: 4 | P15: 2 | Q15: 0 | R15: 0 | S15: 0 | T15: 0 | U15: 0 | V15: 0 | W15: 18 | X15: 2 | Y15: 7 | Z15: 2 | AA15: 7 | AB15: 1 | AC15: 5 | AD15: 4 | AE15: 3 | AF15: 3 | AG15: 16 | AH15: 29 | AI15: 9 | AJ15: 0 | AK15: 0 | AL15: 5.67 | AM15: 6 | AN15: 6 | AO15: 5 | AP15: 2.9 | AQ15: 6 | AR15: 1.83 | AS15: 84 | AT15: 0 | AU15: 9999 | AV15: 154.1 | AW15: 0 | AX15: 0 | AY15: 0 | AZ15: 0 | BA15: 0 | BB15: 0 | BC15: 0 | BD15: 0 | BE15: 0 | BF15: 20 | BG15: 0 | BH15: 0 | BI15: 0 | BJ15: 0 | BK15: 0 | BL15: 0 | BM15: 0 | BN15: 0 | BO15: 8991 | BP15: 0 | BQ15: 0 | BR15: 0 | BS15: 0 | BT15: 4.1 | BU15: 3.5 | BV15: 4.2 | BW15: 3.93 | BX15: 1 | BY15: 1 | BZ15: 1 | CA15: 1 | CB15: 0.3 | CC15: 4 | CD15: 1 | CE15: 20 | CF15: 20 | CG15: 6 | CH15: 0.66666667 | CI15: 20 | CJ15: 33 | CK15: 43 | CL15: 20 | CM15: 20 | CN15: 42 | CO15: 60 | CP15: 30 | CQ15: 60 | CR15: 30 | CS15: 60 | CT15: 0 | CU15: 0 | CV15: 2 | CW15: 2 | CX15: 45106 | CY15: 27360 | CZ15: 48.59 | DA15: NaN | DB15: NaN | DC15: 3 | DD15: 0 | DE15: 4 | DF15: 2 | DG15: 0 | DH15: 2.5 | DI15: 9 | DJ15: 999 | DK15: 6 | DL15: 0 | DM15: 999 | DN15: 9 | DO15: 5 | DP15: 1 | DQ15: 0 | DR15: 6 | DS15: 1 | DT15: NaN | DU15: NaN | DV15: NaN | DW15: 1 | DX15: 19138 | DY15: 6 | DZ15: 1 | EA15: NaN | EB15: NaN | EC15: NaN | ED15: NaN | EE15: NaN | EF15: NaN | EG15: NaN | EH15: NaN | EI15: NaN | EJ15: NaN
A16: 10584 | B16: 221173 | C16: 343.12092 | D16: 3.571429 | E16: 3.8 | F16: 2.833333 | G16: 5.090909 | H16: 3.090909 | I16: 2.25 | J16: 49.64 | K16: White | L16: Female | M16: 4.22 | N16: 3 | O16: 1 | P16: 3 | Q16: 0 | R16: 5.83 | S16: 4.83 | T16: 5.63 | U16: 4.33 | V16: 5.13 | W16: 16 | X16: 1 | Y16: 5 | Z16: 1 | AA16: 9 | AB16: 4 | AC16: 6 | AD16: 8 | AE16: 6 | AF16: 3 | AG16: 27 | AH16: 30 | AI16: 14 | AJ16: 0 | AK16: 0 | AL16: 5.5 | AM16: 6 | AN16: 4.5 | AO16: 6 | AP16: 3 | AQ16: 15 | AR16: 1.42 | AS16: 90 | AT16: 0 | AU16: 2.63 | AV16: 55 | AW16: 21 | AX16: 0 | AY16: 0 | AZ16: 0 | BA16: 0 | BB16: 0 | BC16: 0 | BD16: 0 | BE16: 0 | BF16: 94 | BG16: 74 | BH16: 0 | BI16: 0 | BJ16: 0 | BK16: 0 | BL16: 0 | BM16: 0 | BN16: 0 | BO16: 8991 | BP16: 0 | BQ16: 0 | BR16: 0 | BS16: 0 | BT16: 3.8 | BU16: 4 | BV16: 4.2 | BW16: 4 | BX16: 6 | BY16: 6 | BZ16: 6 | CA16: 3.8333333 | CB16: 1.35 | CC16: 0 | CD16: 0 | CE16: 28 | CF16: 20 | CG16: 10 | CH16: 0.90909091 | CI16: 38 | CJ16: 45 | CK16: 44 | CL16: 30 | CM16: 38 | CN16: 48 | CO16: 50 | CP16: 47 | CQ16: 60 | CR16: 39 | CS16: 60 | CT16: 0 | CU16: 0 | CV16: 6 | CW16: 2 | CX16: 45001 | CY16: 26779 | CZ16: 49.89 | DA16: 4 | DB16: 1 | DC16: 3 | DD16: 0 | DE16: 1 | DF16: 4 | DG16: 0 | DH16: 2.4444444 | DI16: 12 | DJ16: 999 | DK16: 7 | DL16: 2 | DM16: 999 | DN16: 10 | DO16: 3.5 | DP16: 5 | DQ16: 5 | DR16: 8 | DS16: 5 | DT16: NaN | DU16: NaN | DV16: NaN | DW16: NaN | DX16: 19027 | DY16: 8 | DZ16: 1 | EA16: NaN | EB16: NaN | EC16: NaN | ED16: NaN | EE16: NaN | EF16: NaN | EG16: NaN | EH16: NaN | EI16: NaN | EJ16: NaN
A17: 10585 | B17: 161859 | C17: 119.63799 | D17: 4.666667 | E17: 4.363636 | F17: 4.923077 | G17: 4.769231 | H17: 5.714286 | I17: 5.833333 | J17: 63.33 | K17: White | L17: Female | M17: 4.67 | N17: 4 | O17: 4 | P17: 4 | Q17: 0 | R17: 6.67 | S17: 5.67 | T17: 5.63 | U17: 5.17 | V17: 5.8 | W17: 19 | X17: 2 | Y17: 12 | Z17: 4 | AA17: 1 | AB17: 0 | AC17: 5 | AD17: 6 | AE17: 1 | AF17: 1 | AG17: 13 | AH17: 30 | AI17: 9 | AJ17: 0 | AK17: 0 | AL17: 6 | AM17: 6 | AN17: 6 | AO17: 6 | AP17: 3 | AQ17: 11 | AR17: 2.58 | AS17: 84 | AT17: 0 | AU17: 3.43 | AV17: 0 | AW17: 0 | AX17: 0 | AY17: 0 | AZ17: 0 | BA17: 0 | BB17: 0 | BC17: 0 | BD17: 0 | BE17: 0 | BF17: 20 | BG17: 0 | BH17: 0 | BI17: 0 | BJ17: 0 | BK17: 0 | BL17: 0 | BM17: 0 | BN17: 0 | BO17: 8991 | BP17: 0 | BQ17: 0 | BR17: 0 | BS17: 0 | BT17: 3.6 | BU17: 3.7 | BV17: 3.9 | BW17: 3.73 | BX17: 2.6666667 | BY17: 3.3333333 | BZ17: 6 | CA17: 4 | CB17: 1.8 | CC17: 0 | CD17: 0 | CE17: 22 | CF17: 20 | CG17: 9 | CH17: 0.9 | CI17: 31 | CJ17: 28 | CK17: 36 | CL17: 32 | CM17: 29 | CN17: 38 | CO17: 60 | CP17: 34 | CQ17: 60 | CR17: 27 | CS17: 60 | CT17: 0 | CU17: 0 | CV17: 7 | CW17: 1 | CX17: 45106 | CY17: 21854 | CZ17: 63.66 | DA17: NaN | DB17: NaN | DC17: 0 | DD17: 0 | DE17: 1 | DF17: NaN | DG17: 28 | DH17: 2.6111111 | DI17: 12 | DJ17: 999 | DK17: 7 | DL17: 1 | DM17: 999 | DN17: 10 | DO17: NaN | DP17: 6 | DQ17: 3 | DR17: 8 | DS17: 6 | DT17: NaN | DU17: NaN | DV17: NaN | DW17: 2 | DX17: 11793 | DY17: 8 | DZ17: 1 | EA17: NaN | EB17: NaN | EC17: NaN | ED17: NaN | EE17: NaN | EF17: NaN | EG17: NaN | EH17: NaN | EI17: 0 | EJ17: NaN
A18: 10589 | B18: 161988 | C18: 26.772347 | D18: 3.857143 | E18: 4.461538 | F18: 3.846154 | G18: 4.615385 | H18: 6 | I18: 5 | J18: 34.87 | K18: White | L18: Male | M18: 4.44 | N18: 2.5 | O18: 2 | P18: 13 | Q18: 0 | R18: 2.83 | S18: 3 | T18: 3.75 | U18: 3.83 | V18: 3.23 | W18: 45 | X18: 10 | Y18: 21 | Z18: 4 | AA18: 10 | AB18: 4 | AC18: 8 | AD18: 6 | AE18: 6 | AF18: 6 | AG18: 30 | AH18: 26 | AI18: 17 | AJ18: 0 | AK18: 0 | AL18: 0 | AM18: 0 | AN18: 0 | AO18: 0 | AP18: 3.9 | AQ18: 18 | AR18: 4.58 | AS18: 94 | AT18: 0 | AU18: 4.46 | AV18: 44 | AW18: 0 | AX18: 0 | AY18: 0 | AZ18: 0 | BA18: 0 | BB18: 0 | BC18: 0 | BD18: 0 | BE18: 0 | BF18: 20 | BG18: 0 | BH18: 0 | BI18: 0 | BJ18: 0 | BK18: 0 | BL18: 0 | BM18: 0 | BN18: 0 | BO18: 8991 | BP18: 0 | BQ18: 0 | BR18: 0 | BS18: 0 | BT18: 2.2 | BU18: 2.9 | BV18: 3.4 | BW18: 2.83 | BX18: 1.6666667 | BY18: 2.6666667 | BZ18: 3.3333333 | CA18: 3.8333333 | CB18: 1.7 | CC18: 0 | CD18: 0 | CE18: 20 | CF18: 27 | CG18: 6 | CH18: 0.66666667 | CI18: 25 | CJ18: 41 | CK18: 56 | CL18: 23 | CM18: 34 | CN18: 48 | CO18: 58 | CP18: 42 | CQ18: 60 | CR18: 29 | CS18: 60 | CT18: 0 | CU18: 0 | CV18: 5 | CW18: 1 | CX18: 45106 | CY18: 32284 | CZ18: 35.11 | DA18: NaN | DB18: NaN | DC18: 8 | DD18: 5 | DE18: 4 | DF18: 6 | DG18: 26 | DH18: 2.5 | DI18: 12 | DJ18: 999 | DK18: 7 | DL18: 0 | DM18: 999 | DN18: 12 | DO18: 3.5833333 | DP18: 5 | DQ18: 0 | DR18: 3 | DS18: 5 | DT18: NaN | DU18: NaN | DV18: NaN | DW18: NaN | DX18: 19468 | DY18: 3 | DZ18: 0 | EA18: NaN | EB18: NaN | EC18: NaN | ED18: NaN | EE18: NaN | EF18: NaN | EG18: NaN | EH18: NaN | EI18: NaN | EJ18: NaN
A19: 10590 | B19: 30467 | C19: -34.553622 | D19: 2.222222 | E19: 3.5 | F19: 3.076923 | G19: 4.333333 | H19: 5.857143 | I19: 6.166667 | J19: 56.4 | K19: White | L19: Female | M19: 4.56 | N19: 4.2 | O19: 1 | P19: 2 | Q19: 0 | R19: 6.67 | S19: 4.33 | T19: 4.5 | U19: 5.67 | V19: 5.23 | W19: 17 | X19: 2 | Y19: 5 | Z19: 1 | AA19: 9 | AB19: 3 | AC19: 5 | AD19: 3 | AE19: 3 | AF19: 0 | AG19: 14 | AH19: 32 | AI19: 10 | AJ19: 0 | AK19: 0 | AL19: 6.75 | AM19: 7 | AN19: 6.25 | AO19: 7 | AP19: 2.9 | AQ19: 12 | AR19: 3.67 | AS19: 90 | AT19: 3 | AU19: 3.86 | AV19: 0 | AW19: 0 | AX19: 0 | AY19: 0 | AZ19: 0 | BA19: 0 | BB19: 0 | BC19: 0 | BD19: 0 | BE19: 0 | BF19: 20 | BG19: 0 | BH19: 0 | BI19: 0 | BJ19: 0 | BK19: 0 | BL19: 0 | BM19: 0 | BN19: 0 | BO19: 8991 | BP19: 0 | BQ19: 0 | BR19: 0 | BS19: 0 | BT19: 3.2 | BU19: 3.7 | BV19: 3.9 | BW19: 3.6 | BX19: 6 | BY19: 5.6666667 | BZ19: 6 | CA19: 5.6666667 | CB19: 0.55 | CC19: 0 | CD19: 0 | CE19: 27 | CF19: 0 | CG19: 7 | CH19: 0.63636364 | CI19: 34 | CJ19: 53 | CK19: 54 | CL19: 31 | CM19: 33 | CN19: 48 | CO19: 60 | CP19: 47 | CQ19: 60 | CR19: 48 | CS19: 60 | CT19: 0 | CU19: 0 | CV19: 4 | CW19: 1 | CX19: 45000 | CY19: 24498 | CZ19: 56.13 | DA19: 4 | DB19: 1 | DC19: 0 | DD19: 0 | DE19: 0 | DF19: 4 | DG19: 0 | DH19: 2.6111111 | DI19: 10 | DJ19: 999 | DK19: 7 | DL19: 1 | DM19: 999 | DN19: 8 | DO19: 4.1666667 | DP19: 6 | DQ19: 4 | DR19: 6 | DS19: 6 | DT19: NaN | DU19: NaN | DV19: NaN | DW19: 2 | DX19: 21701 | DY19: 6 | DZ19: 0 | EA19: NaN | EB19: NaN | EC19: NaN | ED19: NaN | EE19: NaN | EF19: NaN | EG19: NaN | EH19: NaN | EI19: 0 | EJ19: NaN
A20: 10596 | B20: 130995 | C20: 325.05229 | D20: 3.272727 | E20: 5.25 | F20: 5.076923 | G20: 6.142857 | H20: 6.461538 | I20: 5.142857 | J20: 27.27 | K20: White | L20: Female | M20: 3.67 | N20: 2.89 | O20: 8 | P20: 13 | Q20: 0 | R20: 4.5 | S20: 4.17 | T20: 4.25 | U20: 4.83 | V20: 4.43 | W20: 35 | X20: 17 | Y20: 15 | Z20: 3 | AA20: 0 | AB20: 0 | AC20: 5 | AD20: 3 | AE20: 3 | AF20: 2 | AG20: 13 | AH20: 24 | AI20: 14 | AJ20: 0 | AK20: 0 | AL20: 0 | AM20: 0 | AN20: 0 | AO20: 0 | AP20: 3.6 | AQ20: 12 | AR20: 3.17 | AS20: 82 | AT20: 0 | AU20: 3.57 | AV20: 50.1 | AW20: 0 | AX20: 0 | AY20: 0 | AZ20: 0 | BA20: 0 | BB20: 0 | BC20: 0 | BD20: 0 | BE20: 0 | BF20: 20 | BG20: 0 | BH20: 0 | BI20: 0 | BJ20: 0 | BK20: 0 | BL20: 0 | BM20: 0 | BN20: 0 | BO20: 8991 | BP20: 0 | BQ20: 0 | BR20: 0 | BS20: 0 | BT20: 2.9 | BU20: 3.8 | BV20: 3.5 | BW20: 3.4 | BX20: 2.6666667 | BY20: 2.6666667 | BZ20: 2.6666667 | CA20: 1.8333333 | CB20: 2.15 | CC20: 0 | CD20: 0 | CE20: 24 | CF20: 20 | CG20: 9 | CH20: 0.81818182 | CI20: 31 | CJ20: 31 | CK20: 52 | CL20: 24 | CM20: 37 | CN20: 48 | CO20: 54 | CP20: 47 | CQ20: 60 | CR20: 29 | CS20: 60 | CT20: 0 | CU20: 0 | CV20: 4 | CW20: 1 | CX20: 45106 | CY20: 35004 | CZ20: 27.66 | DA20: NaN | DB20: NaN | DC20: 0 | DD20: 0 | DE20: 3 | DF20: NaN | DG20: 26 | DH20: 2.0555556 | DI20: 6 | DJ20: 999 | DK20: 4 | DL20: 4 | DM20: 999 | DN20: 11 | DO20: 4.3333333 | DP20: 4 | DQ20: 1 | DR20: 2 | DS20: 4 | DT20: NaN | DU20: NaN | DV20: NaN | DW20: NaN | DX20: NaN | DY20: 2 | DZ20: 1 | EA20: NaN | EB20: NaN | EC20: NaN | ED20: NaN | EE20: NaN | EF20: NaN | EG20: NaN | EH20: NaN | EI20: NaN | EJ20: NaN
A21: 10603 | B21: 31853 | C21: -234.82856 | D21: 4.5 | E21: 4.5 | F21: 3.2 | G21: 3 | H21: 5.5 | I21: 5 | J21: 69.22 | K21: Black or African American | L21: Female | M21: 3.56 | N21: 3 | O21: 5 | P21: 0 | Q21: 0 | R21: 7 | S21: 6.5 | T21: 6.88 | U21: 5.17 | V21: 6.37 | W21: 1 | X21: 0 | Y21: 1 | Z21: 0 | AA21: 0 | AB21: 3 | AC21: 2 | AD21: 2 | AE21: 2 | AF21: 3 | AG21: 12 | AH21: 30 | AI21: 11 | AJ21: 0 | AK21: 0 | AL21: 4.08 | AM21: 5 | AN21: 2 | AO21: 5.25 | AP21: 2.4 | AQ21: 11 | AR21: 1.42 | AS21: 91 | AT21: 0 | AU21: 1.54 | AV21: 0 | AW21: 0 | AX21: 0 | AY21: 0 | AZ21: 0 | BA21: 0 | BB21: 0 | BC21: 0 | BD21: 0 | BE21: 0 | BF21: 20 | BG21: 0 | BH21: 0 | BI21: 0 | BJ21: 0 | BK21: 0 | BL21: 0 | BM21: 0 | BN21: 0 | BO21: 8991 | BP21: 0 | BQ21: 0 | BR21: 0 | BS21: 0 | BT21: 3.4 | BU21: 3.7 | BV21: 3.7 | BW21: 3.6 | BX21: 6 | BY21: 6 | BZ21: 6 | CA21: 6 | CB21: 1.65 | CC21: 0 | CD21: 0 | CE21: 27 | CF21: 25 | CG21: 9 | CH21: 0.9 | CI21: 36 | CJ21: 24 | CK21: 42 | CL21: 27 | CM21: 32 | CN21: 42 | CO21: 60 | CP21: 43 | CQ21: 60 | CR21: 37 | CS21: 60 | CT21: 0 | CU21: 0 | CV21: 7 | CW21: 1 | CX21: 45034 | CY21: 19676 | CZ21: 69.43 | DA21: NaN | DB21: NaN | DC21: 0 | DD21: 0 | DE21: 0 | DF21: NaN | DG21: 28 | DH21: 2.5555556 | DI21: 12 | DJ21: 999 | DK21: 5 | DL21: 0 | DM21: 999 | DN21: 9 | DO21: 4.1666667 | DP21: 4 | DQ21: 0 | DR21: 8 | DS21: 4 | DT21: NaN | DU21: NaN | DV21: NaN | DW21: NaN | DX21: 19133 | DY21: 8 | DZ21: 1 | EA21: NaN | EB21: NaN | EC21: NaN | ED21: NaN | EE21: NaN | EF21: NaN | EG21: NaN | EH21: NaN | EI21: 0 | EJ21: NaN
A22: 10606 | B22: 51200 | C22: 137.70306 | D22: 5.384615 | E22: 6.166667 | F22: 5.230769 | G22: 6 | H22: 6.307692 | I22: 5.571429 | J22: 22.4 | K22: White | L22: Female | M22: 3.89 | N22: 3.56 | O22: 0 | P22: 0 | Q22: 0 | R22: 7 | S22: 5.33 | T22: 6.13 | U22: 4.17 | V22: 5.73 | W22: 7 | X22: 4 | Y22: 1 | Z22: 1 | AA22: 1 | AB22: 2 | AC22: 5 | AD22: 6 | AE22: 2 | AF22: 0 | AG22: 15 | AH22: 23 | AI22: 11 | AJ22: 0 | AK22: 0 | AL22: 0 | AM22: 0 | AN22: 0 | AO22: 0 | AP22: 3.2 | AQ22: 6 | AR22: 1.58 | AS22: 96 | AT22: 0 | AU22: 2.77 | AV22: 0 | AW22: 0 | AX22: 0 | AY22: 0 | AZ22: 0 | BA22: 0 | BB22: 0 | BC22: 0 | BD22: 0 | BE22: 0 | BF22: 20 | BG22: 0 | BH22: 0 | BI22: 0 | BJ22: 0 | BK22: 0 | BL22: 0 | BM22: 0 | BN22: 0 | BO22: 8991 | BP22: 0 | BQ22: 0 | BR22: 0 | BS22: 0 | BT22: 3.6 | BU22: 4.2 | BV22: 3.6 | BW22: 3.8 | BX22: 6 | BY22: 5.1666667 | BZ22: 6 | CA22: 5.1666667 | CB22: 0 | CC22: 0 | CD22: 0 | CE22: 33 | CF22: 20 | CG22: 0 | CH22: 0 | CI22: 32 | CJ22: 42 | CK22: 55 | CL22: 21 | CM22: 38 | CN22: 48 | CO22: 0 | CP22: 48 | CQ22: 56 | CR22: 48 | CS22: 60 | CT22: 0 | CU22: 0 | CV22: 5 | CW22: 1 | CX22: 45106 | CY22: 36779 | CZ22: 22.8 | DA22: NaN | DB22: NaN | DC22: 0 | DD22: 0 | DE22: 1 | DF22: NaN | DG22: 28 | DH22: 2.2777778 | DI22: 8 | DJ22: 999 | DK22: 6 | DL22: 2 | DM22: 999 | DN22: 11 | DO22: 3.9166667 | DP22: 5 | DQ22: 4 | DR22: 6 | DS22: 5 | DT22: NaN | DU22: NaN | DV22: NaN | DW22: 3 | DX22: 8077 | DY22: 6 | DZ22: 1 | EA22: NaN | EB22: NaN | EC22: NaN | ED22: NaN | EE22: NaN | EF22: NaN | EG22: NaN | EH22: NaN | EI22: NaN | EJ22: NaN
A23: 10608 | B23: 40594 | C23: 202.18248 | D23: 3 | E23: 2 | F23: 2.4 | G23: 2.5 | H23: 6.857143 | I23: 4.666667 | J23: 29.07 | K23: Black or African American | L23: Female | M23: 3.67 | N23: 3.11 | O23: 0 | P23: 6 | Q23: 0 | R23: 5.67 | S23: 5.33 | T23: 5.75 | U23: 3.17 | V23: 5 | W23: 50 | X23: 13 | Y23: 17 | Z23: 6 | AA23: 14 | AB23: 6 | AC23: 9 | AD23: 8 | AE23: 5 | AF23: 3 | AG23: 31 | AH23: 32 | AI23: 10 | AJ23: 0 | AK23: 0 | AL23: 0 | AM23: 0 | AN23: 0 | AO23: 0 | AP23: 2.9 | AQ23: 9 | AR23: 2.17 | AS23: 97 | AT23: 0 | AU23: 2.06 | AV23: 18 | AW23: 0 | AX23: 0 | AY23: 0 | AZ23: 0 | BA23: 0 | BB23: 0 | BC23: 0 | BD23: 0 | BE23: 0 | BF23: 20 | BG23: 0 | BH23: 0 | BI23: 0 | BJ23: 0 | BK23: 0 | BL23: 0 | BM23: 0 | BN23: 0 | BO23: 8991 | BP23: 0 | BQ23: 0 | BR23: 0 | BS23: 0 | BT23: 3.3 | BU23: 4 | BV23: 3.7 | BW23: 3.67 | BX23: 2.3333333 | BY23: 3.5 | BZ23: 3 | CA23: 2.6666667 | CB23: 1.9 | CC23: 0 | CD23: 0 | CE23: 23 | CF23: 27 | CG23: 11 | CH23: 1.1 | CI23: 34 | CJ23: 28 | CK23: 31 | CL23: 26 | CM23: 33 | CN23: 38 | CO23: 60 | CP23: 33 | CQ23: 60 | CR23: 39 | CS23: 60 | CT23: 0 | CU23: 0 | CV23: 4 | CW23: 1 | CX23: 45105 | CY23: 34339 | CZ23: 29.48 | DA23: NaN | DB23: NaN | DC23: 3 | DD23: 2 | DE23: 3 | DF23: NaN | DG23: 28 | DH23: 2.7777778 | DI23: 12 | DJ23: 999 | DK23: 7 | DL23: 5 | DM23: 999 | DN23: 10 | DO23: 3.9166667 | DP23: 5 | DQ23: 1 | DR23: 5 | DS23: 5 | DT23: NaN | DU23: NaN | DV23: NaN | DW23: 1 | DX23: 19120 | DY23: 5 | DZ23: 1 | EA23: NaN | EB23: NaN | EC23: NaN | ED23: NaN | EE23: NaN | EF23: NaN | EG23: NaN | EH23: NaN | EI23: NaN | EJ23: NaN
A24: 10617 | B24: 190349 | C24: -136.95387 | D24: 5.2 | E24: 3.6 | F24: 4.666667 | G24: 4.571429 | H24: 5.428571 | I24: 3.666667 | J24: 73.4 | K24: White | L24: Female | M24: 5 | N24: 4.3 | O24: 0 | P24: 0 | Q24: 0 | R24: 6.5 | S24: 4.33 | T24: 6.88 | U24: 5.33 | V24: 6 | W24: 3 | X24: 0 | Y24: 2 | Z24: 1 | AA24: 0 | AB24: 1 | AC24: 1 | AD24: 1 | AE24: 0 | AF24: 2 | AG24: 5 | AH24: 36 | AI24: 13 | AJ24: 0 | AK24: 0 | AL24: 7 | AM24: 7 | AN24: 7 | AO24: 7 | AP24: 2.8 | AQ24: 6 | AR24: 2.33 | AS24: 90 | AT24: 4 | AU24: 9999 | AV24: 72.1 | AW24: 25 | AX24: 0 | AY24: 0 | AZ24: 0 | BA24: 0 | BB24: 0 | BC24: 0 | BD24: 0 | BE24: 0 | BF24: 81 | BG24: 61 | BH24: 0 | BI24: 0 | BJ24: 0 | BK24: 0 | BL24: 0 | BM24: 57 | BN24: 51 | BO24: 8991 | BP24: 0 | BQ24: 0 | BR24: 0 | BS24: 0 | BT24: 4.2 | BU24: 4 | BV24: 4 | BW24: 4.07 | BX24: 4 | BY24: 4 | BZ24: 5.1666667 | CA24: 5.3333333 | CB24: 0.45 | CC24: 0 | CD24: 0 | CE24: 23 | CF24: 30 | CG24: 8 | CH24: 0.72727273 | CI24: 31 | CJ24: 40 | CK24: 42 | CL24: 32 | CM24: 28 | CN24: 47 | CO24: 45 | CP24: 47 | CQ24: 41 | CR24: 48 | CS24: 48 | CT24: 0 | CU24: 0 | CV24: 6 | CW24: 2 | CX24: 45000 | CY24: 18203 | CZ24: 73.37 | DA24: 4 | DB24: 1 | DC24: 3 | DD24: 0 | DE24: 0 | DF24: 0 | DG24: 28 | DH24: 2.4444444 | DI24: 11 | DJ24: 999 | DK24: 6 | DL24: 0 | DM24: 999 | DN24: 9 | DO24: 5 | DP24: 6 | DQ24: 3 | DR24: 8 | DS24: 6 | DT24: NaN | DU24: NaN | DV24: NaN | DW24: 1 | DX24: 2174 | DY24: 8 | DZ24: 0 | EA24: NaN | EB24: NaN | EC24: NaN | ED24: NaN | EE24: NaN | EF24: NaN | EG24: NaN | EH24: NaN | EI24: 3 | EJ24: NaN
A25: 10636 | B25: 112596 | C25: 73.222181 | D25: 5.692308 | E25: 5.666667 | F25: 4.923077 | G25: 6.5 | H25: 6.666667 | I25: 5.846154 | J25: 26.81 | K25: Asian | L25: Female | M25: 3.89 | N25: 3.6 | O25: 3 | P25: 3 | Q25: 0 | R25: 5.67 | S25: 4.67 | T25: 6.5 | U25: 3.67 | V25: 5.3 | W25: 34 | X25: 9 | Y25: 16 | Z25: 0 | AA25: 9 | AB25: 0 | AC25: 3 | AD25: 3 | AE25: 2 | AF25: 0 | AG25: 8 | AH25: 21 | AI25: 12 | AJ25: 0 | AK25: 0 | AL25: 6.67 | AM25: 6.25 | AN25: 6.75 | AO25: 7 | AP25: 4.3 | AQ25: 17 | AR25: 4.25 | AS25: 88 | AT25: 3.5 | AU25: 4.77 | AV25: 31 | AW25: 0 | AX25: 0 | AY25: 0 | AZ25: 0 | BA25: 0 | BB25: 0 | BC25: 0 | BD25: 0 | BE25: 0 | BF25: 20 | BG25: 0 | BH25: 0 | BI25: 0 | BJ25: 0 | BK25: 0 | BL25: 0 | BM25: 0 | BN25: 0 | BO25: 8991 | BP25: 0 | BQ25: 0 | BR25: 0 | BS25: 0 | BT25: 3.6 | BU25: 3.9 | BV25: 4 | BW25: 3.83 | BX25: 6 | BY25: 5.1666667 | BZ25: 6 | CA25: 5.1666667 | CB25: 1.8 | CC25: 0 | CD25: 0 | CE25: 28 | CF25: 25 | CG25: 9 | CH25: 0.81818182 | CI25: 36 | CJ25: 32 | CK25: 48 | CL25: 26 | CM25: 34 | CN25: 48 | CO25: 58 | CP25: 40 | CQ25: 60 | CR25: 31 | CS25: 60 | CT25: 0 | CU25: 0 | CV25: 7 | CW25: 1 | CX25: 45001 | CY25: 35260 | CZ25: 26.67 | DA25: 1 | DB25: 1 | DC25: 5 | DD25: 0 | DE25: 0 | DF25: NaN | DG25: 0 | DH25: 2.4444444 | DI25: 12 | DJ25: 999 | DK25: 7 | DL25: 1 | DM25: 999 | DN25: 7 | DO25: 5 | DP25: 6 | DQ25: 4 | DR25: 6 | DS25: 6 | DT25: NaN | DU25: NaN | DV25: NaN | DW25: 1 | DX25: 19087 | DY25: 6 | DZ25: 0 | EA25: NaN | EB25: NaN | EC25: NaN | ED25: NaN | EE25: NaN | EF25: NaN | EG25: NaN | EH25: NaN | EI25: NaN | EJ25: NaN
A26: 10638 | B26: 101951 | C26: -95.447598 | D26: 5.714286 | E26: 6.166667 | F26: 5.076923 | G26: 6.428571 | H26: 6.461538 | I26: 5.428571 | J26: 71.83 | K26: White | L26: Female | M26: 4.56 | N26: 3.9 | O26: 1 | P26: 0 | Q26: 0 | R26: 5.67 | S26: 5.33 | T26: 6.13 | U26: 4.83 | V26: 5.63 | W26: 2 | X26: 1 | Y26: 1 | Z26: 0 | AA26: 0 | AB26: 0 | AC26: 5 | AD26: 9 | AE26: 1 | AF26: 2 | AG26: 17 | AH26: 40 | AI26: 10 | AJ26: 0 | AK26: 0 | AL26: 7 | AM26: 7 | AN26: 7 | AO26: 7 | AP26: 3 | AQ26: 12 | AR26: 2.75 | AS26: 86 | AT26: 2.67 | AU26: 9999 | AV26: 0 | AW26: 0 | AX26: 0 | AY26: 0 | AZ26: 0 | BA26: 0 | BB26: 0 | BC26: 0 | BD26: 0 | BE26: 0 | BF26: 20 | BG26: 0 | BH26: 0 | BI26: 0 | BJ26: 0 | BK26: 0 | BL26: 0 | BM26: 0 | BN26: 0 | BO26: 8991 | BP26: 0 | BQ26: 0 | BR26: 0 | BS26: 0 | BT26: 4.1 | BU26: 4.2 | BV26: 4.2 | BW26: 4.17 | BX26: 6 | BY26: 5.1666667 | BZ26: 6 | CA26: 5.1666667 | CB26: 0.85 | CC26: 0 | CD26: 0 | CE26: 19 | CF26: 24 | CG26: 7 | CH26: 0.875 | CI26: 26 | CJ26: 19 | CK26: 29 | CL26: 26 | CM26: 31 | CN26: 48 | CO26: 60 | CP26: 33 | CQ26: 60 | CR26: 42 | CS26: 60 | CT26: 0 | CU26: 0 | CV26: 6 | CW26: 1 | CX26: 45000 | CY26: 18835 | CZ26: 71.64 | DA26: 4 | DB26: 1 | DC26: 1 | DD26: 0 | DE26: 0 | DF26: NaN | DG26: 28 | DH26: 2.8888889 | DI26: 10 | DJ26: 999 | DK26: 6 | DL26: 6 | DM26: 999 | DN26: 9 | DO26: 3.9166667 | DP26: 4 | DQ26: 5 | DR26: 8 | DS26: 4 | DT26: NaN | DU26: NaN | DV26: NaN | DW26: 1 | DX26: 13021 | DY26: 8 | DZ26: 0 | EA26: NaN | EB26: NaN | EC26: NaN | ED26: NaN | EE26: NaN | EF26: NaN | EG26: NaN | EH26: NaN | EI26: 0 | EJ26: NaN
A27: 10640 | B27: 30392 | C27: 106.88985 | D27: 3 | E27: 5.5 | F27: 2.222222 | G27: 3.555556 | H27: 5 | I27: 4.909091 | J27: 31.73 | K27: White | L27: Female | M27: 3.22 | N27: 3 | O27: 0 | P27: 1 | Q27: 0 | R27: 6 | S27: 4.83 | T27: 4.38 | U27: 5.5 | V27: 5.17 | W27: 23 | X27: 6 | Y27: 14 | Z27: 3 | AA27: 0 | AB27: 2 | AC27: 6 | AD27: 9 | AE27: 3 | AF27: 4 | AG27: 24 | AH27: 34 | AI27: 17 | AJ27: 0 | AK27: 0 | AL27: 6.67 | AM27: 7 | AN27: 6 | AO27: 7 | AP27: 3.3 | AQ27: 19 | AR27: 1.92 | AS27: 84 | AT27: 1.67 | AU27: 9999 | AV27: 0 | AW27: 0 | AX27: 0 | AY27: 0 | AZ27: 0 | BA27: 0 | BB27: 0 | BC27: 0 | BD27: 0 | BE27: 0 | BF27: 20 | BG27: 0 | BH27: 0 | BI27: 0 | BJ27: 0 | BK27: 0 | BL27: 0 | BM27: 0 | BN27: 0 | BO27: 8991 | BP27: 0 | BQ27: 0 | BR27: 0 | BS27: 0 | BT27: 4 | BU27: 4.7 | BV27: 4.6 | BW27: 4.43 | BX27: 6 | BY27: 5.1666667 | BZ27: 6 | CA27: 5.1666667 | CB27: 0.65 | CC27: 0 | CD27: 0 | CE27: 25 | CF27: 27 | CG27: 9 | CH27: 0.9 | CI27: 32 | CJ27: 30 | CK27: 35 | CL27: 25 | CM27: 32 | CN27: 48 | CO27: 0 | CP27: 39 | CQ27: 60 | CR27: 33 | CS27: 60 | CT27: 1 | CU27: 1 | CV27: 7 | CW27: 1 | CX27: 45001 | CY27: 33609 | CZ27: 31.19 | DA27: 4 | DB27: 1 | DC27: 0 | DD27: 0 | DE27: 0 | DF27: NaN | DG27: 0 | DH27: 3.5555556 | DI27: 12 | DJ27: 999 | DK27: 8 | DL27: 12 | DM27: 999 | DN27: 12 | DO27: 4.8333333 | DP27: 5 | DQ27: 5 | DR27: 6 | DS27: 5 | DT27: NaN | DU27: NaN | DV27: NaN | DW27: 3 | DX27: 19145 | DY27: 6 | DZ27: 0 | EA27: NaN | EB27: NaN | EC27: NaN | ED27: NaN | EE27: NaN | EF27: NaN | EG27: NaN | EH27: NaN | EI27: NaN | EJ27: NaN
A28: 10641 | B28: 32278 | C28: -1.5001282 | D28: 3.6 | E28: 4.571429 | F28: 2.5 | G28: 3.6 | H28: 6.285714 | I28: 6.333333 | J28: 44.68 | K28: White | L28: Female | M28: 4.67 | N28: 4.5 | O28: 4 | P28: 1 | Q28: 0 | R28: 6.33 | S28: 4.83 | T28: 6 | U28: 5.83 | V28: 5.8 | W28: 9 | X28: 3 | Y28: 6 | Z28: 0 | AA28: 0 | AB28: 1 | AC28: 2 | AD28: 7 | AE28: 1 | AF28: 1 | AG28: 12 | AH28: 37 | AI28: 11 | AJ28: 0 | AK28: 0 | AL28: 6.75 | AM28: 6.5 | AN28: 6.75 | AO28: 7 | AP28: 2.5 | AQ28: 17 | AR28: 2.83 | AS28: 82 | AT28: 2.67 | AU28: 3.11 | AV28: 0 | AW28: 0 | AX28: 0 | AY28: 0 | AZ28: 0 | BA28: 0 | BB28: 0 | BC28: 0 | BD28: 0 | BE28: 0 | BF28: 20 | BG28: 0 | BH28: 0 | BI28: 0 | BJ28: 0 | BK28: 0 | BL28: 0 | BM28: 0 | BN28: 0 | BO28: 8991 | BP28: 0 | BQ28: 0 | BR28: 0 | BS28: 0 | BT28: 3.5 | BU28: 4 | BV28: 4.1 | BW28: 3.87 | BX28: 6 | BY28: 5.1666667 | BZ28: 3.8333333 | CA28: 3.8333333 | CB28: 1.25 | CC28: 0 | CD28: 0 | CE28: 26 | CF28: 0 | CG28: 9 | CH28: 0.81818182 | CI28: 35 | CJ28: 37 | CK28: 58 | CL28: 26 | CM28: 35 | CN28: 48 | CO28: 47 | CP28: 35 | CQ28: 60 | CR28: 38 | CS28: 60 | CT28: 0 | CU28: 0 | CV28: 7 | CW28: 1 | CX28: 45001 | CY28: 28785 | CZ28: 44.4 | DA28: 4 | DB28: 1 | DC28: 4 | DD28: 4 | DE28: 0 | DF28: NaN | DG28: 31 | DH28: 3.2777778 | DI28: 9 | DJ28: 999 | DK28: 8 | DL28: 8 | DM28: 999 | DN28: 10 | DO28: 5 | DP28: 6 | DQ28: 1 | DR28: 5 | DS28: 6 | DT28: NaN | DU28: NaN | DV28: NaN | DW28: 1 | DX28: 22307 | DY28: 5 | DZ28: 0 | EA28: NaN | EB28: NaN | EC28: NaN | ED28: NaN | EE28: NaN | EF28: NaN | EG28: NaN | EH28: NaN | EI28: NaN | EJ28: NaN
A29: 10642 | B29: 31691 | C29: -32.420433 | D29: 2.285714 | E29: 2.5 | F29: 2.666667 | G29: 2.6 | H29: 5.857143 | I29: 6 | J29: 31.9 | K29: White | L29: Female | M29: 4.67 | N29: 3.2 | O29: 21 | P29: 21 | Q29: 0 | R29: 5 | S29: 2 | T29: 2.13 | U29: 5.83 | V29: 3.67 | W29: 39 | X29: 7 | Y29: 19 | Z29: 8 | AA29: 5 | AB29: 1 | AC29: 7 | AD29: 5 | AE29: 5 | AF29: 4 | AG29: 22 | AH29: 33 | AI29: 13 | AJ29: 0 | AK29: 0 | AL29: 3.83 | AM29: 4.75 | AN29: 1 | AO29: 5.75 | AP29: 2.6 | AQ29: 12 | AR29: 1.92 | AS29: 91 | AT29: 1.17 | AU29: 9999 | AV29: 0 | AW29: 0 | AX29: 0 | AY29: 0 | AZ29: 0 | BA29: 0 | BB29: 0 | BC29: 0 | BD29: 0 | BE29: 0 | BF29: 20 | BG29: 0 | BH29: 0 | BI29: 0 | BJ29: 0 | BK29: 0 | BL29: 0 | BM29: 0 | BN29: 0 | BO29: 8991 | BP29: 0 | BQ29: 0 | BR29: 0 | BS29: 0 | BT29: 2.3 | BU29: 4.2 | BV29: 3.8 | BW29: 3.43 | BX29: 5.1666667 | BY29: 3.5 | BZ29: 3.5 | CA29: 4.3333333 | CB29: 1.6 | CC29: 0 | CD29: 0 | CE29: 26 | CF29: 27 | CG29: 10 | CH29: 0.83333333 | CI29: 34 | CJ29: 46 | CK29: 59 | CL29: 23 | CM29: 28 | CN29: 42 | CO29: 60 | CP29: 39 | CQ29: 60 | CR29: 30 | CS29: 60 | CT29: 0 | CU29: 0 | CV29: 2 | CW29: 4 | CX29: 45000 | CY29: 33473 | CZ29: 31.56 | DA29: 4 | DB29: 1 | DC29: 2 | DD29: 5 | DE29: 6 | DF29: NaN | DG29: 0 | DH29: 2 | DI29: 6 | DJ29: 999 | DK29: 4 | DL29: 6 | DM29: 999 | DN29: 6 | DO29: 2.75 | DP29: 4 | DQ29: 0 | DR29: 4 | DS29: 4 | DT29: NaN | DU29: NaN | DV29: NaN | DW29: 1 | DX29: 19124 | DY29: 4 | DZ29: 0 | EA29: NaN | EB29: NaN | EC29: NaN | ED29: NaN | EE29: NaN | EF29: NaN | EG29: NaN | EH29: NaN | EI29: NaN | EJ29: NaN
A30: 10644 | B30: 101853 | C30: 66.645536 | D30: 2.857143 | E30: 4 | F30: 3.142857 | G30: 3.777778 | H30: 5.692308 | I30: 6.142857 | J30: 69.41 | K30: White | L30: Female | M30: 3.44 | N30: 3.2 | O30: 1 | P30: 1 | Q30: 0 | R30: 5.5 | S30: 3.5 | T30: 4.5 | U30: 5 | V30: 4.6 | W30: 18 | X30: 4 | Y30: 7 | Z30: 2 | AA30: 5 | AB30: 3 | AC30: 6 | AD30: 6 | AE30: 6 | AF30: 4 | AG30: 25 | AH30: 25 | AI30: 11 | AJ30: 0 | AK30: 0 | AL30: 5.92 | AM30: 6 | AN30: 5.75 | AO30: 6 | AP30: 3 | AQ30: 15 | AR30: 4.5 | AS30: 89 | AT30: 3.17 | AU30: 4.37 | AV30: 51.1 | AW30: 0 | AX30: 0 | AY30: 0 | AZ30: 0 | BA30: 0 | BB30: 0 | BC30: 0 | BD30: 0 | BE30: 0 | BF30: 20 | BG30: 0 | BH30: 0 | BI30: 0 | BJ30: 0 | BK30: 0 | BL30: 0 | BM30: 0 | BN30: 0 | BO30: 8991 | BP30: 0 | BQ30: 0 | BR30: 0 | BS30: 0 | BT30: 3.6 | BU30: 3.6 | BV30: 4 | BW30: 3.7333333 | BX30: 3.3333333 | BY30: 4.5 | BZ30: 4.5 | CA30: 4.5 | CB30: 3 | CC30: 0 | CD30: 0 | CE30: 26 | CF30: 32 | CG30: 9 | CH30: 0.9 | CI30: 35 | CJ30: 34 | CK30: 52 | CL30: 29 | CM30: 31 | CN30: 48 | CO30: 55 | CP30: 47 | CQ30: 60 | CR30: 38 | CS30: 60 | CT30: 0 | CU30: 0 | CV30: 6 | CW30: 1 | CX30: 45000 | CY30: 19685 | CZ30: 69.31 | DA30: 4 | DB30: 1 | DC30: 1 | DD30: 4 | DE30: 0 | DF30: NaN | DG30: 23 | DH30: 3 | DI30: 10 | DJ30: 999 | DK30: 8 | DL30: 8 | DM30: 999 | DN30: 9 | DO30: 4.0833333 | DP30: 6 | DQ30: 4 | DR30: 7 | DS30: 6 | DT30: NaN | DU30: NaN | DV30: NaN | DW30: 1 | DX30: 11793 | DY30: 7 | DZ30: 1 | EA30: NaN | EB30: NaN | EC30: NaN | ED30: NaN | EE30: NaN | EF30: NaN | EG30: NaN | EH30: NaN | EI30: 5 | EJ30: NaN
A31: 10647 | B31: 30298 | C31: 20.379283 | D31: 2.25 | E31: 2.5 | F31: 2.444444 | G31: 2.5 | H31: 3.4 | I31: 2.8 | J31: 24.59 | K31: White | L31: Female | M31: 4.22 | N31: 4.5 | O31: 1 | P31: 0 | Q31: 0 | R31: 6.17 | S31: 4.83 | T31: 6.25 | U31: 4.83 | V31: 5.63 | W31: 0 | X31: 0 | Y31: 0 | Z31: 0 | AA31: 0 | AB31: 0 | AC31: 0 | AD31: 1 | AE31: 2 | AF31: 0 | AG31: 3 | AH31: 28 | AI31: 15 | AJ31: 0 | AK31: 0 | AL31: 5.67 | AM31: 5.25 | AN31: 5 | AO31: 6.75 | AP31: 3.3 | AQ31: 6 | AR31: 2.92 | AS31: 89 | AT31: 3 | AU31: 9999 | AV31: 0 | AW31: 0 | AX31: 0 | AY31: 0 | AZ31: 0 | BA31: 0 | BB31: 0 | BC31: 0 | BD31: 0 | BE31: 0 | BF31: 20 | BG31: 0 | BH31: 0 | BI31: 0 | BJ31: 0 | BK31: 0 | BL31: 0 | BM31: 0 | BN31: 0 | BO31: 8991 | BP31: 0 | BQ31: 0 | BR31: 0 | BS31: 0 | BT31: 4 | BU31: 3.8 | BV31: 4.2 | BW31: 4 | BX31: 6 | BY31: 5.1666667 | BZ31: 6 | CA31: 5.1666667 | CB31: 0.95 | CC31: 0 | CD31: 0 | CE31: 30 | CF31: 25 | CG31: 12 | CH31: 1 | CI31: 42 | CJ31: 33 | CK31: 47 | CL31: 24 | CM31: 37 | CN31: 47 | CO31: 48 | CP31: 48 | CQ31: 47 | CR31: 48 | CS31: 60 | CT31: 0 | CU31: 0 | CV31: 5 | CW31: 1 | CX31: 45001 | CY31: 36114 | CZ31: 24.33 | DA31: 4 | DB31: 1 | DC31: 5 | DD31: 0 | DE31: 0 | DF31: NaN | DG31: 0 | DH31: 2.3333333 | DI31: 3 | DJ31: 999 | DK31: 6 | DL31: 1 | DM31: 999 | DN31: 10 | DO31: 4.5833333 | DP31: 5 | DQ31: 1 | DR31: 6 | DS31: 5 | DT31: NaN | DU31: NaN | DV31: NaN | DW31: NaN | DX31: 66212 | DY31: 6 | DZ31: 0 | EA31: NaN | EB31: NaN | EC31: NaN | ED31: NaN | EE31: NaN | EF31: NaN | EG31: NaN | EH31: NaN | EI31: NaN | EJ31: NaN
A32: 10649 | B32: 130259 | C32: 154.58207 | D32: 5.571429 | E32: 5.777778 | F32: 5.384615 | G32: 6.428571 | H32: 6.333333 | I32: 5.333333 | J32: 63.8 | K32: White | L32: Female | M32: 3.33 | N32: 3.3 | O32: 2 | P32: 1 | Q32: 0 | R32: 0 | S32: 0 | T32: 0 | U32: 0 | V32: 0 | W32: 0 | X32: 0 | Y32: 0 | Z32: 0 | AA32: 0 | AB32: 0 | AC32: 0 | AD32: 0 | AE32: 0 | AF32: 0 | AG32: 0 | AH32: 32 | AI32: 12 | AJ32: 1 | AK32: 0 | AL32: 7 | AM32: 7 | AN32: 7 | AO32: 7 | AP32: 3.7 | AQ32: 13 | AR32: 3.08 | AS32: 86 | AT32: 3 | AU32: 3.49 | AV32: 0 | AW32: 0 | AX32: 0 | AY32: 0 | AZ32: 0 | BA32: 0 | BB32: 0 | BC32: 0 | BD32: 0 | BE32: 0 | BF32: 20 | BG32: 0 | BH32: 0 | BI32: 0 | BJ32: 0 | BK32: 0 | BL32: 0 | BM32: 0 | BN32: 0 | BO32: 8991 | BP32: 0 | BQ32: 0 | BR32: 0 | BS32: 0 | BT32: 3.5 | BU32: 3.9 | BV32: 3.4 | BW32: 3.6 | BX32: 6 | BY32: 5.1666667 | BZ32: 6 | CA32: 5.1666667 | CB32: 1.2 | CC32: 0 | CD32: 0 | CE32: 18 | CF32: 0 | CG32: 8 | CH32: 1.3333333 | CI32: 26 | CJ32: 24 | CK32: 29 | CL32: 27 | CM32: 31 | CN32: 41 | CO32: 60 | CP32: 48 | CQ32: 60 | CR32: 14 | CS32: 60 | CT32: 0 | CU32: 0 | CV32: 6 | CW32: 1 | CX32: 45006 | CY32: 21740 | CZ32: 63.7 | DA32: 4 | DB32: 1 | DC32: 6 | DD32: 0 | DE32: 0 | DF32: 2 | DG32: 28 | DH32: 3.3888889 | DI32: 11 | DJ32: 999 | DK32: 8 | DL32: 12 | DM32: 999 | DN32: 12 | DO32: 5 | DP32: 5 | DQ32: 5 | DR32: 8 | DS32: 5 | DT32: NaN | DU32: NaN | DV32: NaN | DW32: 1 | DX32: 8520 | DY32: 8 | DZ32: 0 | EA32: NaN | EB32: NaN | EC32: NaN | ED32: NaN | EE32: NaN | EF32: NaN | EG32: NaN | EH32: NaN | EI32: 0 | EJ32: NaN
A33: 10652 | B33: 120253 | C33: -135.48325 | D33: 4 | E33: 4.714286 | F33: 4 | G33: 4.615385 | H33: 5.142857 | I33: 5.076923 | J33: 70.05 | K33: Asian | L33: Female | M33: 4.44 | N33: 4.11 | O33: 1 | P33: 0 | Q33: 0 | R33: 6.83 | S33: 5.5 | T33: 6.38 | U33: 5.33 | V33: 6.1 | W33: 1 | X33: 1 | Y33: 0 | Z33: 0 | AA33: 0 | AB33: 2 | AC33: 3 | AD33: 6 | AE33: 1 | AF33: 3 | AG33: 15 | AH33: 26 | AI33: 10 | AJ33: 0 | AK33: 0 | AL33: 6.92 | AM33: 6.75 | AN33: 7 | AO33: 7 | AP33: 3 | AQ33: 6 | AR33: 3.33 | AS33: 90 | AT33: 2.33 | AU33: 3.29 | AV33: 0 | AW33: 0 | AX33: 0 | AY33: 0 | AZ33: 0 | BA33: 0 | BB33: 0 | BC33: 0 | BD33: 0 | BE33: 0 | BF33: 20 | BG33: 0 | BH33: 0 | BI33: 0 | BJ33: 0 | BK33: 0 | BL33: 0 | BM33: 0 | BN33: 0 | BO33: 8991 | BP33: 0 | BQ33: 0 | BR33: 0 | BS33: 0 | BT33: 4 | BU33: 3.8 | BV33: 4 | BW33: 3.93 | BX33: 6 | BY33: 5.1666667 | BZ33: 4.5 | CA33: 4.3333333 | CB33: 1 | CC33: 0 | CD33: 0 | CE33: 20 | CF33: 0 | CG33: 7 | CH33: 0.77777778 | CI33: 24 | CJ33: 24 | CK33: 38 | CL33: 25 | CM33: 27 | CN33: 48 | CO33: 60 | CP33: 48 | CQ33: 60 | CR33: 43 | CS33: 60 | CT33: 0 | CU33: 0 | CV33: 2 | CW33: 1 | CX33: 45013 | CY33: 19490 | CZ33: 69.88 | DA33: 1 | DB33: 1 | DC33: 0 | DD33: 0 | DE33: 0 | DF33: 1 | DG33: 36 | DH33: 2.2222222 | DI33: 9 | DJ33: 999 | DK33: 6 | DL33: 1 | DM33: 999 | DN33: 8 | DO33: 5 | DP33: 5 | DQ33: 3 | DR33: 7 | DS33: 5 | DT33: NaN | DU33: NaN | DV33: NaN | DW33: 1 | DX33: 19038 | DY33: 7 | DZ33: 0 | EA33: NaN | EB33: NaN | EC33: NaN | ED33: NaN | EE33: NaN | EF33: NaN | EG33: NaN | EH33: NaN | EI33: 0 | EJ33: NaN
A34: 10656 | B34: 181801 | C34: 29.663521 | D34: 2.5 | E34: 2.571429 | F34: 3.090909 | G34: 2.909091 | H34: 3.090909 | I34: 2.923077 | J34: 21.43 | K34: Black or African American | L34: Male | M34: 5 | N34: 4.2 | O34: 3 | P34: 4 | Q34: 0 | R34: 6.67 | S34: 5.33 | T34: 4.38 | U34: 3.17 | V34: 4.53 | W34: 24 | X34: 3 | Y34: 14 | Z34: 3 | AA34: 4 | AB34: 5 | AC34: 6 | AD34: 0 | AE34: 8 | AF34: 4 | AG34: 23 | AH34: 39 | AI34: 12 | AJ34: 0 | AK34: 0 | AL34: 6.83 | AM34: 7 | AN34: 7 | AO34: 6.5 | AP34: 2.8 | AQ34: 10 | AR34: 4.58 | AS34: 103 | AT34: 2.67 | AU34: 4.74 | AV34: 0.1 | AW34: 0 | AX34: 0 | AY34: 0 | AZ34: 0 | BA34: 0 | BB34: 0 | BC34: 0 | BD34: 0 | BE34: 0 | BF34: 20 | BG34: 0 | BH34: 0 | BI34: 0 | BJ34: 0 | BK34: 0 | BL34: 0 | BM34: 0 | BN34: 0 | BO34: 8991 | BP34: 0 | BQ34: 0 | BR34: 0 | BS34: 0 | BT34: 3.5 | BU34: 2.6 | BV34: 2.8 | BW34: 2.97 | BX34: 5.8333333 | BY34: 6 | BZ34: 6 | CA34: 2.6666667 | CB34: 1.75 | CC34: 0 | CD34: 0 | CE34: 12 | CF34: 20 | CG34: 0 | CH34: 0 | CI34: 12 | CJ34: 35 | CK34: 41 | CL34: 21 | CM34: 32 | CN34: 45 | CO34: 60 | CP34: 48 | CQ34: 60 | CR34: 44 | CS34: 60 | CT34: 0 | CU34: 0 | CV34: 7 | CW34: 2 | CX34: 45013 | CY34: 37204 | CZ34: 21.38 | DA34: 3 | DB34: 0 | DC34: 0 | DD34: 0 | DE34: 2 | DF34: 8 | DG34: 0 | DH34: 1.8333333 | DI34: 6 | DJ34: 999 | DK34: 4 | DL34: 0 | DM34: 999 | DN34: 6 | DO34: 3.4166667 | DP34: 1 | DQ34: 1 | DR34: 5 | DS34: 1 | DT34: NaN | DU34: NaN | DV34: NaN | DW34: 1 | DX34: NaN | DY34: 5 | DZ34: 1 | EA34: NaN | EB34: NaN | EC34: NaN | ED34: NaN | EE34: NaN | EF34: NaN | EG34: NaN | EH34: NaN | EI34: NaN | EJ34: NaN
A35: 10657 | B35: 22364 | C35: 58.420671 | D35: NaN | E35: NaN | F35: NaN | G35: NaN | H35: NaN | I35: NaN | J35: 58.98 | K35: White | L35: Male | M35: 4.33 | N35: 3.8 | O35: 7 | P35: 1 | Q35: 0 | R35: 5.3333333 | S35: 5.8333333 | T35: 5.5 | U35: 5.5 | V35: 5.4666667 | W35: 9 | X35: 2 | Y35: 2 | Z35: 1 | AA35: 4 | AB35: 5 | AC35: 3 | AD35: 8 | AE35: 7 | AF35: 1 | AG35: 24 | AH35: 36 | AI35: 10 | AJ35: 0 | AK35: 0 | AL35: 5.33 | AM35: 4.75 | AN35: 5 | AO35: 6.25 | AP35: 2.3 | AQ35: 13 | AR35: 2.5 | AS35: 87 | AT35: 2.5 | AU35: 3.03 | AV35: 50.1 | AW35: 0 | AX35: 0 | AY35: 0 | AZ35: 0 | BA35: 0 | BB35: 0 | BC35: 0 | BD35: 0 | BE35: 0 | BF35: 20 | BG35: 0 | BH35: 0 | BI35: 0 | BJ35: 0 | BK35: 0 | BL35: 0 | BM35: 0 | BN35: 0 | BO35: 8991 | BP35: 0 | BQ35: 0 | BR35: 0 | BS35: 0 | BT35: 3.7 | BU35: 3.5 | BV35: 3.6 | BW35: 3.6 | BX35: 6 | BY35: 2.6666667 | BZ35: 6 | CA35: 6 | CB35: 1.1 | CC35: 0 | CD35: 0 | CE35: 19 | CF35: 27 | CG35: 7 | CH35: 0.7 | CI35: 26 | CJ35: 37 | CK35: 31 | CL35: 26 | CM35: 32 | CN35: 45 | CO35: 60 | CP35: 36 | CQ35: 60 | CR35: 30 | CS35: 60 | CT35: 0 | CU35: 0 | CV35: 4 | CW35: 1 | CX35: 45013 | CY35: 23497 | CZ35: 58.91 | DA35: 4 | DB35: 0 | DC35: 4 | DD35: 2 | DE35: 1 | DF35: 4 | DG35: 28 | DH35: 1.3888889 | DI35: 4 | DJ35: 999 | DK35: 4 | DL35: 2 | DM35: 999 | DN35: 5 | DO35: 3.75 | DP35: 4 | DQ35: 3 | DR35: 6 | DS35: 4 | DT35: NaN | DU35: NaN | DV35: NaN | DW35: NaN | DX35: 8110 | DY35: 6 | DZ35: 0 | EA35: NaN | EB35: NaN | EC35: NaN | ED35: NaN | EE35: NaN | EF35: NaN | EG35: NaN | EH35: NaN | EI35: 0 | EJ35: NaN
A36: 10659 | B36: 181861 | C36: 33.677244 | D36: 5.857143 | E36: 5.833333 | F36: 6.153846 | G36: 5.538462 | H36: 5 | I36: 5.166667 | J36: 62.39 | K36: Black or African American | L36: Female | M36: 4.22 | N36: 3.3 | O36: 0 | P36: 0 | Q36: 0 | R36: 6.5 | S36: 5.33 | T36: 6.25 | U36: 5.83 | V36: 6 | W36: 11 | X36: 0 | Y36: 4 | Z36: 1 | AA36: 6 | AB36: 3 | AC36: 2 | AD36: 4 | AE36: 1 | AF36: 2 | AG36: 12 | AH36: 34 | AI36: 9 | AJ36: 1 | AK36: 0 | AL36: 6.33 | AM36: 6 | AN36: 6.25 | AO36: 6.75 | AP36: 3.8 | AQ36: 15 | AR36: 2 | AS36: 90 | AT36: 3 | AU36: 9999 | AV36: 0 | AW36: 0 | AX36: 0 | AY36: 0 | AZ36: 0 | BA36: 0 | BB36: 0 | BC36: 0 | BD36: 0 | BE36: 0 | BF36: 20 | BG36: 0 | BH36: 0 | BI36: 0 | BJ36: 0 | BK36: 0 | BL36: 0 | BM36: 0 | BN36: 0 | BO36: 8991 | BP36: 0 | BQ36: 0 | BR36: 0 | BS36: 0 | BT36: 3.6 | BU36: 3.7 | BV36: 3.3 | BW36: 3.53 | BX36: 6 | BY36: 5.1666667 | BZ36: 3.6666667 | CA36: 5.1666667 | CB36: 0.35 | CC36: 0 | CD36: 0 | CE36: 19 | CF36: 20 | CG36: 9 | CH36: 1.2857143 | CI36: 25 | CJ36: 22 | CK36: 31 | CL36: 23 | CM36: 31 | CN36: 37 | CO36: 60 | CP36: 29 | CQ36: 60 | CR36: 26 | CS36: 60 | CT36: 0 | CU36: 0 | CV36: 6 | CW36: 4 | CX36: 45014 | CY36: 22331 | CZ36: 62.1 | DA36: 3 | DB36: 1 | DC36: 0 | DD36: 0 | DE36: 3 | DF36: 13 | DG36: 27 | DH36: 2.3333333 | DI36: 11 | DJ36: 999 | DK36: 6 | DL36: 3 | DM36: 999 | DN36: 8 | DO36: 3.8333333 | DP36: 5 | DQ36: 0 | DR36: 5 | DS36: 5 | DT36: NaN | DU36: NaN | DV36: NaN | DW36: 1 | DX36: 19144 | DY36: 5 | DZ36: 0 | EA36: NaN | EB36: NaN | EC36: NaN | ED36: NaN | EE36: NaN | EF36: NaN | EG36: NaN | EH36: NaN | EI36: 0 | EJ36: NaN
A37: 10661 | B37: 130672 | C37: 51.15587 | D37: NaN | E37: NaN | F37: NaN | G37: NaN | H37: NaN | I37: NaN | J37: 0 | K37: White | L37: Male | M37: 5 | N37: 3.3 | O37: 1 | P37: 0 | Q37: 0 | R37: 6.83 | S37: 5.83 | T37: 6.5 | U37: 6.33 | V37: 6.43 | W37: 16 | X37: 2 | Y37: 8 | Z37: 1 | AA37: 5 | AB37: 0 | AC37: 3 | AD37: 5 | AE37: 0 | AF37: 2 | AG37: 10 | AH37: 42 | AI37: 10 | AJ37: 0 | AK37: 0 | AL37: 7 | AM37: 7 | AN37: 7 | AO37: 7 | AP37: 3.9 | AQ37: 8 | AR37: 1.67 | AS37: 90 | AT37: 3.33 | AU37: 3.4 | AV37: 0 | AW37: 0 | AX37: 0 | AY37: 0 | AZ37: 0 | BA37: 0 | BB37: 0 | BC37: 0 | BD37: 0 | BE37: 0 | BF37: 20 | BG37: 0 | BH37: 0 | BI37: 0 | BJ37: 0 | BK37: 0 | BL37: 0 | BM37: 0 | BN37: 0 | BO37: 8991 | BP37: 0 | BQ37: 0 | BR37: 0 | BS37: 0 | BT37: 3.9 | BU37: 3.9 | BV37: 3.8 | BW37: 3.87 | BX37: 6 | BY37: 5.1666667 | BZ37: 5.1666667 | CA37: 4.3333333 | CB37: 0.2 | CC37: 0 | CD37: 0 | CE37: 24 | CF37: 0 | CG37: 7 | CH37: 0.7 | CI37: 31 | CJ37: 39 | CK37: 45 | CL37: 31 | CM37: 30 | CN37: 48 | CO37: 60 | CP37: 47 | CQ37: 60 | CR37: 48 | CS37: 60 | CT37: 0 | CU37: 0 | CV37: 7 | CW37: 1 | CX37: 45016 | CY37: 26625 | CZ37: 50.35 | DA37: 4 | DB37: 0 | DC37: 4 | DD37: 0 | DE37: 0 | DF37: 2 | DG37: 0 | DH37: 4.125 | DI37: 12 | DJ37: 12 | DK37: 12 | DL37: 0 | DM37: 18 | DN37: 12 | DO37: 5 | DP37: 6 | DQ37: 4 | DR37: 8 | DS37: 6 | DT37: NaN | DU37: NaN | DV37: NaN | DW37: 3 | DX37: 19128 | DY37: 8 | DZ37: 0 | EA37: NaN | EB37: NaN | EC37: NaN | ED37: NaN | EE37: NaN | EF37: NaN | EG37: NaN | EH37: NaN | EI37: NaN | EJ37: NaN
